Workbook

Sheet FORMULA
A1: FORMULA
A2: 1101 C (STARTER) | B2: 1 | D2: 2 | F2: 3 | H2: 4 | J2: 5 | L2: 6 | N2: 7 | P2: 8 | R2: 9 | T2: 10 | V2: 11 | X2: 12 | Z2: 13 | AB2: 14 | AD2: 15
B3: WS 1101 (251124) | D3: WS 1101 (220526)
B4: N01309AY
B5: % | C5: BATCH | D5: % | E5: BATCH | F5: % | G5: BATCH | H5: % | I5: BATCH | J5: % | K5: BATCH | L5: % | M5: BATCH | N5: % | O5: BATCH | P5: % | Q5: BATCH | R5: % | S5: BATCH | T5: % | U5: BATCH | V5: % | W5: BATCH | X5: % | Y5: BATCH | Z5: % | AA5: BATCH | AB5: % | AC5: BATCH | AD5: % | AE5: BATCH
A6: MAIZE/CORN | B6: =1070.2/20 -> 53.51 | C6: =(B6/100)*1000 -> 535.1 | D6: =1136.8/20 -> 56.84 | E6: =(D6/100)*1000 -> 568.4 | G6: =(F6/100)*1000 -> 0 | I6: =(H6/100)*1000 -> 0 | K6: =(J6/100)*1000 -> 0 | M6: =(L6/100)*1000 -> 0 | O6: =(N6/100)*1000 -> 0 | Q6: =(P6/100)*1000 -> 0 | S6: =(R6/100)*1000 -> 0 | U6: =(T6/100)*1000 -> 0 | W6: =(V6/100)*1000 -> 0 | Y6: =(X6/100)*1000 -> 0 | AA6: =(Z6/100)*1000 -> 0 | AC6: =(AB6/100)*1000 -> 0 | AE6: =(AD6/100)*1000 -> 0
A7: SOYBEAN MEAL (ARG) | B7: =652.5/20 -> 32.625 | C7: =(B7/100)*1000 -> 326.25 | D7: =655.6/20 -> 32.78 | E7: =(D7/100)*1000 -> 327.8 | G7: =(F7/100)*1000 -> 0 | I7: =(H7/100)*1000 -> 0 | K7: =(J7/100)*1000 -> 0 | M7: =(L7/100)*1000 -> 0 | O7: =(N7/100)*1000 -> 0 | Q7: =(P7/100)*1000 -> 0 | S7: =(R7/100)*1000 -> 0 | U7: =(T7/100)*1000 -> 0 | W7: =(V7/100)*1000 -> 0 | Y7: =(X7/100)*1000 -> 0 | AA7: =(Z7/100)*1000 -> 0 | AC7: =(AB7/100)*1000 -> 0 | AE7: =(AD7/100)*1000 -> 0
A8: SOYBEAN FULL FAT | B8: =50/20 -> 2.5 | C8: =(B8/100)*1000 -> 25 | D8: 2.5 | E8: =(D8/100)*1000 -> 25 | G8: =(F8/100)*1000 -> 0 | I8: =(H8/100)*1000 -> 0 | K8: =(J8/100)*1000 -> 0 | M8: =(L8/100)*1000 -> 0 | O8: =(N8/100)*1000 -> 0 | Q8: =(P8/100)*1000 -> 0 | S8: =(R8/100)*1000 -> 0 | U8: =(T8/100)*1000 -> 0 | W8: =(V8/100)*1000 -> 0 | Y8: =(X8/100)*1000 -> 0 | AA8: =(Z8/100)*1000 -> 0 | AC8: =(AB8/100)*1000 -> 0 | AE8: =(AD8/100)*1000 -> 0
A9: WHEAT POLLARD | B9: =100/20 -> 5 | C9: =(B9/100)*1000 -> 50 | E9: =(D9/100)*1000 -> 0 | G9: =(F9/100)*1000 -> 0 | I9: =(H9/100)*1000 -> 0 | K9: =(J9/100)*1000 -> 0 | M9: =(L9/100)*1000 -> 0 | O9: =(N9/100)*1000 -> 0 | Q9: =(P9/100)*1000 -> 0 | S9: =(R9/100)*1000 -> 0 | U9: =(T9/100)*1000 -> 0 | W9: =(V9/100)*1000 -> 0 | Y9: =(X9/100)*1000 -> 0 | AA9: =(Z9/100)*1000 -> 0 | AC9: =(AB9/100)*1000 -> 0 | AE9: =(AD9/100)*1000 -> 0
A10: WHEAT | C10: =(B10/100)*1000 -> 0 | E10: =(D10/100)*1000 -> 0 | G10: =(F10/100)*1000 -> 0 | I10: =(H10/100)*1000 -> 0 | K10: =(J10/100)*1000 -> 0 | M10: =(L10/100)*1000 -> 0 | O10: =(N10/100)*1000 -> 0 | Q10: =(P10/100)*1000 -> 0 | S10: =(R10/100)*1000 -> 0 | U10: =(T10/100)*1000 -> 0 | W10: =(V10/100)*1000 -> 0 | Y10: =(X10/100)*1000 -> 0 | AA10: =(Z10/100)*1000 -> 0 | AC10: =(AB10/100)*1000 -> 0 | AE10: =(AD10/100)*1000 -> 0
A11: MEAT AND BONE MEAL | B11: =40/20 -> 2 | C11: =(B11/100)*1000 -> 20 | D11: =40.4/20 -> 2.02 | E11: =(D11/100)*1000 -> 20.2 | G11: =(F11/100)*1000 -> 0 | I11: =(H11/100)*1000 -> 0 | K11: =(J11/100)*1000 -> 0 | M11: =(L11/100)*1000 -> 0 | O11: =(N11/100)*1000 -> 0 | Q11: =(P11/100)*1000 -> 0 | S11: =(R11/100)*1000 -> 0 | U11: =(T11/100)*1000 -> 0 | W11: =(V11/100)*1000 -> 0 | Y11: =(X11/100)*1000 -> 0 | AA11: =(Z11/100)*1000 -> 0 | AC11: =(AB11/100)*1000 -> 0 | AE11: =(AD11/100)*1000 -> 0
A12: CORN GLUTEN MEAL | C12: =(B12/100)*1000 -> 0 | E12: =(D12/100)*1000 -> 0 | G12: =(F12/100)*1000 -> 0 | I12: =(H12/100)*1000 -> 0 | K12: =(J12/100)*1000 -> 0 | M12: =(L12/100)*1000 -> 0 | O12: =(N12/100)*1000 -> 0 | Q12: =(P12/100)*1000 -> 0 | S12: =(R12/100)*1000 -> 0 | U12: =(T12/100)*1000 -> 0 | W12: =(V12/100)*1000 -> 0 | Y12: =(X12/100)*1000 -> 0 | AA12: =(Z12/100)*1000 -> 0 | AC12: =(AB12/100)*1000 -> 0 | AE12: =(AD12/100)*1000 -> 0
A13: MEGAFAT (HARUMI) | B13: =40/20 -> 2 | C13: =(B13/100)*1000 -> 20 | D13: =23/20 -> 1.15 | E13: =(D13/100)*1000 -> 11.5 | G13: =(F13/100)*1000 -> 0 | I13: =(H13/100)*1000 -> 0 | K13: =(J13/100)*1000 -> 0 | M13: =(L13/100)*1000 -> 0 | O13: =(N13/100)*1000 -> 0 | Q13: =(P13/100)*1000 -> 0 | S13: =(R13/100)*1000 -> 0 | U13: =(T13/100)*1000 -> 0 | W13: =(V13/100)*1000 -> 0 | Y13: =(X13/100)*1000 -> 0 | AA13: =(Z13/100)*1000 -> 0 | AC13: =(AB13/100)*1000 -> 0 | AE13: =(AD13/100)*1000 -> 0
A14: DCP 18% | B14: =4.5/20 -> 0.225 | C14: =(B14/100)*1000 -> 2.25 | E14: =(D14/100)*1000 -> 0 | G14: =(F14/100)*1000 -> 0 | I14: =(H14/100)*1000 -> 0 | K14: =(J14/100)*1000 -> 0 | M14: =(L14/100)*1000 -> 0 | O14: =(N14/100)*1000 -> 0 | Q14: =(P14/100)*1000 -> 0 | S14: =(R14/100)*1000 -> 0 | U14: =(T14/100)*1000 -> 0 | W14: =(V14/100)*1000 -> 0 | Y14: =(X14/100)*1000 -> 0 | AA14: =(Z14/100)*1000 -> 0 | AC14: =(AB14/100)*1000 -> 0 | AE14: =(AD14/100)*1000 -> 0
A15: LIMESTONE POWDER (HARUMI) | B15: =1.8/20 -> 0.09 | C15: =(B15/100)*1000 -> 0.9 | E15: =(D15/100)*1000 -> 0 | G15: =(F15/100)*1000 -> 0 | I15: =(H15/100)*1000 -> 0 | K15: =(J15/100)*1000 -> 0 | M15: =(L15/100)*1000 -> 0 | O15: =(N15/100)*1000 -> 0 | Q15: =(P15/100)*1000 -> 0 | S15: =(R15/100)*1000 -> 0 | U15: =(T15/100)*1000 -> 0 | W15: =(V15/100)*1000 -> 0 | Y15: =(X15/100)*1000 -> 0 | AA15: =(Z15/100)*1000 -> 0 | AC15: =(AB15/100)*1000 -> 0 | AE15: =(AD15/100)*1000 -> 0
A16: CHOLINE CHLORIDE 60% | C16: =(B16/100)*1000 -> 0 | E16: =(D16/100)*1000 -> 0 | G16: =(F16/100)*1000 -> 0 | I16: =(H16/100)*1000 -> 0 | K16: =(J16/100)*1000 -> 0 | M16: =(L16/100)*1000 -> 0 | O16: =(N16/100)*1000 -> 0 | Q16: =(P16/100)*1000 -> 0 | S16: =(R16/100)*1000 -> 0 | U16: =(T16/100)*1000 -> 0 | W16: =(V16/100)*1000 -> 0 | Y16: =(X16/100)*1000 -> 0 | AA16: =(Z16/100)*1000 -> 0 | AC16: =(AB16/100)*1000 -> 0 | AE16: =(AD16/100)*1000 -> 0
A17: INDUSTRY FLOUR | C17: =(B17/100)*1000 -> 0 | E17: =(D17/100)*1000 -> 0 | G17: =(F17/100)*1000 -> 0 | I17: =(H17/100)*1000 -> 0 | K17: =(J17/100)*1000 -> 0 | M17: =(L17/100)*1000 -> 0 | O17: =(N17/100)*1000 -> 0 | Q17: =(P17/100)*1000 -> 0 | S17: =(R17/100)*1000 -> 0 | U17: =(T17/100)*1000 -> 0 | W17: =(V17/100)*1000 -> 0 | Y17: =(X17/100)*1000 -> 0 | AA17: =(Z17/100)*1000 -> 0 | AC17: =(AB17/100)*1000 -> 0 | AE17: =(AD17/100)*1000 -> 0
A18: RICE BRAN | C18: =(B18/100)*1000 -> 0 | D18: =50/20 -> 2.5 | E18: =(D18/100)*1000 -> 25 | G18: =(F18/100)*1000 -> 0 | I18: =(H18/100)*1000 -> 0 | K18: =(J18/100)*1000 -> 0 | M18: =(L18/100)*1000 -> 0 | O18: =(N18/100)*1000 -> 0 | Q18: =(P18/100)*1000 -> 0 | S18: =(R18/100)*1000 -> 0 | U18: =(T18/100)*1000 -> 0 | W18: =(V18/100)*1000 -> 0 | Y18: =(X18/100)*1000 -> 0 | AA18: =(Z18/100)*1000 -> 0 | AC18: =(AB18/100)*1000 -> 0 | AE18: =(AD18/100)*1000 -> 0
A19: EP 200 | C19: =(B19/100)*1000 -> 0 | E19: =(D19/100)*1000 -> 0 | G19: =(F19/100)*1000 -> 0 | I19: =(H19/100)*1000 -> 0 | K19: =(J19/100)*1000 -> 0 | M19: =(L19/100)*1000 -> 0 | O19: =(N19/100)*1000 -> 0 | Q19: =(P19/100)*1000 -> 0 | S19: =(R19/100)*1000 -> 0 | U19: =(T19/100)*1000 -> 0 | W19: =(V19/100)*1000 -> 0 | Y19: =(X19/100)*1000 -> 0 | AA19: =(Z19/100)*1000 -> 0 | AC19: =(AB19/100)*1000 -> 0 | AE19: =(AD19/100)*1000 -> 0
A20: SOYTIDE | C20: =(B20/100)*1000 -> 0 | E20: =(D20/100)*1000 -> 0 | G20: =(F20/100)*1000 -> 0 | I20: =(H20/100)*1000 -> 0 | K20: =(J20/100)*1000 -> 0 | M20: =(L20/100)*1000 -> 0 | O20: =(N20/100)*1000 -> 0 | Q20: =(P20/100)*1000 -> 0 | S20: =(R20/100)*1000 -> 0 | U20: =(T20/100)*1000 -> 0 | W20: =(V20/100)*1000 -> 0 | Y20: =(X20/100)*1000 -> 0 | AA20: =(Z20/100)*1000 -> 0 | AC20: =(AB20/100)*1000 -> 0 | AE20: =(AD20/100)*1000 -> 0
A21: DCP 18% (HARUMI) | C21: =(B21/100)*1000 -> 0 | E21: =(D21/100)*1000 -> 0 | G21: =(F21/100)*1000 -> 0 | I21: =(H21/100)*1000 -> 0 | K21: =(J21/100)*1000 -> 0 | M21: =(L21/100)*1000 -> 0 | O21: =(N21/100)*1000 -> 0 | Q21: =(P21/100)*1000 -> 0 | S21: =(R21/100)*1000 -> 0 | U21: =(T21/100)*1000 -> 0 | W21: =(V21/100)*1000 -> 0 | Y21: =(X21/100)*1000 -> 0 | AA21: =(Z21/100)*1000 -> 0 | AC21: =(AB21/100)*1000 -> 0 | AE21: =(AD21/100)*1000 -> 0
A22: 1 | C22: =(B22/100)*1000 -> 0 | E22: =(D22/100)*1000 -> 0 | G22: =(F22/100)*1000 -> 0 | I22: =(H22/100)*1000 -> 0 | K22: =(J22/100)*1000 -> 0 | M22: =(L22/100)*1000 -> 0 | O22: =(N22/100)*1000 -> 0 | Q22: =(P22/100)*1000 -> 0 | S22: =(R22/100)*1000 -> 0 | U22: =(T22/100)*1000 -> 0 | W22: =(V22/100)*1000 -> 0 | Y22: =(X22/100)*1000 -> 0 | AA22: =(Z22/100)*1000 -> 0 | AC22: =(AB22/100)*1000 -> 0 | AE22: =(AD22/100)*1000 -> 0
A23: 2 | C23: =(B23/100)*1000 -> 0 | E23: =(D23/100)*1000 -> 0 | G23: =(F23/100)*1000 -> 0 | I23: =(H23/100)*1000 -> 0 | K23: =(J23/100)*1000 -> 0 | M23: =(L23/100)*1000 -> 0 | O23: =(N23/100)*1000 -> 0 | Q23: =(P23/100)*1000 -> 0 | S23: =(R23/100)*1000 -> 0 | U23: =(T23/100)*1000 -> 0 | W23: =(V23/100)*1000 -> 0 | Y23: =(X23/100)*1000 -> 0 | AA23: =(Z23/100)*1000 -> 0 | AC23: =(AB23/100)*1000 -> 0 | AE23: =(AD23/100)*1000 -> 0
A24: 3 | C24: =(B24/100)*1000 -> 0 | E24: =(D24/100)*1000 -> 0 | G24: =(F24/100)*1000 -> 0 | I24: =(H24/100)*1000 -> 0 | K24: =(J24/100)*1000 -> 0 | M24: =(L24/100)*1000 -> 0 | O24: =(N24/100)*1000 -> 0 | Q24: =(P24/100)*1000 -> 0 | S24: =(R24/100)*1000 -> 0 | U24: =(T24/100)*1000 -> 0 | W24: =(V24/100)*1000 -> 0 | Y24: =(X24/100)*1000 -> 0 | AA24: =(Z24/100)*1000 -> 0 | AC24: =(AB24/100)*1000 -> 0 | AE24: =(AD24/100)*1000 -> 0
A25: PREMIX 1101 (20KG) | B25: 2 | C25: =(B25/100)*1000 -> 20 | E25: =(D25/100)*1000 -> 0 | G25: =(F25/100)*1000 -> 0 | I25: =(H25/100)*1000 -> 0 | K25: =(J25/100)*1000 -> 0 | M25: =(L25/100)*1000 -> 0 | O25: =(N25/100)*1000 -> 0 | Q25: =(P25/100)*1000 -> 0 | S25: =(R25/100)*1000 -> 0 | U25: =(T25/100)*1000 -> 0 | W25: =(V25/100)*1000 -> 0 | Y25: =(X25/100)*1000 -> 0 | AA25: =(Z25/100)*1000 -> 0 | AC25: =(AB25/100)*1000 -> 0 | AE25: =(AD25/100)*1000 -> 0
A26: PREMIX 1102 (20KG) | C26: =(B26/100)*1000 -> 0 | E26: =(D26/100)*1000 -> 0 | G26: =(F26/100)*1000 -> 0 | I26: =(H26/100)*1000 -> 0 | K26: =(J26/100)*1000 -> 0 | M26: =(L26/100)*1000 -> 0 | O26: =(N26/100)*1000 -> 0 | Q26: =(P26/100)*1000 -> 0 | S26: =(R26/100)*1000 -> 0 | U26: =(T26/100)*1000 -> 0 | W26: =(V26/100)*1000 -> 0 | Y26: =(X26/100)*1000 -> 0 | AA26: =(Z26/100)*1000 -> 0 | AC26: =(AB26/100)*1000 -> 0 | AE26: =(AD26/100)*1000 -> 0
A27: PREMIX 1103 (20KG) | C27: =(B27/100)*1000 -> 0 | E27: =(D27/100)*1000 -> 0 | G27: =(F27/100)*1000 -> 0 | I27: =(H27/100)*1000 -> 0 | K27: =(J27/100)*1000 -> 0 | M27: =(L27/100)*1000 -> 0 | O27: =(N27/100)*1000 -> 0 | Q27: =(P27/100)*1000 -> 0 | S27: =(R27/100)*1000 -> 0 | U27: =(T27/100)*1000 -> 0 | W27: =(V27/100)*1000 -> 0 | Y27: =(X27/100)*1000 -> 0 | AA27: =(Z27/100)*1000 -> 0 | AC27: =(AB27/100)*1000 -> 0 | AE27: =(AD27/100)*1000 -> 0
A28: PREMIX 311 (20KG) | C28: =(B28/100)*1000 -> 0 | E28: =(D28/100)*1000 -> 0 | G28: =(F28/100)*1000 -> 0 | I28: =(H28/100)*1000 -> 0 | K28: =(J28/100)*1000 -> 0 | M28: =(L28/100)*1000 -> 0 | O28: =(N28/100)*1000 -> 0 | Q28: =(P28/100)*1000 -> 0 | S28: =(R28/100)*1000 -> 0 | U28: =(T28/100)*1000 -> 0 | W28: =(V28/100)*1000 -> 0 | Y28: =(X28/100)*1000 -> 0 | AA28: =(Z28/100)*1000 -> 0 | AC28: =(AB28/100)*1000 -> 0 | AE28: =(AD28/100)*1000 -> 0
A29: PREMIX 312 (20KG) | C29: =(B29/100)*1000 -> 0 | E29: =(D29/100)*1000 -> 0 | G29: =(F29/100)*1000 -> 0 | I29: =(H29/100)*1000 -> 0 | K29: =(J29/100)*1000 -> 0 | M29: =(L29/100)*1000 -> 0 | O29: =(N29/100)*1000 -> 0 | Q29: =(P29/100)*1000 -> 0 | S29: =(R29/100)*1000 -> 0 | U29: =(T29/100)*1000 -> 0 | W29: =(V29/100)*1000 -> 0 | Y29: =(X29/100)*1000 -> 0 | AA29: =(Z29/100)*1000 -> 0 | AC29: =(AB29/100)*1000 -> 0 | AE29: =(AD29/100)*1000 -> 0
A30: 1 | C30: =(B30/100)*1000 -> 0 | E30: =(D30/100)*1000 -> 0 | G30: =(F30/100)*1000 -> 0 | I30: =(H30/100)*1000 -> 0 | K30: =(J30/100)*1000 -> 0 | M30: =(L30/100)*1000 -> 0 | O30: =(N30/100)*1000 -> 0 | Q30: =(P30/100)*1000 -> 0 | S30: =(R30/100)*1000 -> 0 | U30: =(T30/100)*1000 -> 0 | W30: =(V30/100)*1000 -> 0 | Y30: =(X30/100)*1000 -> 0 | AA30: =(Z30/100)*1000 -> 0 | AC30: =(AB30/100)*1000 -> 0 | AE30: =(AD30/100)*1000 -> 0
A31: PREMIX 8100 (20KG) | C31: =(B31/100)*1000 -> 0 | E31: =(D31/100)*1000 -> 0 | G31: =(F31/100)*1000 -> 0 | I31: =(H31/100)*1000 -> 0 | K31: =(J31/100)*1000 -> 0 | M31: =(L31/100)*1000 -> 0 | O31: =(N31/100)*1000 -> 0 | Q31: =(P31/100)*1000 -> 0 | S31: =(R31/100)*1000 -> 0 | U31: =(T31/100)*1000 -> 0 | W31: =(V31/100)*1000 -> 0 | Y31: =(X31/100)*1000 -> 0 | AA31: =(Z31/100)*1000 -> 0 | AC31: =(AB31/100)*1000 -> 0 | AE31: =(AD31/100)*1000 -> 0
A32: PREMIX 8101 (20KG) | C32: =(B32/100)*1000 -> 0 | E32: =(D32/100)*1000 -> 0 | G32: =(F32/100)*1000 -> 0 | I32: =(H32/100)*1000 -> 0 | K32: =(J32/100)*1000 -> 0 | M32: =(L32/100)*1000 -> 0 | O32: =(N32/100)*1000 -> 0 | Q32: =(P32/100)*1000 -> 0 | S32: =(R32/100)*1000 -> 0 | U32: =(T32/100)*1000 -> 0 | W32: =(V32/100)*1000 -> 0 | Y32: =(X32/100)*1000 -> 0 | AA32: =(Z32/100)*1000 -> 0 | AC32: =(AB32/100)*1000 -> 0 | AE32: =(AD32/100)*1000 -> 0
A33: PREMIX 8102 (20KG) | C33: =(B33/100)*1000 -> 0 | E33: =(D33/100)*1000 -> 0 | G33: =(F33/100)*1000 -> 0 | I33: =(H33/100)*1000 -> 0 | K33: =(J33/100)*1000 -> 0 | M33: =(L33/100)*1000 -> 0 | O33: =(N33/100)*1000 -> 0 | Q33: =(P33/100)*1000 -> 0 | S33: =(R33/100)*1000 -> 0 | U33: =(T33/100)*1000 -> 0 | W33: =(V33/100)*1000 -> 0 | Y33: =(X33/100)*1000 -> 0 | AA33: =(Z33/100)*1000 -> 0 | AC33: =(AB33/100)*1000 -> 0 | AE33: =(AD33/100)*1000 -> 0
A34: PREMIX 8103 (20KG) | C34: =(B34/100)*1000 -> 0 | E34: =(D34/100)*1000 -> 0 | G34: =(F34/100)*1000 -> 0 | I34: =(H34/100)*1000 -> 0 | K34: =(J34/100)*1000 -> 0 | M34: =(L34/100)*1000 -> 0 | O34: =(N34/100)*1000 -> 0 | Q34: =(P34/100)*1000 -> 0 | S34: =(R34/100)*1000 -> 0 | U34: =(T34/100)*1000 -> 0 | W34: =(V34/100)*1000 -> 0 | Y34: =(X34/100)*1000 -> 0 | AA34: =(Z34/100)*1000 -> 0 | AC34: =(AB34/100)*1000 -> 0 | AE34: =(AD34/100)*1000 -> 0
A35: PREMIX 8108 (20KG) | C35: =(B35/100)*1000 -> 0 | E35: =(D35/100)*1000 -> 0 | G35: =(F35/100)*1000 -> 0 | I35: =(H35/100)*1000 -> 0 | K35: =(J35/100)*1000 -> 0 | M35: =(L35/100)*1000 -> 0 | O35: =(N35/100)*1000 -> 0 | Q35: =(P35/100)*1000 -> 0 | S35: =(R35/100)*1000 -> 0 | U35: =(T35/100)*1000 -> 0 | W35: =(V35/100)*1000 -> 0 | Y35: =(X35/100)*1000 -> 0 | AA35: =(Z35/100)*1000 -> 0 | AC35: =(AB35/100)*1000 -> 0 | AE35: =(AD35/100)*1000 -> 0
A36: PREMIX 8109 (20KG) | C36: =(B36/100)*1000 -> 0 | E36: =(D36/100)*1000 -> 0 | G36: =(F36/100)*1000 -> 0 | I36: =(H36/100)*1000 -> 0 | K36: =(J36/100)*1000 -> 0 | M36: =(L36/100)*1000 -> 0 | O36: =(N36/100)*1000 -> 0 | Q36: =(P36/100)*1000 -> 0 | S36: =(R36/100)*1000 -> 0 | U36: =(T36/100)*1000 -> 0 | W36: =(V36/100)*1000 -> 0 | Y36: =(X36/100)*1000 -> 0 | AA36: =(Z36/100)*1000 -> 0 | AC36: =(AB36/100)*1000 -> 0 | AE36: =(AD36/100)*1000 -> 0
A37: YENMIX 121 (20KG) | C37: =(B37/100)*1000 -> 0 | E37: =(D37/100)*1000 -> 0 | G37: =(F37/100)*1000 -> 0 | I37: =(H37/100)*1000 -> 0 | K37: =(J37/100)*1000 -> 0 | M37: =(L37/100)*1000 -> 0 | O37: =(N37/100)*1000 -> 0 | Q37: =(P37/100)*1000 -> 0 | S37: =(R37/100)*1000 -> 0 | U37: =(T37/100)*1000 -> 0 | W37: =(V37/100)*1000 -> 0 | Y37: =(X37/100)*1000 -> 0 | AA37: =(Z37/100)*1000 -> 0 | AC37: =(AB37/100)*1000 -> 0 | AE37: =(AD37/100)*1000 -> 0
A38: YENMIX 122 (19.50KG) | C38: =(B38/100)*1000 -> 0 | E38: =(D38/100)*1000 -> 0 | G38: =(F38/100)*1000 -> 0 | I38: =(H38/100)*1000 -> 0 | K38: =(J38/100)*1000 -> 0 | M38: =(L38/100)*1000 -> 0 | O38: =(N38/100)*1000 -> 0 | Q38: =(P38/100)*1000 -> 0 | S38: =(R38/100)*1000 -> 0 | U38: =(T38/100)*1000 -> 0 | W38: =(V38/100)*1000 -> 0 | Y38: =(X38/100)*1000 -> 0 | AA38: =(Z38/100)*1000 -> 0 | AC38: =(AB38/100)*1000 -> 0 | AE38: =(AD38/100)*1000 -> 0
A39: YENMIX 123 (18.90KG) | C39: =(B39/100)*1000 -> 0 | E39: =(D39/100)*1000 -> 0 | G39: =(F39/100)*1000 -> 0 | I39: =(H39/100)*1000 -> 0 | K39: =(J39/100)*1000 -> 0 | M39: =(L39/100)*1000 -> 0 | O39: =(N39/100)*1000 -> 0 | Q39: =(P39/100)*1000 -> 0 | S39: =(R39/100)*1000 -> 0 | U39: =(T39/100)*1000 -> 0 | W39: =(V39/100)*1000 -> 0 | Y39: =(X39/100)*1000 -> 0 | AA39: =(Z39/100)*1000 -> 0 | AC39: =(AB39/100)*1000 -> 0 | AE39: =(AD39/100)*1000 -> 0
A40: YENMIX 122 (20.50KG) | C40: =(B40/100)*1000 -> 0 | E40: =(D40/100)*1000 -> 0 | G40: =(F40/100)*1000 -> 0 | I40: =(H40/100)*1000 -> 0 | K40: =(J40/100)*1000 -> 0 | M40: =(L40/100)*1000 -> 0 | O40: =(N40/100)*1000 -> 0 | Q40: =(P40/100)*1000 -> 0 | S40: =(R40/100)*1000 -> 0 | U40: =(T40/100)*1000 -> 0 | W40: =(V40/100)*1000 -> 0 | Y40: =(X40/100)*1000 -> 0 | AA40: =(Z40/100)*1000 -> 0 | AC40: =(AB40/100)*1000 -> 0 | AE40: =(AD40/100)*1000 -> 0
...

Sheet PRODUCE
B1: MT
B2: =FORMULA!A2 -> 1101 C (STARTER) | R2: =FORMULA!A90 -> 1102 C/P (GROWER) | AH2: =FORMULA!A178 -> 1103 P (FINISHER 1) | AX2: =FORMULA!A266 -> 1104 P (FINISHER 2) | BN2: =FORMULA!A354 -> 8100&8101&8102&8103 (BROILER) | CD2: =FORMULA!A442 -> 121 (BROILER), 311, 312 | CT2: =FORMULA!A530 -> 122 (BROILER), 5201, 5202 | DJ2: =FORMULA!A618 -> 123 (BROILER) | EA2: RAW_M | EB2: =B2 -> 1101 C (STARTER) | ER2: =R2 -> 1102 C/P (GROWER) | FH2: =AH2 -> 1103 P (FINISHER 1) | FX2: =AX2 -> 1104 P (FINISHER 2) | GN2: =BN2 -> 8100&8101&8102&8103 (BROILER) | HD2: =CD2 -> 121 (BROILER), 311, 312 | HT2: =CT2 -> 122 (BROILER), 5201, 5202 | IJ2: =DJ2 -> 123 (BROILER)
B3: =FORMULA!$B$3 -> WS 1101 (251124) | C3: =FORMULA!$D$3 -> WS 1101 (220526) | D3: =FORMULA!$F$3 -> 0 | E3: =FORMULA!$H$3 -> 0 | F3: =FORMULA!$J$3 -> 0 | G3: =FORMULA!$L$3 -> 0 | H3: =FORMULA!$N$3 -> 0 | I3: =FORMULA!$P$3 -> 0 | J3: =FORMULA!$R$3 -> 0 | K3: =FORMULA!$T$3 -> 0 | L3: =FORMULA!$V$3 -> 0 | M3: =FORMULA!$X$3 -> 0 | N3: =FORMULA!$Z$3 -> 0 | O3: =FORMULA!$AB$3 -> 0 | P3: =FORMULA!$AD$3 -> 0 | R3: =FORMULA!$B$91 -> WS 1102 (290825) | S3: =FORMULA!$D$91 -> 0 | T3: =FORMULA!$F$91 -> 0 | U3: =FORMULA!$H$91 -> 0 | V3: =FORMULA!$J$91 -> 0 | W3: =FORMULA!$L$91 -> 0 | X3: =FORMULA!$N$91 -> 0 | Y3: =FORMULA!$P$91 -> 0 | Z3: =FORMULA!$R$91 -> 0 | AA3: =FORMULA!$T$91 -> 0 | AB3: =FORMULA!$V$91 -> 0 | AC3: =FORMULA!$X$91 -> 0 | AD3: =FORMULA!$Z$91 -> 0 | AE3: =FORMULA!$AB$91 -> 0 | AF3: =FORMULA!$AD$91 -> 0 | AH3: =FORMULA!$B$179 -> WS 1103 (290825) | AI3: =FORMULA!$D$179 -> WS 1103 (220526) | AJ3: =FORMULA!$F$179 -> 0 | AK3: =FORMULA!$H$179 -> 0 | AL3: =FORMULA!$J$179 -> 0 | AM3: =FORMULA!$L$179 -> 0 | AN3: =FORMULA!$N$179 -> 0 | AO3: =FORMULA!$P$179 -> 0 | AP3: =FORMULA!$R$179 -> 0 | AQ3: =FORMULA!$T$179 -> 0 | AR3: =FORMULA!$V$179 -> 0 | AS3: =FORMULA!$X$179 -> 0 | AT3: =FORMULA!$Z$179 -> 0 | AU3: =FORMULA!$AB$179 -> 0 | AV3: =FORMULA!$AD$179 -> 0 | AX3: =FORMULA!$B$267 -> 0 | AY3: =FORMULA!$D$267 -> 0 | AZ3: =FORMULA!$F$267 -> 0 | BA3: =FORMULA!$H$267 -> 0 | BB3: =FORMULA!$J$267 -> 0 | BC3: =FORMULA!$L$267 -> 0 | BD3: =FORMULA!$N$267 -> 0 | BE3: =FORMULA!$P$267 -> 0 | BF3: =FORMULA!$R$267 -> 0 | BG3: =FORMULA!$T$267 -> 0 | BH3: =FORMULA!$V$267 -> 0 | BI3: =FORMULA!$X$267 -> 0 | BJ3: =FORMULA!$Z$267 -> 0 | BK3: =FORMULA!$AB$267 -> 0 | BL3: =FORMULA!$AD$267 -> 0 | BN3: =FORMULA!$B$355 -> WS 8100 (290825) | BO3: =FORMULA!$D$355 -> WS 8100 (280426) | BP3: =FORMULA!$F$355 -> 0 | BQ3: =FORMULA!$H$355 -> WS 8102 (290825) | BR3: =FORMULA!$J$355 -> WS 8102 (121225) | BS3: =FORMULA!$L$355 -> WS 8102 (020326) | BT3: =FORMULA!$N$355 -> WS 8102 (020326) | BU3: =FORMULA!$P$355 -> WS 8102 (060526) | BV3: =FORMULA!$R$355 -> WS 8102 (060526) | BW3: =FORMULA!$T$355 -> WS 8103 (070526) | BX3: =FORMULA!$V$355 -> WS 8102 (070526) | BY3: =FORMULA!$X$355 -> WS 8103 (061125) | BZ3: =FORMULA!$Z$355 -> WS 8103 (250226) | CA3: =FORMULA!$AB$355 -> WS 8102 (080526) | CB3: =FORMULA!$AD$355 -> WS 8109 (080526) | CD3: =FORMULA!$B$443 -> YH 121 (050226) | CE3: =FORMULA!$D$443 -> YH 121 (190326) | CF3: =FORMULA!$F$443 -> YH 121 (020426) | CG3: =FORMULA!$H$443 -> 0 | CH3: =FORMULA!$J$443 -> 0 | CI3: =FORMULA!$L$443 -> 0 | CJ3: =FORMULA!$N$443 -> 0 | CK3: =FORMULA!$P$443 -> 0 | CL3: =FORMULA!$R$443 -> 0 | CM3: =FORMULA!$T$443 -> 311 (130526) | CN3: =FORMULA!$V$443 -> 312 (130526) | CO3: =FORMULA!$X$443 -> 0 | CP3: =FORMULA!$Z$443 -> 0 | CQ3: =FORMULA!$AB$443 -> 0 | CR3: =FORMULA!$AD$443 -> 0 | CT3: =FORMULA!$B$531 -> YH 122 (050226) | CU3: =FORMULA!$D$531 -> YH 122 (190326) | CV3: =FORMULA!$F$531 -> YH 122 (200426) | CW3: =FORMULA!$H$531 -> 0 | CX3: =FORMULA!$J$531 -> 0 | CY3: =FORMULA!$L$531 -> 0 | CZ3: =FORMULA!$N$531 -> 5201 (090426) | DA3: =FORMULA!$P$531 -> 5201 (090426) | DB3: =FORMULA!$R$531 -> 0 | DC3: =FORMULA!$T$531 -> 5202 (090426) | DD3: =FORMULA!$V$531 -> 5202 (090426) | DE3: =FORMULA!$X$531 -> 0 | DF3: =FORMULA!$Z$531 -> 5203 (090426) | DG3: =FORMULA!$AB$531 -> 5203 (090426) | DH3: =FORMULA!$AD$531 -> 0 | DJ3: =FORMULA!$B$619 -> YH 123 (050226) | DK3: =FORMULA!$D$619 -> YH 123 (130326) | DL3: =FORMULA!$F$619 -> YH 123 (190326) | DM3: =FORMULA!$H$619 -> YH 123 (200426) | DN3: =FORMULA!$J$619 -> 0 | DO3: =FORMULA!$L$619 -> 0 | DP3: =FORMULA!$N$619 -> 0 | DQ3: =FORMULA!$P$619 -> 0 | DR3: =FORMULA!$R$619 -> 0 | DS3: =FORMULA!$T$619 -> 0 | DT3: =FORMULA!$V$619 -> 0 | DU3: =FORMULA!$X$619 -> 0 | DV3: =FORMULA!$Z$619 -> 0 | DW3: =FORMULA!$AB$619 -> 0 | DX3: =FORMULA!$AD$619 -> 0
A4: JANUARY | B4: =FORMULA!$B$4 -> N01309AY | C4: =FORMULA!$D$4 -> 0 | D4: =FORMULA!$F$4 -> 0 | E4: =FORMULA!$H$4 -> 0 | F4: =FORMULA!$J$4 -> 0 | G4: =FORMULA!$L$4 -> 0 | H4: =FORMULA!$N$4 -> 0 | I4: =FORMULA!$P$4 -> 0 | J4: =FORMULA!$R$4 -> 0 | K4: =FORMULA!$T$4 -> 0 | L4: =FORMULA!$V$4 -> 0 | M4: =FORMULA!$X$4 -> 0 | N4: =FORMULA!$Z$4 -> 0 | O4: =FORMULA!$AB$4 -> 0 | P4: =FORMULA!$AD$4 -> 0 | R4: =FORMULA!$B$92 -> N025-06 | S4: =FORMULA!$D$92 -> 0 | T4: =FORMULA!$F$92 -> 0 | U4: =FORMULA!$H$92 -> 0 | V4: =FORMULA!$J$92 -> 0 | W4: =FORMULA!$L$92 -> 0 | X4: =FORMULA!$N$92 -> 0 | Y4: =FORMULA!$P$92 -> 0 | Z4: =FORMULA!$R$92 -> 0 | AA4: =FORMULA!$T$92 -> 0 | AB4: =FORMULA!$V$92 -> 0 | AC4: =FORMULA!$X$92 -> 0 | AD4: =FORMULA!$Z$92 -> 0 | AE4: =FORMULA!$AB$92 -> 0 | AF4: =FORMULA!$AD$92 -> 0 | AH4: =FORMULA!$B$180 -> N035-06 | AI4: =FORMULA!$D$180 -> WITH 1103 TOP UP | AJ4: =FORMULA!$F$180 -> 0 | AK4: =FORMULA!$H$180 -> 0 | AL4: =FORMULA!$J$180 -> 0 | AM4: =FORMULA!$L$180 -> 0 | AN4: =FORMULA!$N$180 -> 0 | AO4: =FORMULA!$P$180 -> 0 | AP4: =FORMULA!$R$180 -> 0 | AQ4: =FORMULA!$T$180 -> 0 | AR4: =FORMULA!$V$180 -> 0 | AS4: =FORMULA!$X$180 -> 0 | AT4: =FORMULA!$Z$180 -> 0 | AU4: =FORMULA!$AB$180 -> 0 | AV4: =FORMULA!$AD$180 -> 0 | AX4: =FORMULA!$B$268 -> 0 | AY4: =FORMULA!$D$268 -> 0 | AZ4: =FORMULA!$F$268 -> 0 | BA4: =FORMULA!$H$268 -> 0 | BB4: =FORMULA!$J$268 -> 0 | BC4: =FORMULA!$L$268 -> 0 | BD4: =FORMULA!$N$268 -> 0 | BE4: =FORMULA!$P$268 -> 0 | BF4: =FORMULA!$R$268 -> 0 | BG4: =FORMULA!$T$268 -> 0 | BH4: =FORMULA!$V$268 -> 0 | BI4: =FORMULA!$X$268 -> 0 | BJ4: =FORMULA!$Z$268 -> 0 | BK4: =FORMULA!$AB$268 -> 0 | BL4: =FORMULA!$AD$268 -> 0 | BN4: =FORMULA!$B$356 -> NR 14-04 | BO4: =FORMULA!$D$356 -> 0 | BP4: =FORMULA!$F$356 -> 0 | BQ4: =FORMULA!$H$356 -> NR 24-04Z | BR4: =FORMULA!$J$356 -> WITH BMD | BS4: =FORMULA!$L$356 -> 8102 Top Up&PM 8108 | BT4: =FORMULA!$N$356 -> 8102 Top Up&PM 8102 | BU4: =FORMULA!$P$356 -> 8102 Top Up&PM 8102 | BV4: =FORMULA!$R$356 -> 8102 Top Up&PM 8108 | BW4: =FORMULA!$T$356 -> 8103 Top Up&PM 8103 | BX4: =FORMULA!$V$356 -> 8103 Top Up&PM 8109 | BY4: =FORMULA!$X$356 -> NR 34-04 | BZ4: =FORMULA!$Z$356 -> NR 34-04 | CA4: =FORMULA!$AB$356 -> 8102 TOP UP | CB4: =FORMULA!$AD$356 -> 8103 TOP UP | CD4: =FORMULA!$B$444 -> SOYTIDE&TOXISORB | CE4: =FORMULA!$D$444 -> SOYTIDE&TOXIWALL | CF4: =FORMULA!$F$444 -> EP 200&TOXIWALL | CG4: =FORMULA!$H$444 -> 0 | CH4: =FORMULA!$J$444 -> 0 | CI4: =FORMULA!$L$444 -> 0 | CJ4: =FORMULA!$N$444 -> 0 | CK4: =FORMULA!$P$444 -> 0 | CL4: =FORMULA!$R$444 -> 0 | CM4: =FORMULA!$T$444 -> 0 | CN4: =FORMULA!$V$444 -> 0 | CO4: =FORMULA!$X$444 -> 0 | CP4: =FORMULA!$Z$444 -> 0 | CQ4: =FORMULA!$AB$444 -> 0 | CR4: =FORMULA!$AD$444 -> 0 | CT4: =FORMULA!$B$532 -> WITH TOXISORB | CU4: =FORMULA!$D$532 -> WITH TOXIWALL | CV4: =FORMULA!$F$532 -> WITH TOXIWALL, YM 20.50kg | CW4: =FORMULA!$H$532 -> 0 | CX4: =FORMULA!$J$532 -> 0 | CY4: =FORMULA!$L$532 -> 0 | CZ4: =FORMULA!$N$532 -> 0 | DA4: =FORMULA!$P$532 -> REDUCE CORN FOR 2MT | DB4: =FORMULA!$R$532 -> 0 | DC4: =FORMULA!$T$532 -> 0 | DD4: =FORMULA!$V$532 -> K20 | DE4: =FORMULA!$X$532 -> 0 | DF4: =FORMULA!$Z$532 -> ALREADY 2MT | DG4: =FORMULA!$AB$532 -> K21 | DH4: =FORMULA!$AD$532 -> 0 | DJ4: =FORMULA!$B$620 -> WITH TOXISORB | DK4: =FORMULA!$D$620 -> WITHOUT WHEAT POLLARD | DL4: =FORMULA!$F$620 -> WITH TOXIWALL | DM4: =FORMULA!$H$620 -> WITH TOXIWALL, YM 20.00kg | DN4: =FORMULA!$J$620 -> 0 | DO4: =FORMULA!$L$620 -> 0 | DP4: =FORMULA!$N$620 -> 0 | DQ4: =FORMULA!$P$620 -> 0 | DR4: =FORMULA!$R$620 -> 0 | DS4: =FORMULA!$T$620 -> 0 | DT4: =FORMULA!$V$620 -> 0 | DU4: =FORMULA!$X$620 -> 0 | DV4: =FORMULA!$Z$620 -> 0 | DW4: =FORMULA!$AB$620 -> 0 | DX4: =FORMULA!$AD$620 -> 0
A5: ='VAC & MED'!C6 -> 46023 | EB5: =FORMULA!$B$4 -> N01309AY | EC5: =FORMULA!$C$4 -> 0 | ED5: =FORMULA!$F$4 -> 0 | EE5: =FORMULA!$H$4 -> 0 | EF5: =FORMULA!$J$4 -> 0 | EG5: =FORMULA!$L$4 -> 0 | EH5: =FORMULA!$N$4 -> 0 | EI5: =FORMULA!$P$4 -> 0 | EJ5: =FORMULA!$R$4 -> 0 | EK5: =FORMULA!$T$4 -> 0 | EL5: =FORMULA!$V$4 -> 0 | EM5: =FORMULA!$X$4 -> 0 | EN5: =FORMULA!$Z$4 -> 0 | EO5: =FORMULA!$AB$4 -> 0 | EP5: =FORMULA!$AD$4 -> 0 | ER5: =FORMULA!$B$92 -> N025-06 | ES5: =FORMULA!$D$92 -> 0 | ET5: =FORMULA!$F$92 -> 0 | EU5: =FORMULA!$H$92 -> 0 | EV5: =FORMULA!$J$92 -> 0 | EW5: =FORMULA!$L$92 -> 0 | EX5: =FORMULA!$N$92 -> 0 | EY5: =FORMULA!$P$92 -> 0 | EZ5: =FORMULA!$R$92 -> 0 | FA5: =FORMULA!$T$92 -> 0 | FB5: =FORMULA!$V$92 -> 0 | FC5: =FORMULA!$X$92 -> 0 | FD5: =FORMULA!$Z$92 -> 0 | FE5: =FORMULA!$AB$92 -> 0 | FF5: =FORMULA!$AD$92 -> 0 | FH5: =FORMULA!$B$180 -> N035-06 | FI5: =FORMULA!$D$180 -> WITH 1103 TOP UP | FJ5: =FORMULA!$F$180 -> 0 | FK5: =FORMULA!$H$180 -> 0 | FL5: =FORMULA!$J$180 -> 0 | FM5: =FORMULA!$L$180 -> 0 | FN5: =FORMULA!$N$180 -> 0 | FO5: =FORMULA!$P$180 -> 0 | FP5: =FORMULA!$R$180 -> 0 | FQ5: =FORMULA!$T$180 -> 0 | FR5: =FORMULA!$V$180 -> 0 | FS5: =FORMULA!$X$180 -> 0 | FT5: =FORMULA!$Z$180 -> 0 | FU5: =FORMULA!$AB$180 -> 0 | FV5: =FORMULA!$AD$180 -> 0 | FX5: =FORMULA!$B$268 -> 0 | FY5: =FORMULA!$D$268 -> 0 | FZ5: =FORMULA!$F$268 -> 0 | GA5: =FORMULA!$H$268 -> 0 | GB5: =FORMULA!$J$268 -> 0 | GC5: =FORMULA!$L$268 -> 0 | GD5: =FORMULA!$N$268 -> 0 | GE5: =FORMULA!$P$268 -> 0 | GF5: =FORMULA!R$268 -> 0 | GG5: =FORMULA!$T$268 -> 0 | GH5: =FORMULA!$V$268 -> 0 | GI5: =FORMULA!$X$268 -> 0 | GJ5: =FORMULA!$Z$268 -> 0 | GK5: =FORMULA!AB$268 -> 0 | GL5: =FORMULA!AD$268 -> 0 | GN5: =FORMULA!$B$356 -> NR 14-04 | GO5: =FORMULA!$D$356 -> 0 | GP5: =FORMULA!$F$356 -> 0 | GQ5: =FORMULA!$H$356 -> NR 24-04Z | GR5: =FORMULA!$J$356 -> WITH BMD | GS5: =FORMULA!$L$356 -> 8102 Top Up&PM 8108 | GT5: =FORMULA!$N$356 -> 8102 Top Up&PM 8102 | GU5: =FORMULA!$P$356 -> 8102 Top Up&PM 8102 | GV5: =FORMULA!$R$356 -> 8102 Top Up&PM 8108 | GW5: =FORMULA!$T$356 -> 8103 Top Up&PM 8103 | GX5: =FORMULA!$V$356 -> 8103 Top Up&PM 8109 | GY5: =FORMULA!$X$356 -> NR 34-04 | GZ5: =FORMULA!$Z$356 -> NR 34-04 | HA5: =FORMULA!$AB$356 -> 8102 TOP UP | HB5: =FORMULA!$AD$356 -> 8103 TOP UP | HD5: =FORMULA!$B$444 -> SOYTIDE&TOXISORB | HE5: =FORMULA!$D$444 -> SOYTIDE&TOXIWALL | HF5: =FORMULA!$F$444 -> EP 200&TOXIWALL | HG5: =FORMULA!$H$444 -> 0 | HH5: =FORMULA!$J$444 -> 0 | HI5: =FORMULA!$L$444 -> 0 | HJ5: =FORMULA!$N$444 -> 0 | HK5: =FORMULA!$P$444 -> 0 | HL5: =FORMULA!$R$444 -> 0 | HM5: =FORMULA!$T$444 -> 0 | HN5: =FORMULA!$V$444 -> 0 | HO5: =FORMULA!$X$444 -> 0 | HP5: =FORMULA!$Z$444 -> 0 | HQ5: =FORMULA!$AB$444 -> 0 | HR5: =FORMULA!$AD$444 -> 0 | HT5: =FORMULA!$B$532 -> WITH TOXISORB | HU5: =FORMULA!$D$532 -> WITH TOXIWALL | HV5: =FORMULA!$F$532 -> WITH TOXIWALL, YM 20.50kg | HW5: =FORMULA!$H$532 -> 0 | HX5: =FORMULA!$J$532 -> 0 | HY5: =FORMULA!$L$532 -> 0 | HZ5: =FORMULA!$N$532 -> 0 | IA5: =FORMULA!$P$532 -> REDUCE CORN FOR 2MT | IB5: =FORMULA!$R$532 -> 0 | IC5: =FORMULA!$T$532 -> 0 | ID5: =FORMULA!$V$532 -> K20 | IE5: =FORMULA!$X$532 -> 0 | IF5: =FORMULA!$Z$532 -> ALREADY 2MT | IG5: =FORMULA!$AB$532 -> K21 | IH5: =FORMULA!$AD$532 -> 0 | IJ5: =FORMULA!$B$620 -> WITH TOXISORB | IK5: =FORMULA!$D$620 -> WITHOUT WHEAT POLLARD | IL5: =FORMULA!$F$620 -> WITH TOXIWALL | IM5: =FORMULA!$H$620 -> WITH TOXIWALL, YM 20.00kg | IN5: =FORMULA!$J$620 -> 0 | IO5: =FORMULA!$L$620 -> 0 | IP5: =FORMULA!$N$620 -> 0 | IQ5: =FORMULA!$P$620 -> 0 | IR5: =FORMULA!$R$620 -> 0 | IS5: =FORMULA!$T$620 -> 0 | IT5: =FORMULA!$V$620 -> 0 | IU5: =FORMULA!$X$620 -> 0 | IV5: =FORMULA!$Z$620 -> 0 | IW5: =FORMULA!$AB$620 -> 0 | IX5: =FORMULA!$AD$620 -> 0
A6: ='VAC & MED'!C7 -> 46024 | AH6: 40 | BQ6: 28 | EB6: =FORMULA!$B$4 -> N01309AY | EC6: =FORMULA!$B$4 -> N01309AY | ED6: =FORMULA!$B$4 -> N01309AY | EE6: =FORMULA!$H$4 -> 0 | EF6: =FORMULA!$J$4 -> 0 | EG6: =FORMULA!$L$4 -> 0 | EH6: =FORMULA!$N$4 -> 0 | EI6: =FORMULA!$P$4 -> 0 | EJ6: =FORMULA!$R$4 -> 0 | EK6: =FORMULA!$T$4 -> 0 | ER6: =FORMULA!$B$92 -> N025-06 | ES6: =FORMULA!$D$92 -> 0 | ET6: =FORMULA!$F$92 -> 0 | EU6: =FORMULA!$H$92 -> 0 | EV6: =FORMULA!$J$92 -> 0 | EW6: =FORMULA!$L$92 -> 0 | EX6: =FORMULA!$N$92 -> 0 | EY6: =FORMULA!$P$92 -> 0 | EZ6: =FORMULA!$R$92 -> 0 | FA6: =FORMULA!$R$92 -> 0 | FB6: =FORMULA!$R$92 -> 0 | FC6: =FORMULA!$R$92 -> 0 | FD6: =FORMULA!$R$92 -> 0 | FE6: =FORMULA!$R$92 -> 0 | FF6: =FORMULA!$T$92 -> 0 | FH6: =FORMULA!$B$92 -> N025-06 | FI6: =FORMULA!$D$92 -> 0 | FJ6: =FORMULA!$F$92 -> 0 | FK6: =FORMULA!$H$92 -> 0 | FL6: =FORMULA!$J$92 -> 0 | FM6: =FORMULA!$L$92 -> 0 | FN6: =FORMULA!$N$92 -> 0 | FO6: =FORMULA!$P$92 -> 0 | FP6: =FORMULA!$R$92 -> 0 | FQ6: =FORMULA!$R$92 -> 0 | FR6: =FORMULA!$R$92 -> 0 | FS6: =FORMULA!$R$92 -> 0 | FT6: =FORMULA!$R$92 -> 0 | FU6: =FORMULA!$R$92 -> 0 | FV6: =FORMULA!$T$92 -> 0 | FX6: =FORMULA!$B$268 -> 0 | FY6: =FORMULA!$D$268 -> 0 | FZ6: =FORMULA!$F$268 -> 0 | GA6: =FORMULA!$H$268 -> 0 | GB6: =FORMULA!$J$268 -> 0 | GC6: =FORMULA!$L$268 -> 0 | GD6: =FORMULA!$N$268 -> 0 | GE6: =FORMULA!$P$268 -> 0 | GF6: =FORMULA!$R$268 -> 0 | GG6: =FORMULA!$R$268 -> 0 | GH6: =FORMULA!$R$268 -> 0 | GI6: =FORMULA!$R$268 -> 0 | GJ6: =FORMULA!$R$268 -> 0 | GK6: =FORMULA!$R$268 -> 0 | GN6: =FORMULA!$B$268 -> 0 | GO6: =FORMULA!$D$268 -> 0 | GP6: =FORMULA!$F$268 -> 0 | GQ6: =FORMULA!$H$268 -> 0 | GR6: =FORMULA!$J$268 -> 0 | GS6: =FORMULA!$L$268 -> 0 | GT6: =FORMULA!$N$268 -> 0 | GU6: =FORMULA!$P$268 -> 0 | GV6: =FORMULA!$R$268 -> 0 | GW6: =FORMULA!$R$268 -> 0 | GX6: =FORMULA!$R$268 -> 0 | GY6: =FORMULA!$R$268 -> 0 | GZ6: =FORMULA!$R$268 -> 0 | HA6: =FORMULA!$R$268 -> 0 | HB6: =FORMULA!$R$268 -> 0 | HD6: =FORMULA!$B$268 -> 0 | HE6: =FORMULA!$D$268 -> 0 | HF6: =FORMULA!$F$268 -> 0 | HG6: =FORMULA!$H$268 -> 0 | HH6: =FORMULA!$J$268 -> 0 | HI6: =FORMULA!$L$268 -> 0 | HJ6: =FORMULA!$N$268 -> 0 | HK6: =FORMULA!$P$268 -> 0 | HL6: =FORMULA!$R$268 -> 0 | HM6: =FORMULA!$R$268 -> 0 | HN6: =FORMULA!$R$268 -> 0 | HO6: =FORMULA!$R$268 -> 0 | HP6: =FORMULA!$R$268 -> 0 | HQ6: =FORMULA!$R$268 -> 0 | HT6: =FORMULA!$B$268 -> 0 | HU6: =FORMULA!$D$268 -> 0 | HV6: =FORMULA!$F$268 -> 0 | HW6: =FORMULA!$H$268 -> 0 | HX6: =FORMULA!$J$268 -> 0 | HY6: =FORMULA!$L$268 -> 0 | HZ6: =FORMULA!$N$268 -> 0 | IA6: =FORMULA!$P$268 -> 0 | IB6: =FORMULA!$R$268 -> 0 | IC6: =FORMULA!$R$268 -> 0 | ID6: =FORMULA!$R$268 -> 0 | IE6: =FORMULA!$R$268 -> 0 | IF6: =FORMULA!$R$268 -> 0 | IG6: =FORMULA!$R$268 -> 0 | IJ6: =FORMULA!$B$268 -> 0 | IK6: =FORMULA!$D$268 -> 0 | IL6: =FORMULA!$F$268 -> 0 | IM6: =FORMULA!$H$268 -> 0 | IN6: =FORMULA!$J$268 -> 0 | IO6: =FORMULA!$L$268 -> 0 | IP6: =FORMULA!$N$268 -> 0 | IQ6: =FORMULA!$P$268 -> 0 | IR6: =FORMULA!$R$268 -> 0 | IS6: =FORMULA!$R$268 -> 0 | IT6: =FORMULA!$R$268 -> 0 | IU6: =FORMULA!$R$268 -> 0 | IV6: =FORMULA!$R$268 -> 0 | IW6: =FORMULA!$R$268 -> 0
A7: ='VAC & MED'!C8 -> 46025 | AH7: 50 | BQ7: 12 | BR7: 30 | EA7: =FORMULA!$A$6 -> MAIZE/CORN | EB7: =FORMULA!$C$6 -> 535.1 | EC7: =FORMULA!$E$6 -> 568.4 | ED7: =FORMULA!$G$6 -> 0 | EE7: =FORMULA!$I$6 -> 0 | EF7: =FORMULA!$K$6 -> 0 | EG7: =FORMULA!$M$6 -> 0 | EH7: =FORMULA!$O$6 -> 0 | EI7: =FORMULA!$Q$6 -> 0 | EJ7: =FORMULA!$S$6 -> 0 | EK7: =FORMULA!$U$6 -> 0 | EL7: =FORMULA!$W$6 -> 0 | EM7: =FORMULA!$Y$6 -> 0 | EN7: =FORMULA!$AA$6 -> 0 | EO7: =FORMULA!$AC$6 -> 0 | EP7: =FORMULA!$AE$6 -> 0 | ER7: =FORMULA!$C$94 -> 585.5 | ES7: =FORMULA!$E94 -> 0 | ET7: =FORMULA!$G94 -> 0 | EU7: =FORMULA!$I94 -> 0 | EV7: =FORMULA!$K94 -> 0 | EW7: =FORMULA!$M94 -> 0 | EX7: =FORMULA!$O94 -> 0 | EY7: =FORMULA!$Q94 -> 0 | EZ7: =FORMULA!$S94 -> 0 | FA7: =FORMULA!$U94 -> 0 | FB7: =FORMULA!$W94 -> 0 | FC7: =FORMULA!$Y94 -> 0 | FD7: =FORMULA!$AA94 -> 0 | FE7: =FORMULA!$AC94 -> 0 | FF7: =FORMULA!$AE94 -> 0 | FH7: =FORMULA!$C182 -> 627.5 | FI7: =FORMULA!$E182 -> 649.2 | FJ7: =FORMULA!$G182 -> 0 | FK7: =FORMULA!$I182 -> 0 | FL7: =FORMULA!$K182 -> 0 | FM7: =FORMULA!$M182 -> 0 | FN7: =FORMULA!$O182 -> 0 | FO7: =FORMULA!$Q182 -> 0 | FP7: =FORMULA!$S182 -> 0 | FQ7: =FORMULA!$U182 -> 0 | FR7: =FORMULA!$W182 -> 0 | FS7: =FORMULA!$Y182 -> 0 | FT7: =FORMULA!$AA182 -> 0 | FU7: =FORMULA!$AC182 -> 0 | FV7: =FORMULA!$AE182 -> 0 | FX7: =FORMULA!$C270 -> 0 | FY7: =FORMULA!$E270 -> 0 | FZ7: =FORMULA!$G270 -> 0 | GA7: =FORMULA!$I270 -> 0 | GB7: =FORMULA!$K270 -> 0 | GC7: =FORMULA!$M270 -> 0 | GD7: =FORMULA!$O270 -> 0 | GE7: =FORMULA!$Q270 -> 0 | GF7: =FORMULA!$S270 -> 0 | GG7: =FORMULA!$U270 -> 0 | GH7: =FORMULA!$W270 -> 0 | GI7: =FORMULA!$Y270 -> 0 | GJ7: =FORMULA!$AA270 -> 0 | GK7: =FORMULA!$AC270 -> 0 | GL7: =FORMULA!$AE270 -> 0 | GN7: =FORMULA!$C358 -> 539.1 | GO7: =FORMULA!$E358 -> 538.32 | GP7: =FORMULA!$G358 -> 0 | GQ7: =FORMULA!$I358 -> 537.5 | GR7: =FORMULA!$K358 -> 536.5 | GS7: =FORMULA!$M358 -> 506.38 | GT7: =FORMULA!$O358 -> 506.38 | GU7: =FORMULA!$Q358 -> 556.38 | GV7: =FORMULA!$S358 -> 556.38 | GW7: =FORMULA!$U358 -> 557.88 | GX7: =FORMULA!$W358 -> 557.88 | GY7: =FORMULA!$Y358 -> 620.25 | GZ7: =FORMULA!$AA358 -> 620.5 | HA7: =FORMULA!$AC358 -> 555.38 | HB7: =FORMULA!$AE358 -> 555.88 | HD7: =FORMULA!$C446 -> 515.55 | HE7: =FORMULA!$E446 -> 516.55 | HF7: =FORMULA!$G446 -> 519.065 | HG7: =FORMULA!$I446 -> 0 | HH7: =FORMULA!$K446 -> 0 | HI7: =FORMULA!$M446 -> 0 | HJ7: =FORMULA!$O446 -> 0 | HK7: =FORMULA!$Q446 -> 0 | HL7: =FORMULA!$S446 -> 0 | HM7: =FORMULA!$U446 -> 577 | HN7: =FORMULA!$W446 -> 616 | HO7: =FORMULA!$Y446 -> 0 | HP7: =FORMULA!$AA446 -> 0 | HQ7: =FORMULA!$AC446 -> 0 | HR7: =FORMULA!$AE446 -> 0 | HT7: =FORMULA!$C534 -> 501.35 | HU7: =FORMULA!$E534 -> 502.35 | HV7: =FORMULA!$G534 -> 501.35 | HW7: =FORMULA!$I534 -> 0 | HX7: =FORMULA!$K534 -> 0 | HY7: =FORMULA!$M534 -> 0 | HZ7: =FORMULA!$O534 -> 524.85 | IA7: =FORMULA!$Q534 -> 511.25 | IB7: =FORMULA!$S534 -> 0 | IC7: =FORMULA!$U534 -> 545.145 | ID7: =FORMULA!$W534 -> 543.95 | IE7: =FORMULA!$Y534 -> 0 | IF7: =FORMULA!$AA534 -> 614.4 | IG7: =FORMULA!$AC534 -> 606.7 | IH7: =FORMULA!$AE534 -> 0 | IJ7: =FORMULA!$C622 -> 534.6 | IK7: =FORMULA!$E622 -> 501.03 | IL7: =FORMULA!$G622 -> 535.6 | IM7: =FORMULA!$I622 -> 534.5 | IN7: =FORMULA!$K622 -> 0 | IO7: =FORMULA!$M622 -> 0 | IP7: =FORMULA!$O622 -> 0 | IQ7: =FORMULA!$Q622 -> 0 | IR7: =FORMULA!$S622 -> 0 | IS7: =FORMULA!$U622 -> 0 | IT7: =FORMULA!$W622 -> 0 | IU7: =FORMULA!$Y622 -> 0 | IV7: =FORMULA!$AA622 -> 0 | IW7: =FORMULA!$AC622 -> 0 | IX7: =FORMULA!$AE622 -> 0
A8: ='VAC & MED'!C9 -> 46026 | EA8: =FORMULA!$A$7 -> SOYBEAN MEAL (ARG) | EB8: =FORMULA!$C7 -> 326.25 | EC8: =FORMULA!$E7 -> 327.8 | ED8: =FORMULA!$G7 -> 0 | EE8: =FORMULA!$I7 -> 0 | EF8: =FORMULA!$K7 -> 0 | EG8: =FORMULA!$M7 -> 0 | EH8: =FORMULA!$O7 -> 0 | EI8: =FORMULA!$Q7 -> 0 | EJ8: =FORMULA!$S7 -> 0 | EK8: =FORMULA!$U7 -> 0 | EL8: =FORMULA!$W7 -> 0 | EM8: =FORMULA!$Y7 -> 0 | EN8: =FORMULA!$AA7 -> 0 | EO8: =FORMULA!$AC7 -> 0 | EP8: =FORMULA!$AE7 -> 0 | ER8: =FORMULA!$C95 -> 254 | ES8: =FORMULA!$E95 -> 0 | ET8: =FORMULA!$G95 -> 0 | EU8: =FORMULA!$I95 -> 0 | EV8: =FORMULA!$K95 -> 0 | EW8: =FORMULA!$M95 -> 0 | EX8: =FORMULA!$O95 -> 0 | EY8: =FORMULA!$Q95 -> 0 | EZ8: =FORMULA!$S95 -> 0 | FA8: =FORMULA!$U95 -> 0 | FB8: =FORMULA!$W95 -> 0 | FC8: =FORMULA!$Y95 -> 0 | FD8: =FORMULA!$AA95 -> 0 | FE8: =FORMULA!$AC95 -> 0 | FF8: =FORMULA!$AE95 -> 0 | FH8: =FORMULA!$C183 -> 136.5 | FI8: =FORMULA!$E183 -> 161.55 | FJ8: =FORMULA!$G183 -> 0 | FK8: =FORMULA!$I183 -> 0 | FL8: =FORMULA!$K183 -> 0 | FM8: =FORMULA!$M183 -> 0 | FN8: =FORMULA!$O183 -> 0 | FO8: =FORMULA!$Q183 -> 0 | FP8: =FORMULA!$S183 -> 0 | FQ8: =FORMULA!$U183 -> 0 | FR8: =FORMULA!$W183 -> 0 | FS8: =FORMULA!$Y183 -> 0 | FT8: =FORMULA!$AA183 -> 0 | FU8: =FORMULA!$AC183 -> 0 | FV8: =FORMULA!$AE183 -> 0 | FX8: =FORMULA!$C271 -> 0 | FY8: =FORMULA!$E271 -> 0 | FZ8: =FORMULA!$G271 -> 0 | GA8: =FORMULA!$I271 -> 0 | GB8: =FORMULA!$K271 -> 0 | GC8: =FORMULA!$M271 -> 0 | GD8: =FORMULA!$O271 -> 0 | GE8: =FORMULA!$Q271 -> 0 | GF8: =FORMULA!$S271 -> 0 | GG8: =FORMULA!$U271 -> 0 | GH8: =FORMULA!$W271 -> 0 | GI8: =FORMULA!$Y271 -> 0 | GJ8: =FORMULA!$AA271 -> 0 | GK8: =FORMULA!$AC271 -> 0 | GL8: =FORMULA!$AE271 -> 0 | GN8: =FORMULA!$C359 -> 302 | GO8: =FORMULA!$E359 -> 285.6 | GP8: =FORMULA!$G359 -> 0 | GQ8: =FORMULA!$I359 -> 279 | GR8: =FORMULA!$K359 -> 279 | GS8: =FORMULA!$M359 -> 317.2 | GT8: =FORMULA!$O359 -> 317.2 | GU8: =FORMULA!$Q359 -> 317.2 | GV8: =FORMULA!$S359 -> 317.2 | GW8: =FORMULA!$U359 -> 317.2 | GX8: =FORMULA!$W359 -> 317.2 | GY8: =FORMULA!$Y359 -> 201.75 | GZ8: =FORMULA!$AA359 -> 201.5 | HA8: =FORMULA!$AC359 -> 317.2 | HB8: =FORMULA!$AE359 -> 317.2 | HD8: =FORMULA!$C447 -> 238.5 | HE8: =FORMULA!$E447 -> 238.5 | HF8: =FORMULA!$G447 -> 232.335 | HG8: =FORMULA!$I447 -> 0 | HH8: =FORMULA!$K447 -> 0 | HI8: =FORMULA!$M447 -> 0 | HJ8: =FORMULA!$O447 -> 0 | HK8: =FORMULA!$Q447 -> 0 | HL8: =FORMULA!$S447 -> 0 | HM8: =FORMULA!$U447 -> 257 | HN8: =FORMULA!$W447 -> 200 | HO8: =FORMULA!$Y447 -> 0 | HP8: =FORMULA!$AA447 -> 0 | HQ8: =FORMULA!$AC447 -> 0 | HR8: =FORMULA!$AE447 -> 0 | HT8: =FORMULA!$C535 -> 205 | HU8: =FORMULA!$E535 -> 205 | HV8: =FORMULA!$G535 -> 205 | HW8: =FORMULA!$I535 -> 0 | HX8: =FORMULA!$K535 -> 0 | HY8: =FORMULA!$M535 -> 0 | HZ8: =FORMULA!$O535 -> 336.07 | IA8: =FORMULA!$Q535 -> 336.07 | IB8: =FORMULA!$S535 -> 0 | IC8: =FORMULA!$U535 -> 297.485 | ID8: =FORMULA!$W535 -> 297.5 | IE8: =FORMULA!$Y535 -> 0 | IF8: =FORMULA!$AA535 -> 223.8 | IG8: =FORMULA!$AC535 -> 215.6 | IH8: =FORMULA!$AE535 -> 0 | IJ8: =FORMULA!$C623 -> 171.5 | IK8: =FORMULA!$E623 -> 195 | IL8: =FORMULA!$G623 -> 171.5 | IM8: =FORMULA!$I623 -> 171.5 | IN8: =FORMULA!$K623 -> 0 | IO8: =FORMULA!$M623 -> 0 | IP8: =FORMULA!$O623 -> 0 | IQ8: =FORMULA!$Q623 -> 0 | IR8: =FORMULA!$S623 -> 0 | IS8: =FORMULA!$U623 -> 0 | IT8: =FORMULA!$W623 -> 0 | IU8: =FORMULA!$Y623 -> 0 | IV8: =FORMULA!$AA623 -> 0 | IW8: =FORMULA!$AC623 -> 0 | IX8: =FORMULA!$AE623 -> 0
A9: ='VAC & MED'!C10 -> 46027 | BY9: 120 | EA9: =FORMULA!$A$8 -> SOYBEAN FULL FAT | EB9: =FORMULA!$C8 -> 25 | EC9: =FORMULA!$E8 -> 25 | ED9: =FORMULA!$G8 -> 0 | EE9: =FORMULA!$I8 -> 0 | EF9: =FORMULA!$K8 -> 0 | EG9: =FORMULA!$M8 -> 0 | EH9: =FORMULA!$O8 -> 0 | EI9: =FORMULA!$Q8 -> 0 | EJ9: =FORMULA!$S8 -> 0 | EK9: =FORMULA!$U8 -> 0 | EL9: =FORMULA!$W8 -> 0 | EM9: =FORMULA!$Y8 -> 0 | EN9: =FORMULA!$AA8 -> 0 | EO9: =FORMULA!$AC8 -> 0 | EP9: =FORMULA!$AE8 -> 0 | ER9: =FORMULA!$C96 -> 25 | ES9: =FORMULA!$E96 -> 0 | ET9: =FORMULA!$G96 -> 0 | EU9: =FORMULA!$I96 -> 0 | EV9: =FORMULA!$K96 -> 0 | EW9: =FORMULA!$M96 -> 0 | EX9: =FORMULA!$O96 -> 0 | EY9: =FORMULA!$Q96 -> 0 | EZ9: =FORMULA!$S96 -> 0 | FA9: =FORMULA!$U96 -> 0 | FB9: =FORMULA!$W96 -> 0 | FC9: =FORMULA!$Y96 -> 0 | FD9: =FORMULA!$AA96 -> 0 | FE9: =FORMULA!$AC96 -> 0 | FF9: =FORMULA!$AE96 -> 0 | FH9: =FORMULA!$C184 -> 80 | FI9: =FORMULA!$E184 -> 75 | FJ9: =FORMULA!$G184 -> 0 | FK9: =FORMULA!$I184 -> 0 | FL9: =FORMULA!$K184 -> 0 | FM9: =FORMULA!$M184 -> 0 | FN9: =FORMULA!$O184 -> 0 | FO9: =FORMULA!$Q184 -> 0 | FP9: =FORMULA!$S184 -> 0 | FQ9: =FORMULA!$U184 -> 0 | FR9: =FORMULA!$W184 -> 0 | FS9: =FORMULA!$Y184 -> 0 | FT9: =FORMULA!$AA184 -> 0 | FU9: =FORMULA!$AC184 -> 0 | FV9: =FORMULA!$AE184 -> 0 | FX9: =FORMULA!$C272 -> 0 | FY9: =FORMULA!$E272 -> 0 | FZ9: =FORMULA!$G272 -> 0 | GA9: =FORMULA!$I272 -> 0 | GB9: =FORMULA!$K272 -> 0 | GC9: =FORMULA!$M272 -> 0 | GD9: =FORMULA!$O272 -> 0 | GE9: =FORMULA!$Q272 -> 0 | GF9: =FORMULA!$S272 -> 0 | GG9: =FORMULA!$U272 -> 0 | GH9: =FORMULA!$W272 -> 0 | GI9: =FORMULA!$Y272 -> 0 | GJ9: =FORMULA!$AA272 -> 0 | GK9: =FORMULA!$AC272 -> 0 | GL9: =FORMULA!$AE272 -> 0 | GN9: =FORMULA!$C360 -> 50 | GO9: =FORMULA!$E360 -> 50 | GP9: =FORMULA!$G360 -> 0 | GQ9: =FORMULA!$I360 -> 50 | GR9: =FORMULA!$K360 -> 50 | GS9: =FORMULA!$M360 -> 50 | GT9: =FORMULA!$O360 -> 50 | GU9: =FORMULA!$Q360 -> 50 | GV9: =FORMULA!$S360 -> 50 | GW9: =FORMULA!$U360 -> 50 | GX9: =FORMULA!$W360 -> 50 | GY9: =FORMULA!$Y360 -> 45 | GZ9: =FORMULA!$AA360 -> 45 | HA9: =FORMULA!$AC360 -> 50 | HB9: =FORMULA!$AE360 -> 50 | HD9: =FORMULA!$C448 -> 66.5 | HE9: =FORMULA!$E448 -> 66.5 | HF9: =FORMULA!$G448 -> 66.665 | HG9: =FORMULA!$I448 -> 0 | HH9: =FORMULA!$K448 -> 0 | HI9: =FORMULA!$M448 -> 0 | HJ9: =FORMULA!$O448 -> 0 | HK9: =FORMULA!$Q448 -> 0 | HL9: =FORMULA!$S448 -> 0 | HM9: =FORMULA!$U448 -> 30 | HN9: =FORMULA!$W448 -> 40 | HO9: =FORMULA!$Y448 -> 0 | HP9: =FORMULA!$AA448 -> 0 | HQ9: =FORMULA!$AC448 -> 0 | HR9: =FORMULA!$AE448 -> 0 | HT9: =FORMULA!$C536 -> 83.5 | HU9: =FORMULA!$E536 -> 83.5 | HV9: =FORMULA!$G536 -> 83.5 | HW9: =FORMULA!$I536 -> 0 | HX9: =FORMULA!$K536 -> 0 | HY9: =FORMULA!$M536 -> 0 | HZ9: =FORMULA!$O536 -> 50 | IA9: =FORMULA!$Q536 -> 50 | IB9: =FORMULA!$S536 -> 0 | IC9: =FORMULA!$U536 -> 60 | ID9: =FORMULA!$W536 -> 60 | IE9: =FORMULA!$Y536 -> 0 | IF9: =FORMULA!$AA536 -> 70 | IG9: =FORMULA!$AC536 -> 70 | IH9: =FORMULA!$AE536 -> 0 | IJ9: =FORMULA!$C624 -> 85 | IK9: =FORMULA!$E624 -> 100 | IL9: =FORMULA!$G624 -> 85 | IM9: =FORMULA!$I624 -> 85 | IN9: =FORMULA!$K624 -> 0 | IO9: =FORMULA!$M624 -> 0 | IP9: =FORMULA!$O624 -> 0 | IQ9: =FORMULA!$Q624 -> 0 | IR9: =FORMULA!$S624 -> 0 | IS9: =FORMULA!$U624 -> 0 | IT9: =FORMULA!$W624 -> 0 | IU9: =FORMULA!$Y624 -> 0 | IV9: =FORMULA!$AA624 -> 0 | IW9: =FORMULA!$AC624 -> 0 | IX9: =FORMULA!$AE624 -> 0
A10: ='VAC & MED'!C11 -> 46028 | BR10: 70 | BY10: 10 | EA10: =FORMULA!$A$9 -> WHEAT POLLARD | EB10: =FORMULA!$C9 -> 50 | EC10: =FORMULA!$E9 -> 0 | ED10: =FORMULA!$G9 -> 0 | EE10: =FORMULA!$I9 -> 0 | EF10: =FORMULA!$K9 -> 0 | EG10: =FORMULA!$M9 -> 0 | EH10: =FORMULA!$O9 -> 0 | EI10: =FORMULA!$Q9 -> 0 | EJ10: =FORMULA!$S9 -> 0 | EK10: =FORMULA!$U9 -> 0 | EL10: =FORMULA!$W9 -> 0 | EM10: =FORMULA!$Y9 -> 0 | EN10: =FORMULA!$AA9 -> 0 | EO10: =FORMULA!$AC9 -> 0 | EP10: =FORMULA!$AE9 -> 0 | ER10: =FORMULA!$C97 -> 50 | ES10: =FORMULA!$E97 -> 0 | ET10: =FORMULA!$G97 -> 0 | EU10: =FORMULA!$I97 -> 0 | EV10: =FORMULA!$K97 -> 0 | EW10: =FORMULA!$M97 -> 0 | EX10: =FORMULA!$O97 -> 0 | EY10: =FORMULA!$Q97 -> 0 | EZ10: =FORMULA!$S97 -> 0 | FA10: =FORMULA!$U97 -> 0 | FB10: =FORMULA!$W97 -> 0 | FC10: =FORMULA!$Y97 -> 0 | FD10: =FORMULA!$AA97 -> 0 | FE10: =FORMULA!$AC97 -> 0 | FF10: =FORMULA!$AE97 -> 0 | FH10: =FORMULA!$C185 -> 70 | FI10: =FORMULA!$E185 -> 0 | FJ10: =FORMULA!$G185 -> 0 | FK10: =FORMULA!$I185 -> 0 | FL10: =FORMULA!$K185 -> 0 | FM10: =FORMULA!$M185 -> 0 | FN10: =FORMULA!$O185 -> 0 | FO10: =FORMULA!$Q185 -> 0 | FP10: =FORMULA!$S185 -> 0 | FQ10: =FORMULA!$U185 -> 0 | FR10: =FORMULA!$W185 -> 0 | FS10: =FORMULA!$Y185 -> 0 | FT10: =FORMULA!$AA185 -> 0 | FU10: =FORMULA!$AC185 -> 0 | FV10: =FORMULA!$AE185 -> 0 | FX10: =FORMULA!$C273 -> 0 | FY10: =FORMULA!$E273 -> 0 | FZ10: =FORMULA!$G273 -> 0 | GA10: =FORMULA!$I273 -> 0 | GB10: =FORMULA!$K273 -> 0 | GC10: =FORMULA!$M273 -> 0 | GD10: =FORMULA!$O273 -> 0 | GE10: =FORMULA!$Q273 -> 0 | GF10: =FORMULA!$S273 -> 0 | GG10: =FORMULA!$U273 -> 0 | GH10: =FORMULA!$W273 -> 0 | GI10: =FORMULA!$Y273 -> 0 | GJ10: =FORMULA!$AA273 -> 0 | GK10: =FORMULA!$AC273 -> 0 | GL10: =FORMULA!$AE273 -> 0 | GN10: =FORMULA!$C361 -> 25 | GO10: =FORMULA!$E361 -> 0 | GP10: =FORMULA!$G361 -> 0 | GQ10: =FORMULA!$I361 -> 50 | GR10: =FORMULA!$K361 -> 50 | GS10: =FORMULA!$M361 -> 50 | GT10: =FORMULA!$O361 -> 50 | GU10: =FORMULA!$Q361 -> 0 | GV10: =FORMULA!$S361 -> 0 | GW10: =FORMULA!$U361 -> 0 | GX10: =FORMULA!$W361 -> 0 | GY10: =FORMULA!$Y361 -> 20 | GZ10: =FORMULA!$AA361 -> 20 | HA10: =FORMULA!$AC361 -> 0 | HB10: =FORMULA!$AE361 -> 0 | HD10: =FORMULA!$C449 -> 10 | HE10: =FORMULA!$E449 -> 10 | HF10: =FORMULA!$G449 -> 12 | HG10: =FORMULA!$I449 -> 0 | HH10: =FORMULA!$K449 -> 0 | HI10: =FORMULA!$M449 -> 0 | HJ10: =FORMULA!$O449 -> 0 | HK10: =FORMULA!$Q449 -> 0 | HL10: =FORMULA!$S449 -> 0 | HM10: =FORMULA!$U449 -> 20 | HN10: =FORMULA!$W449 -> 20 | HO10: =FORMULA!$Y449 -> 0 | HP10: =FORMULA!$AA449 -> 0 | HQ10: =FORMULA!$AC449 -> 0 | HR10: =FORMULA!$AE449 -> 0 | HT10: =FORMULA!$C537 -> 13 | HU10: =FORMULA!$E537 -> 13 | HV10: =FORMULA!$G537 -> 13 | HW10: =FORMULA!$I537 -> 0 | HX10: =FORMULA!$K537 -> 0 | HY10: =FORMULA!$M537 -> 0 | HZ10: =FORMULA!$O537 -> 0 | IA10: =FORMULA!$Q537 -> 0 | IB10: =FORMULA!$S537 -> 0 | IC10: =FORMULA!$U537 -> 0 | ID10: =FORMULA!$W537 -> 0 | IE10: =FORMULA!$Y537 -> 0 | IF10: =FORMULA!$AA537 -> 0 | IG10: =FORMULA!$AC537 -> 0 | IH10: =FORMULA!$AE537 -> 0 | IJ10: =FORMULA!$C625 -> 12 | IK10: =FORMULA!$E625 -> 0 | IL10: =FORMULA!$G625 -> 12 | IM10: =FORMULA!$I625 -> 12 | IN10: =FORMULA!$K625 -> 0 | IO10: =FORMULA!$M625 -> 0 | IP10: =FORMULA!$O625 -> 0 | IQ10: =FORMULA!$Q625 -> 0 | IR10: =FORMULA!$S625 -> 0 | IS10: =FORMULA!$U625 -> 0 | IT10: =FORMULA!$W625 -> 0 | IU10: =FORMULA!$Y625 -> 0 | IV10: =FORMULA!$AA625 -> 0 | IW10: =FORMULA!$AC625 -> 0 | IX10: =FORMULA!$AE625 -> 0
A11: ='VAC & MED'!C12 -> 46029 | AH11: 10 | BR11: 50 | BY11: 20 | EA11: =FORMULA!$A$10 -> WHEAT | EB11: =FORMULA!$C10 -> 0 | EC11: =FORMULA!$E10 -> 0 | ED11: =FORMULA!$G10 -> 0 | EE11: =FORMULA!$I10 -> 0 | EF11: =FORMULA!$K10 -> 0 | EG11: =FORMULA!$M10 -> 0 | EH11: =FORMULA!$O10 -> 0 | EI11: =FORMULA!$Q10 -> 0 | EJ11: =FORMULA!$S10 -> 0 | EK11: =FORMULA!$U10 -> 0 | EL11: =FORMULA!$W10 -> 0 | EM11: =FORMULA!$Y10 -> 0 | EN11: =FORMULA!$AA10 -> 0 | EO11: =FORMULA!$AC10 -> 0 | EP11: =FORMULA!$AE10 -> 0 | ER11: =FORMULA!$C98 -> 0 | ES11: =FORMULA!$E98 -> 0 | ET11: =FORMULA!$G98 -> 0 | EU11: =FORMULA!$I98 -> 0 | EV11: =FORMULA!$K98 -> 0 | EW11: =FORMULA!$M98 -> 0 | EX11: =FORMULA!$O98 -> 0 | EY11: =FORMULA!$Q98 -> 0 | EZ11: =FORMULA!$S98 -> 0 | FA11: =FORMULA!$U98 -> 0 | FB11: =FORMULA!$W98 -> 0 | FC11: =FORMULA!$Y98 -> 0 | FD11: =FORMULA!$AA98 -> 0 | FE11: =FORMULA!$AC98 -> 0 | FF11: =FORMULA!$AE98 -> 0 | FH11: =FORMULA!$C186 -> 0 | FI11: =FORMULA!$E186 -> 0 | FJ11: =FORMULA!$G186 -> 0 | FK11: =FORMULA!$I186 -> 0 | FL11: =FORMULA!$K186 -> 0 | FM11: =FORMULA!$M186 -> 0 | FN11: =FORMULA!$O186 -> 0 | FO11: =FORMULA!$Q186 -> 0 | FP11: =FORMULA!$S186 -> 0 | FQ11: =FORMULA!$U186 -> 0 | FR11: =FORMULA!$W186 -> 0 | FS11: =FORMULA!$Y186 -> 0 | FT11: =FORMULA!$AA186 -> 0 | FU11: =FORMULA!$AC186 -> 0 | FV11: =FORMULA!$AE186 -> 0 | FX11: =FORMULA!$C274 -> 0 | FY11: =FORMULA!$E274 -> 0 | FZ11: =FORMULA!$G274 -> 0 | GA11: =FORMULA!$I274 -> 0 | GB11: =FORMULA!$K274 -> 0 | GC11: =FORMULA!$M274 -> 0 | GD11: =FORMULA!$O274 -> 0 | GE11: =FORMULA!$Q274 -> 0 | GF11: =FORMULA!$S274 -> 0 | GG11: =FORMULA!$U274 -> 0 | GH11: =FORMULA!$W274 -> 0 | GI11: =FORMULA!$Y274 -> 0 | GJ11: =FORMULA!$AA274 -> 0 | GK11: =FORMULA!$AC274 -> 0 | GL11: =FORMULA!$AE274 -> 0 | GN11: =FORMULA!$C362 -> 0 | GO11: =FORMULA!$E362 -> 0 | GP11: =FORMULA!$G362 -> 0 | GQ11: =FORMULA!$I362 -> 0 | GR11: =FORMULA!$K362 -> 0 | GS11: =FORMULA!$M362 -> 0 | GT11: =FORMULA!$O362 -> 0 | GU11: =FORMULA!$Q362 -> 0 | GV11: =FORMULA!$S362 -> 0 | GW11: =FORMULA!$U362 -> 0 | GX11: =FORMULA!$W362 -> 0 | GY11: =FORMULA!$Y362 -> 0 | GZ11: =FORMULA!$AA362 -> 0 | HA11: =FORMULA!$AC362 -> 0 | HB11: =FORMULA!$AE362 -> 0 | HD11: =FORMULA!$C450 -> 0 | HE11: =FORMULA!$E450 -> 0 | HF11: =FORMULA!$G450 -> 0 | HG11: =FORMULA!$I450 -> 0 | HH11: =FORMULA!$K450 -> 0 | HI11: =FORMULA!$M450 -> 0 | HJ11: =FORMULA!$O450 -> 0 | HK11: =FORMULA!$Q450 -> 0 | HL11: =FORMULA!$S450 -> 0 | HM11: =FORMULA!$U450 -> 0 | HN11: =FORMULA!$W450 -> 0 | HO11: =FORMULA!$Y450 -> 0 | HP11: =FORMULA!$AA450 -> 0 | HQ11: =FORMULA!$AC450 -> 0 | HR11: =FORMULA!$AE450 -> 0 | HT11: =FORMULA!$C538 -> 0 | HU11: =FORMULA!$E538 -> 0 | HV11: =FORMULA!$G538 -> 0 | HW11: =FORMULA!$I538 -> 0 | HX11: =FORMULA!$K538 -> 0 | HY11: =FORMULA!$M538 -> 0 | HZ11: =FORMULA!$O538 -> 0 | IA11: =FORMULA!$Q538 -> 0 | IB11: =FORMULA!$S538 -> 0 | IC11: =FORMULA!$U538 -> 0 | ID11: =FORMULA!$W538 -> 0 | IE11: =FORMULA!$Y538 -> 0 | IF11: =FORMULA!$AA538 -> 0 | IG11: =FORMULA!$AC538 -> 0 | IH11: =FORMULA!$AE538 -> 0 | IJ11: =FORMULA!$C626 -> 0 | IK11: =FORMULA!$E626 -> 0 | IL11: =FORMULA!$G626 -> 0 | IM11: =FORMULA!$I626 -> 0 | IN11: =FORMULA!$K626 -> 0 | IO11: =FORMULA!$M626 -> 0 | IP11: =FORMULA!$O626 -> 0 | IQ11: =FORMULA!$Q626 -> 0 | IR11: =FORMULA!$S626 -> 0 | IS11: =FORMULA!$U626 -> 0 | IT11: =FORMULA!$W626 -> 0 | IU11: =FORMULA!$Y626 -> 0 | IV11: =FORMULA!$AA626 -> 0 | IW11: =FORMULA!$AC626 -> 0 | IX11: =FORMULA!$AE626 -> 0
A12: ='VAC & MED'!C13 -> 46030 | BR12: 30 | EA12: =FORMULA!$A$11 -> MEAT AND BONE MEAL | EB12: =FORMULA!$C11 -> 20 | EC12: =FORMULA!$E11 -> 20.2 | ED12: =FORMULA!$G11 -> 0 | EE12: =FORMULA!$I11 -> 0 | EF12: =FORMULA!$K11 -> 0 | EG12: =FORMULA!$M11 -> 0 | EH12: =FORMULA!$O11 -> 0 | EI12: =FORMULA!$Q11 -> 0 | EJ12: =FORMULA!$S11 -> 0 | EK12: =FORMULA!$U11 -> 0 | EL12: =FORMULA!$W11 -> 0 | EM12: =FORMULA!$Y11 -> 0 | EN12: =FORMULA!$AA11 -> 0 | EO12: =FORMULA!$AC11 -> 0 | EP12: =FORMULA!$AE11 -> 0 | ER12: =FORMULA!$C99 -> 10 | ES12: =FORMULA!$E99 -> 0 | ET12: =FORMULA!$G99 -> 0 | EU12: =FORMULA!$I99 -> 0 | EV12: =FORMULA!$K99 -> 0 | EW12: =FORMULA!$M99 -> 0 | EX12: =FORMULA!$O99 -> 0 | EY12: =FORMULA!$Q99 -> 0 | EZ12: =FORMULA!$S99 -> 0 | FA12: =FORMULA!$U99 -> 0 | FB12: =FORMULA!$W99 -> 0 | FC12: =FORMULA!$Y99 -> 0 | FD12: =FORMULA!$AA99 -> 0 | FE12: =FORMULA!$AC99 -> 0 | FF12: =FORMULA!$AE99 -> 0 | FH12: =FORMULA!$C187 -> 15.5 | FI12: =FORMULA!$E187 -> 15 | FJ12: =FORMULA!$G187 -> 0 | FK12: =FORMULA!$I187 -> 0 | FL12: =FORMULA!$K187 -> 0 | FM12: =FORMULA!$M187 -> 0 | FN12: =FORMULA!$O187 -> 0 | FO12: =FORMULA!$Q187 -> 0 | FP12: =FORMULA!$S187 -> 0 | FQ12: =FORMULA!$U187 -> 0 | FR12: =FORMULA!$W187 -> 0 | FS12: =FORMULA!$Y187 -> 0 | FT12: =FORMULA!$AA187 -> 0 | FU12: =FORMULA!$AC187 -> 0 | FV12: =FORMULA!$AE187 -> 0 | FX12: =FORMULA!$C275 -> 0 | FY12: =FORMULA!$E275 -> 0 | FZ12: =FORMULA!$G275 -> 0 | GA12: =FORMULA!$I275 -> 0 | GB12: =FORMULA!$K275 -> 0 | GC12: =FORMULA!$M275 -> 0 | GD12: =FORMULA!$O275 -> 0 | GE12: =FORMULA!$Q275 -> 0 | GF12: =FORMULA!$S275 -> 0 | GG12: =FORMULA!$U275 -> 0 | GH12: =FORMULA!$W275 -> 0 | GI12: =FORMULA!$Y275 -> 0 | GJ12: =FORMULA!$AA275 -> 0 | GK12: =FORMULA!$AC275 -> 0 | GL12: =FORMULA!$AE275 -> 0 | GN12: =FORMULA!$C363 -> 20 | GO12: =FORMULA!$E363 -> 20 | GP12: =FORMULA!$G363 -> 0 | GQ12: =FORMULA!$I363 -> 20 | GR12: =FORMULA!$K363 -> 20 | GS12: =FORMULA!$M363 -> 0 | GT12: =FORMULA!$O363 -> 0 | GU12: =FORMULA!$Q363 -> 0 | GV12: =FORMULA!$S363 -> 0 | GW12: =FORMULA!$U363 -> 0 | GX12: =FORMULA!$W363 -> 0 | GY12: =FORMULA!$Y363 -> 20 | GZ12: =FORMULA!$AA363 -> 20 | HA12: =FORMULA!$AC363 -> 0 | HB12: =FORMULA!$AE363 -> 0 | HD12: =FORMULA!$C451 -> 25 | HE12: =FORMULA!$E451 -> 25 | HF12: =FORMULA!$G451 -> 25 | HG12: =FORMULA!$I451 -> 0 | HH12: =FORMULA!$K451 -> 0 | HI12: =FORMULA!$M451 -> 0 | HJ12: =FORMULA!$O451 -> 0 | HK12: =FORMULA!$Q451 -> 0 | HL12: =FORMULA!$S451 -> 0 | HM12: =FORMULA!$U451 -> 75 | HN12: =FORMULA!$W451 -> 65 | HO12: =FORMULA!$Y451 -> 0 | HP12: =FORMULA!$AA451 -> 0 | HQ12: =FORMULA!$AC451 -> 0 | HR12: =FORMULA!$AE451 -> 0 | HT12: =FORMULA!$C539 -> 0 | HU12: =FORMULA!$E539 -> 0 | HV12: =FORMULA!$G539 -> 0 | HW12: =FORMULA!$I539 -> 0 | HX12: =FORMULA!$K539 -> 0 | HY12: =FORMULA!$M539 -> 0 | HZ12: =FORMULA!$O539 -> 0 | IA12: =FORMULA!$Q539 -> 0 | IB12: =FORMULA!$S539 -> 0 | IC12: =FORMULA!$U539 -> 0 | ID12: =FORMULA!$W539 -> 0 | IE12: =FORMULA!$Y539 -> 0 | IF12: =FORMULA!$AA539 -> 0 | IG12: =FORMULA!$AC539 -> 0 | IH12: =FORMULA!$AE539 -> 0 | IJ12: =FORMULA!$C627 -> 0 | IK12: =FORMULA!$E627 -> 0 | IL12: =FORMULA!$G627 -> 0 | IM12: =FORMULA!$I627 -> 0 | IN12: =FORMULA!$K627 -> 0 | IO12: =FORMULA!$M627 -> 0 | IP12: =FORMULA!$O627 -> 0 | IQ12: =FORMULA!$Q627 -> 0 | IR12: =FORMULA!$S627 -> 0 | IS12: =FORMULA!$U627 -> 0 | IT12: =FORMULA!$W627 -> 0 | IU12: =FORMULA!$Y627 -> 0 | IV12: =FORMULA!$AA627 -> 0 | IW12: =FORMULA!$AC627 -> 0 | IX12: =FORMULA!$AE627 -> 0
A13: ='VAC & MED'!C14 -> 46031 | BR13: 40 | EA13: =FORMULA!$A$12 -> CORN GLUTEN MEAL | EB13: =FORMULA!$C12 -> 0 | EC13: =FORMULA!$E12 -> 0 | ED13: =FORMULA!$G12 -> 0 | EE13: =FORMULA!$I12 -> 0 | EF13: =FORMULA!$K12 -> 0 | EG13: =FORMULA!$M12 -> 0 | EH13: =FORMULA!$O12 -> 0 | EI13: =FORMULA!$Q12 -> 0 | EJ13: =FORMULA!$S12 -> 0 | EK13: =FORMULA!$U12 -> 0 | EL13: =FORMULA!$W12 -> 0 | EM13: =FORMULA!$Y12 -> 0 | EN13: =FORMULA!$AA12 -> 0 | EO13: =FORMULA!$AC12 -> 0 | EP13: =FORMULA!$AE12 -> 0 | ER13: =FORMULA!$C100 -> 25 | ES13: =FORMULA!$E100 -> 0 | ET13: =FORMULA!$G100 -> 0 | EU13: =FORMULA!$I100 -> 0 | EV13: =FORMULA!$K100 -> 0 | EW13: =FORMULA!$M100 -> 0 | EX13: =FORMULA!$O100 -> 0 | EY13: =FORMULA!$Q100 -> 0 | EZ13: =FORMULA!$S100 -> 0 | FA13: =FORMULA!$U100 -> 0 | FB13: =FORMULA!$W100 -> 0 | FC13: =FORMULA!$Y100 -> 0 | FD13: =FORMULA!$AA100 -> 0 | FE13: =FORMULA!$AC100 -> 0 | FF13: =FORMULA!$AE100 -> 0 | FH13: =FORMULA!$C188 -> 25 | FI13: =FORMULA!$E188 -> 20 | FJ13: =FORMULA!$G188 -> 0 | FK13: =FORMULA!$I188 -> 0 | FL13: =FORMULA!$K188 -> 0 | FM13: =FORMULA!$M188 -> 0 | FN13: =FORMULA!$O188 -> 0 | FO13: =FORMULA!$Q188 -> 0 | FP13: =FORMULA!$S188 -> 0 | FQ13: =FORMULA!$U188 -> 0 | FR13: =FORMULA!$W188 -> 0 | FS13: =FORMULA!$Y188 -> 0 | FT13: =FORMULA!$AA188 -> 0 | FU13: =FORMULA!$AC188 -> 0 | FV13: =FORMULA!$AE188 -> 0 | FX13: =FORMULA!$C276 -> 0 | FY13: =FORMULA!$E276 -> 0 | FZ13: =FORMULA!$G276 -> 0 | GA13: =FORMULA!$I276 -> 0 | GB13: =FORMULA!$K276 -> 0 | GC13: =FORMULA!$M276 -> 0 | GD13: =FORMULA!$O276 -> 0 | GE13: =FORMULA!$Q276 -> 0 | GF13: =FORMULA!$S276 -> 0 | GG13: =FORMULA!$U276 -> 0 | GH13: =FORMULA!$W276 -> 0 | GI13: =FORMULA!$Y276 -> 0 | GJ13: =FORMULA!$AA276 -> 0 | GK13: =FORMULA!$AC276 -> 0 | GL13: =FORMULA!$AE276 -> 0 | GN13: =FORMULA!$C364 -> 20 | GO13: =FORMULA!$E364 -> 15 | GP13: =FORMULA!$G364 -> 0 | GQ13: =FORMULA!$I364 -> 20 | GR13: =FORMULA!$K364 -> 20 | GS13: =FORMULA!$M364 -> 19.5 | GT13: =FORMULA!$O364 -> 19.5 | GU13: =FORMULA!$Q364 -> 19.5 | GV13: =FORMULA!$S364 -> 19.5 | GW13: =FORMULA!$U364 -> 19.5 | GX13: =FORMULA!$W364 -> 19.5 | GY13: =FORMULA!$Y364 -> 20 | GZ13: =FORMULA!$AA364 -> 20 | HA13: =FORMULA!$AC364 -> 19.5 | HB13: =FORMULA!$AE364 -> 19.5 | HD13: =FORMULA!$C452 -> 28 | HE13: =FORMULA!$E452 -> 28 | HF13: =FORMULA!$G452 -> 34 | HG13: =FORMULA!$I452 -> 0 | HH13: =FORMULA!$K452 -> 0 | HI13: =FORMULA!$M452 -> 0 | HJ13: =FORMULA!$O452 -> 0 | HK13: =FORMULA!$Q452 -> 0 | HL13: =FORMULA!$S452 -> 0 | HM13: =FORMULA!$U452 -> 0 | HN13: =FORMULA!$W452 -> 10 | HO13: =FORMULA!$Y452 -> 0 | HP13: =FORMULA!$AA452 -> 0 | HQ13: =FORMULA!$AC452 -> 0 | HR13: =FORMULA!$AE452 -> 0 | HT13: =FORMULA!$C540 -> 42 | HU13: =FORMULA!$E540 -> 42 | HV13: =FORMULA!$G540 -> 42 | HW13: =FORMULA!$I540 -> 0 | HX13: =FORMULA!$K540 -> 0 | HY13: =FORMULA!$M540 -> 0 | HZ13: =FORMULA!$O540 -> 0 | IA13: =FORMULA!$Q540 -> 0 | IB13: =FORMULA!$S540 -> 0 | IC13: =FORMULA!$U540 -> 0 | ID13: =FORMULA!$W540 -> 0 | IE13: =FORMULA!$Y540 -> 0 | IF13: =FORMULA!$AA540 -> 10 | IG13: =FORMULA!$AC540 -> 10 | IH13: =FORMULA!$AE540 -> 0 | IJ13: =FORMULA!$C628 -> 45 | IK13: =FORMULA!$E628 -> 0 | IL13: =FORMULA!$G628 -> 45 | IM13: =FORMULA!$I628 -> 45 | IN13: =FORMULA!$K628 -> 0 | IO13: =FORMULA!$M628 -> 0 | IP13: =FORMULA!$O628 -> 0 | IQ13: =FORMULA!$Q628 -> 0 | IR13: =FORMULA!$S628 -> 0 | IS13: =FORMULA!$U628 -> 0 | IT13: =FORMULA!$W628 -> 0 | IU13: =FORMULA!$Y628 -> 0 | IV13: =FORMULA!$AA628 -> 0 | IW13: =FORMULA!$AC628 -> 0 | IX13: =FORMULA!$AE628 -> 0
A14: ='VAC & MED'!C15 -> 46032 | BN14: 22 | EA14: =FORMULA!$A$13 -> MEGAFAT (HARUMI) | EB14: =FORMULA!$C13 -> 20 | EC14: =FORMULA!$E13 -> 11.5 | ED14: =FORMULA!$G13 -> 0 | EE14: =FORMULA!$I13 -> 0 | EF14: =FORMULA!$K13 -> 0 | EG14: =FORMULA!$M13 -> 0 | EH14: =FORMULA!$O13 -> 0 | EI14: =FORMULA!$Q13 -> 0 | EJ14: =FORMULA!$S13 -> 0 | EK14: =FORMULA!$U13 -> 0 | EL14: =FORMULA!$W13 -> 0 | EM14: =FORMULA!$Y13 -> 0 | EN14: =FORMULA!$AA13 -> 0 | EO14: =FORMULA!$AC13 -> 0 | EP14: =FORMULA!$AE13 -> 0 | ER14: =FORMULA!$C101 -> 25 | ES14: =FORMULA!$E101 -> 0 | ET14: =FORMULA!$G101 -> 0 | EU14: =FORMULA!$I101 -> 0 | EV14: =FORMULA!$K101 -> 0 | EW14: =FORMULA!$M101 -> 0 | EX14: =FORMULA!$O101 -> 0 | EY14: =FORMULA!$Q101 -> 0 | EZ14: =FORMULA!$S101 -> 0 | FA14: =FORMULA!$U101 -> 0 | FB14: =FORMULA!$W101 -> 0 | FC14: =FORMULA!$Y101 -> 0 | FD14: =FORMULA!$AA101 -> 0 | FE14: =FORMULA!$AC101 -> 0 | FF14: =FORMULA!$AE101 -> 0 | FH14: =FORMULA!$C189 -> 25 | FI14: =FORMULA!$E189 -> 27 | FJ14: =FORMULA!$G189 -> 0 | FK14: =FORMULA!$I189 -> 0 | FL14: =FORMULA!$K189 -> 0 | FM14: =FORMULA!$M189 -> 0 | FN14: =FORMULA!$O189 -> 0 | FO14: =FORMULA!$Q189 -> 0 | FP14: =FORMULA!$S189 -> 0 | FQ14: =FORMULA!$U189 -> 0 | FR14: =FORMULA!$W189 -> 0 | FS14: =FORMULA!$Y189 -> 0 | FT14: =FORMULA!$AA189 -> 0 | FU14: =FORMULA!$AC189 -> 0 | FV14: =FORMULA!$AE189 -> 0 | FX14: =FORMULA!$C277 -> 0 | FY14: =FORMULA!$E277 -> 0 | FZ14: =FORMULA!$G277 -> 0 | GA14: =FORMULA!$I277 -> 0 | GB14: =FORMULA!$K277 -> 0 | GC14: =FORMULA!$M277 -> 0 | GD14: =FORMULA!$O277 -> 0 | GE14: =FORMULA!$Q277 -> 0 | GF14: =FORMULA!$S277 -> 0 | GG14: =FORMULA!$U277 -> 0 | GH14: =FORMULA!$W277 -> 0 | GI14: =FORMULA!$Y277 -> 0 | GJ14: =FORMULA!$AA277 -> 0 | GK14: =FORMULA!$AC277 -> 0 | GL14: =FORMULA!$AE277 -> 0 | GN14: =FORMULA!$C365 -> 13 | GO14: =FORMULA!$E365 -> 10 | GP14: =FORMULA!$G365 -> 0 | GQ14: =FORMULA!$I365 -> 20 | GR14: =FORMULA!$K365 -> 20 | GS14: =FORMULA!$M365 -> 23.5 | GT14: =FORMULA!$O365 -> 23.5 | GU14: =FORMULA!$Q365 -> 23.5 | GV14: =FORMULA!$S365 -> 23.5 | GW14: =FORMULA!$U365 -> 23.5 | GX14: =FORMULA!$W365 -> 23.5 | GY14: =FORMULA!$Y365 -> 15 | GZ14: =FORMULA!$AA365 -> 15 | HA14: =FORMULA!$AC365 -> 23.5 | HB14: =FORMULA!$AE365 -> 23.5 | HD14: =FORMULA!$C453 -> 15 | HE14: =FORMULA!$E453 -> 15 | HF14: =FORMULA!$G453 -> 14.665 | HG14: =FORMULA!$I453 -> 0 | HH14: =FORMULA!$K453 -> 0 | HI14: =FORMULA!$M453 -> 0 | HJ14: =FORMULA!$O453 -> 0 | HK14: =FORMULA!$Q453 -> 0 | HL14: =FORMULA!$S453 -> 0 | HM14: =FORMULA!$U453 -> 13 | HN14: =FORMULA!$W453 -> 23 | HO14: =FORMULA!$Y453 -> 0 | HP14: =FORMULA!$AA453 -> 0 | HQ14: =FORMULA!$AC453 -> 0 | HR14: =FORMULA!$AE453 -> 0 | HT14: =FORMULA!$C541 -> 20 | HU14: =FORMULA!$E541 -> 20 | HV14: =FORMULA!$G541 -> 20 | HW14: =FORMULA!$I541 -> 0 | HX14: =FORMULA!$K541 -> 0 | HY14: =FORMULA!$M541 -> 0 | HZ14: =FORMULA!$O541 -> 0 | IA14: =FORMULA!$Q541 -> 0 | IB14: =FORMULA!$S541 -> 0 | IC14: =FORMULA!$U541 -> 5 | ID14: =FORMULA!$W541 -> 5 | IE14: =FORMULA!$Y541 -> 0 | IF14: =FORMULA!$AA541 -> 5 | IG14: =FORMULA!$AC541 -> 5 | IH14: =FORMULA!$AE541 -> 0 | IJ14: =FORMULA!$C629 -> 19.5 | IK14: =FORMULA!$E629 -> 25 | IL14: =FORMULA!$G629 -> 19.5 | IM14: =FORMULA!$I629 -> 19.5 | IN14: =FORMULA!$K629 -> 0 | IO14: =FORMULA!$M629 -> 0 | IP14: =FORMULA!$O629 -> 0 | IQ14: =FORMULA!$Q629 -> 0 | IR14: =FORMULA!$S629 -> 0 | IS14: =FORMULA!$U629 -> 0 | IT14: =FORMULA!$W629 -> 0 | IU14: =FORMULA!$Y629 -> 0 | IV14: =FORMULA!$AA629 -> 0 | IW14: =FORMULA!$AC629 -> 0 | IX14: =FORMULA!$AE629 -> 0
