Workbook
Name WeekHeight: _xlfn.LET( _xlpm.y, IFERROR(--Chart_Y,0), _xlpm.maxY, IFERROR(MAX(_xlpm.y),0), _xlpm.n, ROWS(CHART!WeekSeparator), IF(_xlpm.n=0, NA(), _xlfn.SEQUENCE(_xlpm.n,1,_xlpm.maxY,0)) )
Name WeekPosition: _xlfn.LET( _xlpm.wp, CHART!WeekSeparator, _xlpm.n, ROWS(_xlpm.wp), IF(_xlpm.n<=1, NA(), (_xlfn.TAKE(_xlpm.wp,_xlpm.n-1)+_xlfn.DROP(_xlpm.wp,1))/2 ) )
Name WeekZero: _xlfn.LET( _xlpm.n, ROWS(CHART!WeekSeparator), IF(_xlpm.n=0, NA(), _xlfn.SEQUENCE(_xlpm.n,1,0,0)) )
Name WeekZeroCentre: _xlfn.SEQUENCE(ROWS(CHART!WeekPosition),,0)

Sheet TEMPLATE
A2: HOUSE: | B2: {=MID(CELL("filename",B2),FIND("]",CELL("filename",B2))+1,255)} -> #VALUE!
A3: FEMALE INTAKE: | C3: DEAD ON ARRIVAL:
A4: MALE INTAKE: | C4: DEAD ON ARRIVAL:
A5: INTAKE DATE:
A6: =HYPERLINK("#'" & $B$2 & "'!A11","🔹 Daily") -> #VALUE! | B6: =HYPERLINK("#Dashboard!A1", "📊 Dashboard") -> 📊 Dashboard | C6: WEEKLY ARBOR ACRES | D6: WEEKLY ARBOR ACRES | E6: WEEKLY ARBOR ACRES | F6: WEEKLY ARBOR ACRES | G6: WEEKLY ARBOR ACRES | H6: WEEKLY ARBOR ACRES | I6: WEEKLY ARBOR ACRES | J6: WEEKLY ARBOR ACRES | K6: WEEKLY ARBOR ACRES | L6: WEEKLY ARBOR ACRES | M6: WEEKLY ARBOR ACRES | N6: WEEKLY ARBOR ACRES | O6: WEEKLY ARBOR ACRES | P6: WEEKLY ARBOR ACRES | Q6: WEEKLY ARBOR ACRES | R6: WEEKLY ARBOR ACRES | S6: WEEKLY ARBOR ACRES | T6: WEEKLY ARBOR ACRES | U6: WEEKLY ARBOR ACRES | V6: WEEKLY ARBOR ACRES | W6: WEEKLY ARBOR ACRES | X6: WEEKLY ARBOR ACRES | Y6: WEEKLY ARBOR ACRES | Z6: WEEKLY ARBOR ACRES | AA6: WEEKLY ARBOR ACRES | AB6: WEEKLY ARBOR ACRES | AC6: WEEKLY ARBOR ACRES | AD6: WEEKLY ARBOR ACRES | AE6: WEEKLY ARBOR ACRES | AF6: WEEKLY ARBOR ACRES | AG6: WEEKLY ARBOR ACRES | AH6: WEEKLY ARBOR ACRES
A7: =HYPERLINK("#'" & $B$2 & "'!A508", "📆 Weekly Data") -> #VALUE! | B7: =HYPERLINK("#Chart!A1","📈 Chart") -> 📈 Chart | C7: DEAD MALE | D7: CULL MALE | E7: DEAD FEMALE | F7: CULL FEMALE | G7: START MALE | H7: START FEMALE | I7: END MALE | J7: END FEMALE | K7: CULL MALE% | L7: DEAD MALE% | M7: CULL FEMALE% | N7: DEAD FEMALE% | O7: STANDARD MORTALITY% | P7: MALE FEED (kg) | Q7: FEMALE FEED (kg) | R7: TOTAL FEED (KG) | S7: TOTAL EGGS | T7: WEEKLY EGG PROD% | U7: HEN WEEK PROD. | V7: TOTAL H.E | W7: JUMBO% | X7: SMALL% | Y7: ABNORMAL% | Z7: CRACK% | AA7: H.E% | AB7: EGG WEIGHT (g) | AC7: MALE BW | AD7: MALE UNI% | AE7: FEMALE BW | AF7: FEMALE UNI% | AG7: STD MALE BW | AH7: STD FEMALE BW
C8: DEPLETION | N8: FEED | Y8: EGG PRODUCTION | AL8: BODY WEIGHT | AP8: WATER INTAKE | AW8: TIME | BC8: REMARKS
A9: AGE | B9: DATE | C9: CULL MALE | D9: CULL FEMALE | E9: DEAD MALE | F9: DEAD FEMALE | G9: MALE STOCK | H9: FEMALE STOCK | I9: CULL MALE% | J9: DEAD MALE% | K9: CULL FEMALE% | L9: DEAD FEMALE% | M9: CUM. MALE% | N9: CUM. FEMALE% | O9: STANDARD MORTALITY% | P9: FEED PROGRAM | Q9: GIVEN MALE G/B | R9: GIVEN FEMALE G/B | S9: ACTUAL MALE G/B | T9: ACTUAL FEMALE G/B | U9: MALE TOTAL FEED (kg) | V9: FEMALE TOTAL FEED (kg) | W9: STANDARD MALE FEED | X9: STANDARD FEMALE FEED | Y9: EGG COLLECTED | Z9: JUMBO | AA9: SMALL | AB9: ABNORMAL | AC9: CRACK | AD9: GRAM EGG | AE9: REJECT | AF9: H.E | AG9: EGG PRODUCTION% | AH9: JUMBO% | AI9: SMALL% | AJ9: ABNORMAL% | AK9: CRACK% | AL9: REJECT% | AM9: H.E% | AN9: MALE BODY WEIGHT | AO9: MALE UNIFORMITY | AP9: FEMALE BODY WEIGHT | AQ9: FEMALE UNIFORMITY | AR9: 8AM (m^3) | AS9: 11AM (m^3) | AT9: 5PM (m^3) | AU9: DAILY WATER (L) | AV9: 24H WATER (L) | AW9: WATER:FEED (L/kg) | AX9: WATER/BIRD (ml/bird) | AY9: LIGHT ON | AZ9: LIGHT OFF | BA9: LIGHT DURATION | BB9: FEED START | BC9: FEED END | BD9: FEED DURATION | BE9: REMARKS
A10: 0 | B10: =B5 -> 0 | G10: =B4-D4 -> 0 | H10: =B3-D3 -> 0 | O10: 0.0005
A11: =A10+1.1 -> 1.1 | B11: =B10+1 -> 1 | G11: =G10-E11-C11 -> 0 | H11: =H10-F11-D11 -> 0 | I11: =IFERROR(C11/G10,0) -> 0 | J11: =IFERROR(E11/G10,0) -> 0 | K11: =IFERROR(D11/H10,0) -> 0 | L11: =IFERROR(F11/H10,0) -> 0 | M11: =IF(ROW()=11, IF($B$4>0,E11/$B$4,""), IF($B$4>0, (OFFSET(M11,-1,0)*$B$4 + E11)/$B$4, "") ) | N11: =IF(ROW()=11, IF($B$4>0,F11/$B$4,""), IF($B$4>0, (OFFSET(N11,-1,0)*$B$4 + F11)/$B$4, "") ) | O11: =$O$10 -> 0.0005 | S11: =IF($P11="FULL FEED",Q11,Q11*2) -> 0 | T11: =IF($P11="FULL FEED",R11,R11*2) -> 0 | U11: =IF(P11="FULL FEED",(Q11*G11/1000),(Q11*2*G11/1000)) -> 0 | V11: =IF(P11="FULL FEED",(R11*H11/1000),(R11*2*H11/1000)) -> 0 | AE11: =SUM(Z11,AA11,AB11,AC11) -> 0 | AF11: =Y11-AE11 -> 0 | AG11: =IFERROR(Y11/H10,0) -> 0 | AH11: =IFERROR(Z11/$Y11,0) -> 0 | AI11: =IFERROR(AA11/$Y11,0) -> 0 | AJ11: =IFERROR(AB11/$Y11,0) -> 0 | AK11: =IFERROR(AC11/$Y11,0) -> 0 | AL11: =IFERROR(AE11/Y11,0) -> 0 | AM11: =IFERROR(AF11/Y11,0) -> 0 | AU11: =IF(OR(AT11="",AR11=""),"", (AT11-AR11)/100*1000) | AV11: =IF(OR(AR12="",OFFSET(AR12,-1,0)=""),"", (AR12-OFFSET(AR12,-1,0))/100*1000) | AW11: =IFERROR(IF(OR(AR11="",AT11="",K11="",L11=""),"", ((AT11-AR11)/100*1000)/(U11+V11)),0) | AX11: =IF(OR(AR11="",AR12="",M11="",N11=""),"", ((AR12-AR11)/100*1000)/((G11+H11))*1000) | BA11: =IF(OR(AY11="",AZ11=""),"",MOD(AZ11-AY11,1)*24) | BD11: =IF(OR(BB11="",BC11=""),"",MOD(BC11-BB11,1)*24)
A12: =A11+0.1 -> 1.2 | B12: =B11+1 -> 2 | G12: =G11-E12-C12 -> 0 | H12: =H11-F12-D12 -> 0 | I12: =IFERROR(C12/G11,0) -> 0 | J12: =IFERROR(E12/G11,0) -> 0 | K12: =IFERROR(D12/H11,0) -> 0 | L12: =IFERROR(F12/H11,0) -> 0 | M12: =IF(ROW()=11, IF($B$4>0,E12/$B$4,""), IF($B$4>0, (OFFSET(M12,-1,0)*$B$4 + E12)/$B$4, "") ) | N12: =IF(ROW()=11, IF($B$4>0,F12/$B$4,""), IF($B$4>0, (OFFSET(N12,-1,0)*$B$4 + F12)/$B$4, "") ) | O12: =$O$10 -> 0.0005 | S12: =IF($P12="FULL FEED",Q12,Q12*2) -> 0 | T12: =IF($P12="FULL FEED",R12,R12*2) -> 0 | U12: =IF(P12="FULL FEED",(Q12*G12/1000),(Q12*2*G12/1000)) -> 0 | V12: =IF(P12="FULL FEED",(R12*H12/1000),(R12*2*H12/1000)) -> 0 | AE12: =SUM(Z12,AA12,AB12,AC12) -> 0 | AF12: =Y12-AE12 -> 0 | AG12: =IFERROR(Y12/H11,0) -> 0 | AH12: =IFERROR(Z12/$Y12,0) -> 0 | AI12: =IFERROR(AA12/$Y12,0) -> 0 | AJ12: =IFERROR(AB12/$Y12,0) -> 0 | AK12: =IFERROR(AC12/$Y12,0) -> 0 | AL12: =IFERROR(AE12/Y12,0) -> 0 | AM12: =IFERROR(AF12/Y12,0) -> 0 | AU12: =IF(OR(AT12="",AR12=""),"", (AT12-AR12)/100*1000) | AV12: =IF(OR(AR13="",OFFSET(AR13,-1,0)=""),"", (AR13-OFFSET(AR13,-1,0))/100*1000) | AW12: =IFERROR(IF(OR(AR12="",AT12="",K12="",L12=""),"", ((AT12-AR12)/100*1000)/(U12+V12)),0) | AX12: =IF(OR(AR12="",AR13="",M12="",N12=""),"", ((AR13-AR12)/100*1000)/((G12+H12))*1000) | BA12: =IF(OR(AY12="",AZ12=""),"",MOD(AZ12-AY12,1)*24) | BD12: =IF(OR(BB12="",BC12=""),"",MOD(BC12-BB12,1)*24)
A13: =A12+0.1 -> 1.3 | B13: =B12+1 -> 3 | G13: =G12-E13-C13 -> 0 | H13: =H12-F13-D13 -> 0 | I13: =IFERROR(C13/G12,0) -> 0 | J13: =IFERROR(E13/G12,0) -> 0 | K13: =IFERROR(D13/H12,0) -> 0 | L13: =IFERROR(F13/H12,0) -> 0 | M13: =IF(ROW()=11, IF($B$4>0,E13/$B$4,""), IF($B$4>0, (OFFSET(M13,-1,0)*$B$4 + E13)/$B$4, "") ) | N13: =IF(ROW()=11, IF($B$4>0,F13/$B$4,""), IF($B$4>0, (OFFSET(N13,-1,0)*$B$4 + F13)/$B$4, "") ) | O13: =$O$10 -> 0.0005 | S13: =IF($P13="FULL FEED",Q13,Q13*2) -> 0 | T13: =IF($P13="FULL FEED",R13,R13*2) -> 0 | U13: =IF(P13="FULL FEED",(Q13*G13/1000),(Q13*2*G13/1000)) -> 0 | V13: =IF(P13="FULL FEED",(R13*H13/1000),(R13*2*H13/1000)) -> 0 | AE13: =SUM(Z13,AA13,AB13,AC13) -> 0 | AF13: =Y13-AE13 -> 0 | AG13: =IFERROR(Y13/H12,0) -> 0 | AH13: =IFERROR(Z13/$Y13,0) -> 0 | AI13: =IFERROR(AA13/$Y13,0) -> 0 | AJ13: =IFERROR(AB13/$Y13,0) -> 0 | AK13: =IFERROR(AC13/$Y13,0) -> 0 | AL13: =IFERROR(AE13/Y13,0) -> 0 | AM13: =IFERROR(AF13/Y13,0) -> 0 | AU13: =IF(OR(AT13="",AR13=""),"", (AT13-AR13)/100*1000) | AV13: =IF(OR(AR14="",OFFSET(AR14,-1,0)=""),"", (AR14-OFFSET(AR14,-1,0))/100*1000) | AW13: =IFERROR(IF(OR(AR13="",AT13="",K13="",L13=""),"", ((AT13-AR13)/100*1000)/(U13+V13)),0) | AX13: =IF(OR(AR13="",AR14="",M13="",N13=""),"", ((AR14-AR13)/100*1000)/((G13+H13))*1000) | BA13: =IF(OR(AY13="",AZ13=""),"",MOD(AZ13-AY13,1)*24) | BD13: =IF(OR(BB13="",BC13=""),"",MOD(BC13-BB13,1)*24)
A14: =A13+0.1 -> 1.4 | B14: =B13+1 -> 4 | G14: =G13-E14-C14 -> 0 | H14: =H13-F14-D14 -> 0 | I14: =IFERROR(C14/G13,0) -> 0 | J14: =IFERROR(E14/G13,0) -> 0 | K14: =IFERROR(D14/H13,0) -> 0 | L14: =IFERROR(F14/H13,0) -> 0 | M14: =IF(ROW()=11, IF($B$4>0,E14/$B$4,""), IF($B$4>0, (OFFSET(M14,-1,0)*$B$4 + E14)/$B$4, "") ) | N14: =IF(ROW()=11, IF($B$4>0,F14/$B$4,""), IF($B$4>0, (OFFSET(N14,-1,0)*$B$4 + F14)/$B$4, "") ) | O14: =$O$10 -> 0.0005 | S14: =IF($P14="FULL FEED",Q14,Q14*2) -> 0 | T14: =IF($P14="FULL FEED",R14,R14*2) -> 0 | U14: =IF(P14="FULL FEED",(Q14*G14/1000),(Q14*2*G14/1000)) -> 0 | V14: =IF(P14="FULL FEED",(R14*H14/1000),(R14*2*H14/1000)) -> 0 | AE14: =SUM(Z14,AA14,AB14,AC14) -> 0 | AF14: =Y14-AE14 -> 0 | AG14: =IFERROR(Y14/H13,0) -> 0 | AH14: =IFERROR(Z14/$Y14,0) -> 0 | AI14: =IFERROR(AA14/$Y14,0) -> 0 | AJ14: =IFERROR(AB14/$Y14,0) -> 0 | AK14: =IFERROR(AC14/$Y14,0) -> 0 | AL14: =IFERROR(AE14/Y14,0) -> 0 | AM14: =IFERROR(AF14/Y14,0) -> 0 | AU14: =IF(OR(AT14="",AR14=""),"", (AT14-AR14)/100*1000) | AV14: =IF(OR(AR15="",OFFSET(AR15,-1,0)=""),"", (AR15-OFFSET(AR15,-1,0))/100*1000) | AW14: =IFERROR(IF(OR(AR14="",AT14="",K14="",L14=""),"", ((AT14-AR14)/100*1000)/(U14+V14)),0) | AX14: =IF(OR(AR14="",AR15="",M14="",N14=""),"", ((AR15-AR14)/100*1000)/((G14+H14))*1000) | BA14: =IF(OR(AY14="",AZ14=""),"",MOD(AZ14-AY14,1)*24) | BD14: =IF(OR(BB14="",BC14=""),"",MOD(BC14-BB14,1)*24)
A15: =A14+0.1 -> 1.5 | B15: =B14+1 -> 5 | G15: =G14-E15-C15 -> 0 | H15: =H14-F15-D15 -> 0 | I15: =IFERROR(C15/G14,0) -> 0 | J15: =IFERROR(E15/G14,0) -> 0 | K15: =IFERROR(D15/H14,0) -> 0 | L15: =IFERROR(F15/H14,0) -> 0 | M15: =IF(ROW()=11, IF($B$4>0,E15/$B$4,""), IF($B$4>0, (OFFSET(M15,-1,0)*$B$4 + E15)/$B$4, "") ) | N15: =IF(ROW()=11, IF($B$4>0,F15/$B$4,""), IF($B$4>0, (OFFSET(N15,-1,0)*$B$4 + F15)/$B$4, "") ) | O15: =$O$10 -> 0.0005 | S15: =IF($P15="FULL FEED",Q15,Q15*2) -> 0 | T15: =IF($P15="FULL FEED",R15,R15*2) -> 0 | U15: =IF(P15="FULL FEED",(Q15*G15/1000),(Q15*2*G15/1000)) -> 0 | V15: =IF(P15="FULL FEED",(R15*H15/1000),(R15*2*H15/1000)) -> 0 | AE15: =SUM(Z15,AA15,AB15,AC15) -> 0 | AF15: =Y15-AE15 -> 0 | AG15: =IFERROR(Y15/H14,0) -> 0 | AH15: =IFERROR(Z15/$Y15,0) -> 0 | AI15: =IFERROR(AA15/$Y15,0) -> 0 | AJ15: =IFERROR(AB15/$Y15,0) -> 0 | AK15: =IFERROR(AC15/$Y15,0) -> 0 | AL15: =IFERROR(AE15/Y15,0) -> 0 | AM15: =IFERROR(AF15/Y15,0) -> 0 | AU15: =IF(OR(AT15="",AR15=""),"", (AT15-AR15)/100*1000) | AV15: =IF(OR(AR16="",OFFSET(AR16,-1,0)=""),"", (AR16-OFFSET(AR16,-1,0))/100*1000) | AW15: =IFERROR(IF(OR(AR15="",AT15="",K15="",L15=""),"", ((AT15-AR15)/100*1000)/(U15+V15)),0) | AX15: =IF(OR(AR15="",AR16="",M15="",N15=""),"", ((AR16-AR15)/100*1000)/((G15+H15))*1000) | BA15: =IF(OR(AY15="",AZ15=""),"",MOD(AZ15-AY15,1)*24) | BD15: =IF(OR(BB15="",BC15=""),"",MOD(BC15-BB15,1)*24)
A16: =A15+0.1 -> 1.6 | B16: =B15+1 -> 6 | G16: =G15-E16-C16 -> 0 | H16: =H15-F16-D16 -> 0 | I16: =IFERROR(C16/G15,0) -> 0 | J16: =IFERROR(E16/G15,0) -> 0 | K16: =IFERROR(D16/H15,0) -> 0 | L16: =IFERROR(F16/H15,0) -> 0 | M16: =IF(ROW()=11, IF($B$4>0,E16/$B$4,""), IF($B$4>0, (OFFSET(M16,-1,0)*$B$4 + E16)/$B$4, "") ) | N16: =IF(ROW()=11, IF($B$4>0,F16/$B$4,""), IF($B$4>0, (OFFSET(N16,-1,0)*$B$4 + F16)/$B$4, "") ) | O16: =$O$10 -> 0.0005 | S16: =IF($P16="FULL FEED",Q16,Q16*2) -> 0 | T16: =IF($P16="FULL FEED",R16,R16*2) -> 0 | U16: =IF(P16="FULL FEED",(Q16*G16/1000),(Q16*2*G16/1000)) -> 0 | V16: =IF(P16="FULL FEED",(R16*H16/1000),(R16*2*H16/1000)) -> 0 | AE16: =SUM(Z16,AA16,AB16,AC16) -> 0 | AF16: =Y16-AE16 -> 0 | AG16: =IFERROR(Y16/H15,0) -> 0 | AH16: =IFERROR(Z16/$Y16,0) -> 0 | AI16: =IFERROR(AA16/$Y16,0) -> 0 | AJ16: =IFERROR(AB16/$Y16,0) -> 0 | AK16: =IFERROR(AC16/$Y16,0) -> 0 | AL16: =IFERROR(AE16/Y16,0) -> 0 | AM16: =IFERROR(AF16/Y16,0) -> 0 | AU16: =IF(OR(AT16="",AR16=""),"", (AT16-AR16)/100*1000) | AV16: =IF(OR(AR17="",OFFSET(AR17,-1,0)=""),"", (AR17-OFFSET(AR17,-1,0))/100*1000) | AW16: =IFERROR(IF(OR(AR16="",AT16="",K16="",L16=""),"", ((AT16-AR16)/100*1000)/(U16+V16)),0) | AX16: =IF(OR(AR16="",AR17="",M16="",N16=""),"", ((AR17-AR16)/100*1000)/((G16+H16))*1000) | BA16: =IF(OR(AY16="",AZ16=""),"",MOD(AZ16-AY16,1)*24) | BD16: =IF(OR(BB16="",BC16=""),"",MOD(BC16-BB16,1)*24)
A17: =A16+0.1 -> 1.7 | B17: =B16+1 -> 7 | G17: =G16-E17-C17 -> 0 | H17: =H16-F17-D17 -> 0 | I17: =IFERROR(C17/G16,0) -> 0 | J17: =IFERROR(E17/G16,0) -> 0 | K17: =IFERROR(D17/H16,0) -> 0 | L17: =IFERROR(F17/H16,0) -> 0 | M17: =IF(ROW()=11, IF($B$4>0,E17/$B$4,""), IF($B$4>0, (OFFSET(M17,-1,0)*$B$4 + E17)/$B$4, "") ) | N17: =IF(ROW()=11, IF($B$4>0,F17/$B$4,""), IF($B$4>0, (OFFSET(N17,-1,0)*$B$4 + F17)/$B$4, "") ) | O17: =$O$10 -> 0.0005 | S17: =IF($P17="FULL FEED",Q17,Q17*2) -> 0 | T17: =IF($P17="FULL FEED",R17,R17*2) -> 0 | U17: =IF(P17="FULL FEED",(Q17*G17/1000),(Q17*2*G17/1000)) -> 0 | V17: =IF(P17="FULL FEED",(R17*H17/1000),(R17*2*H17/1000)) -> 0 | AE17: =SUM(Z17,AA17,AB17,AC17) -> 0 | AF17: =Y17-AE17 -> 0 | AG17: =IFERROR(Y17/H16,0) -> 0 | AH17: =IFERROR(Z17/$Y17,0) -> 0 | AI17: =IFERROR(AA17/$Y17,0) -> 0 | AJ17: =IFERROR(AB17/$Y17,0) -> 0 | AK17: =IFERROR(AC17/$Y17,0) -> 0 | AL17: =IFERROR(AE17/Y17,0) -> 0 | AM17: =IFERROR(AF17/Y17,0) -> 0 | AU17: =IF(OR(AT17="",AR17=""),"", (AT17-AR17)/100*1000) | AV17: =IF(OR(AR18="",OFFSET(AR18,-1,0)=""),"", (AR18-OFFSET(AR18,-1,0))/100*1000) | AW17: =IFERROR(IF(OR(AR17="",AT17="",K17="",L17=""),"", ((AT17-AR17)/100*1000)/(U17+V17)),0) | AX17: =IF(OR(AR17="",AR18="",M17="",N17=""),"", ((AR18-AR17)/100*1000)/((G17+H17))*1000) | BA17: =IF(OR(AY17="",AZ17=""),"",MOD(AZ17-AY17,1)*24) | BD17: =IF(OR(BB17="",BC17=""),"",MOD(BC17-BB17,1)*24)
A18: =A11+1 -> 2.1 | B18: =B17+1 -> 8 | G18: =G17-E18-C18 -> 0 | H18: =H17-F18-D18 -> 0 | I18: =IFERROR(C18/G17,0) -> 0 | J18: =IFERROR(E18/G17,0) -> 0 | K18: =IFERROR(D18/H17,0) -> 0 | L18: =IFERROR(F18/H17,0) -> 0 | M18: =IF(ROW()=11, IF($B$4>0,E18/$B$4,""), IF($B$4>0, (OFFSET(M18,-1,0)*$B$4 + E18)/$B$4, "") ) | N18: =IF(ROW()=11, IF($B$4>0,F18/$B$4,""), IF($B$4>0, (OFFSET(N18,-1,0)*$B$4 + F18)/$B$4, "") ) | O18: =$O$10 -> 0.0005 | S18: =IF($P18="FULL FEED",Q18,Q18*2) -> 0 | T18: =IF($P18="FULL FEED",R18,R18*2) -> 0 | U18: =IF(P18="FULL FEED",(Q18*G18/1000),(Q18*2*G18/1000)) -> 0 | V18: =IF(P18="FULL FEED",(R18*H18/1000),(R18*2*H18/1000)) -> 0 | W18: 33 | X18: 20 | AE18: =SUM(Z18,AA18,AB18,AC18) -> 0 | AF18: =Y18-AE18 -> 0 | AG18: =IFERROR(Y18/H17,0) -> 0 | AH18: =IFERROR(Z18/$Y18,0) -> 0 | AI18: =IFERROR(AA18/$Y18,0) -> 0 | AJ18: =IFERROR(AB18/$Y18,0) -> 0 | AK18: =IFERROR(AC18/$Y18,0) -> 0 | AL18: =IFERROR(AE18/Y18,0) -> 0 | AM18: =IFERROR(AF18/Y18,0) -> 0 | AU18: =IF(OR(AT18="",AR18=""),"", (AT18-AR18)/100*1000) | AV18: =IF(OR(AR19="",OFFSET(AR19,-1,0)=""),"", (AR19-OFFSET(AR19,-1,0))/100*1000) | AW18: =IFERROR(IF(OR(AR18="",AT18="",K18="",L18=""),"", ((AT18-AR18)/100*1000)/(U18+V18)),0) | AX18: =IF(OR(AR18="",AR19="",M18="",N18=""),"", ((AR19-AR18)/100*1000)/((G18+H18))*1000) | BA18: =IF(OR(AY18="",AZ18=""),"",MOD(AZ18-AY18,1)*24) | BD18: =IF(OR(BB18="",BC18=""),"",MOD(BC18-BB18,1)*24)
A19: =A12+1 -> 2.2 | B19: =B18+1 -> 9 | G19: =G18-E19-C19 -> 0 | H19: =H18-F19-D19 -> 0 | I19: =IFERROR(C19/G18,0) -> 0 | J19: =IFERROR(E19/G18,0) -> 0 | K19: =IFERROR(D19/H18,0) -> 0 | L19: =IFERROR(F19/H18,0) -> 0 | M19: =IF(ROW()=11, IF($B$4>0,E19/$B$4,""), IF($B$4>0, (OFFSET(M19,-1,0)*$B$4 + E19)/$B$4, "") ) | N19: =IF(ROW()=11, IF($B$4>0,F19/$B$4,""), IF($B$4>0, (OFFSET(N19,-1,0)*$B$4 + F19)/$B$4, "") ) | O19: =$O$10 -> 0.0005 | S19: =IF($P19="FULL FEED",Q19,Q19*2) -> 0 | T19: =IF($P19="FULL FEED",R19,R19*2) -> 0 | U19: =IF(P19="FULL FEED",(Q19*G19/1000),(Q19*2*G19/1000)) -> 0 | V19: =IF(P19="FULL FEED",(R19*H19/1000),(R19*2*H19/1000)) -> 0 | W19: =W18 -> 33 | X19: =X18 -> 20 | AE19: =SUM(Z19,AA19,AB19,AC19) -> 0 | AF19: =Y19-AE19 -> 0 | AG19: =IFERROR(Y19/H18,0) -> 0 | AH19: =IFERROR(Z19/$Y19,0) -> 0 | AI19: =IFERROR(AA19/$Y19,0) -> 0 | AJ19: =IFERROR(AB19/$Y19,0) -> 0 | AK19: =IFERROR(AC19/$Y19,0) -> 0 | AL19: =IFERROR(AE19/Y19,0) -> 0 | AM19: =IFERROR(AF19/Y19,0) -> 0 | AU19: =IF(OR(AT19="",AR19=""),"", (AT19-AR19)/100*1000) | AV19: =IF(OR(AR20="",OFFSET(AR20,-1,0)=""),"", (AR20-OFFSET(AR20,-1,0))/100*1000) | AW19: =IFERROR(IF(OR(AR19="",AT19="",K19="",L19=""),"", ((AT19-AR19)/100*1000)/(U19+V19)),0) | AX19: =IF(OR(AR19="",AR20="",M19="",N19=""),"", ((AR20-AR19)/100*1000)/((G19+H19))*1000) | BA19: =IF(OR(AY19="",AZ19=""),"",MOD(AZ19-AY19,1)*24) | BD19: =IF(OR(BB19="",BC19=""),"",MOD(BC19-BB19,1)*24)
A20: =A13+1 -> 2.3 | B20: =B19+1 -> 10 | G20: =G19-E20-C20 -> 0 | H20: =H19-F20-D20 -> 0 | I20: =IFERROR(C20/G19,0) -> 0 | J20: =IFERROR(E20/G19,0) -> 0 | K20: =IFERROR(D20/H19,0) -> 0 | L20: =IFERROR(F20/H19,0) -> 0 | M20: =IF(ROW()=11, IF($B$4>0,E20/$B$4,""), IF($B$4>0, (OFFSET(M20,-1,0)*$B$4 + E20)/$B$4, "") ) | N20: =IF(ROW()=11, IF($B$4>0,F20/$B$4,""), IF($B$4>0, (OFFSET(N20,-1,0)*$B$4 + F20)/$B$4, "") ) | O20: =$O$10 -> 0.0005 | S20: =IF($P20="FULL FEED",Q20,Q20*2) -> 0 | T20: =IF($P20="FULL FEED",R20,R20*2) -> 0 | U20: =IF(P20="FULL FEED",(Q20*G20/1000),(Q20*2*G20/1000)) -> 0 | V20: =IF(P20="FULL FEED",(R20*H20/1000),(R20*2*H20/1000)) -> 0 | W20: =W19 -> 33 | X20: =X19 -> 20 | AE20: =SUM(Z20,AA20,AB20,AC20) -> 0 | AF20: =Y20-AE20 -> 0 | AG20: =IFERROR(Y20/H19,0) -> 0 | AH20: =IFERROR(Z20/$Y20,0) -> 0 | AI20: =IFERROR(AA20/$Y20,0) -> 0 | AJ20: =IFERROR(AB20/$Y20,0) -> 0 | AK20: =IFERROR(AC20/$Y20,0) -> 0 | AL20: =IFERROR(AE20/Y20,0) -> 0 | AM20: =IFERROR(AF20/Y20,0) -> 0 | AU20: =IF(OR(AT20="",AR20=""),"", (AT20-AR20)/100*1000) | AV20: =IF(OR(AR21="",OFFSET(AR21,-1,0)=""),"", (AR21-OFFSET(AR21,-1,0))/100*1000) | AW20: =IFERROR(IF(OR(AR20="",AT20="",K20="",L20=""),"", ((AT20-AR20)/100*1000)/(U20+V20)),0) | AX20: =IF(OR(AR20="",AR21="",M20="",N20=""),"", ((AR21-AR20)/100*1000)/((G20+H20))*1000) | BA20: =IF(OR(AY20="",AZ20=""),"",MOD(AZ20-AY20,1)*24) | BD20: =IF(OR(BB20="",BC20=""),"",MOD(BC20-BB20,1)*24)
A21: =A14+1 -> 2.4 | B21: =B20+1 -> 11 | G21: =G20-E21-C21 -> 0 | H21: =H20-F21-D21 -> 0 | I21: =IFERROR(C21/G20,0) -> 0 | J21: =IFERROR(E21/G20,0) -> 0 | K21: =IFERROR(D21/H20,0) -> 0 | L21: =IFERROR(F21/H20,0) -> 0 | M21: =IF(ROW()=11, IF($B$4>0,E21/$B$4,""), IF($B$4>0, (OFFSET(M21,-1,0)*$B$4 + E21)/$B$4, "") ) | N21: =IF(ROW()=11, IF($B$4>0,F21/$B$4,""), IF($B$4>0, (OFFSET(N21,-1,0)*$B$4 + F21)/$B$4, "") ) | O21: =$O$10 -> 0.0005 | S21: =IF($P21="FULL FEED",Q21,Q21*2) -> 0 | T21: =IF($P21="FULL FEED",R21,R21*2) -> 0 | U21: =IF(P21="FULL FEED",(Q21*G21/1000),(Q21*2*G21/1000)) -> 0 | V21: =IF(P21="FULL FEED",(R21*H21/1000),(R21*2*H21/1000)) -> 0 | W21: =W20 -> 33 | X21: =X20 -> 20 | AE21: =SUM(Z21,AA21,AB21,AC21) -> 0 | AF21: =Y21-AE21 -> 0 | AG21: =IFERROR(Y21/H20,0) -> 0 | AH21: =IFERROR(Z21/$Y21,0) -> 0 | AI21: =IFERROR(AA21/$Y21,0) -> 0 | AJ21: =IFERROR(AB21/$Y21,0) -> 0 | AK21: =IFERROR(AC21/$Y21,0) -> 0 | AL21: =IFERROR(AE21/Y21,0) -> 0 | AM21: =IFERROR(AF21/Y21,0) -> 0 | AU21: =IF(OR(AT21="",AR21=""),"", (AT21-AR21)/100*1000) | AV21: =IF(OR(AR22="",OFFSET(AR22,-1,0)=""),"", (AR22-OFFSET(AR22,-1,0))/100*1000) | AW21: =IFERROR(IF(OR(AR21="",AT21="",K21="",L21=""),"", ((AT21-AR21)/100*1000)/(U21+V21)),0) | AX21: =IF(OR(AR21="",AR22="",M21="",N21=""),"", ((AR22-AR21)/100*1000)/((G21+H21))*1000) | BA21: =IF(OR(AY21="",AZ21=""),"",MOD(AZ21-AY21,1)*24) | BD21: =IF(OR(BB21="",BC21=""),"",MOD(BC21-BB21,1)*24)
A22: =A15+1 -> 2.5 | B22: =B21+1 -> 12 | G22: =G21-E22-C22 -> 0 | H22: =H21-F22-D22 -> 0 | I22: =IFERROR(C22/G21,0) -> 0 | J22: =IFERROR(E22/G21,0) -> 0 | K22: =IFERROR(D22/H21,0) -> 0 | L22: =IFERROR(F22/H21,0) -> 0 | M22: =IF(ROW()=11, IF($B$4>0,E22/$B$4,""), IF($B$4>0, (OFFSET(M22,-1,0)*$B$4 + E22)/$B$4, "") ) | N22: =IF(ROW()=11, IF($B$4>0,F22/$B$4,""), IF($B$4>0, (OFFSET(N22,-1,0)*$B$4 + F22)/$B$4, "") ) | O22: =$O$10 -> 0.0005 | S22: =IF($P22="FULL FEED",Q22,Q22*2) -> 0 | T22: =IF($P22="FULL FEED",R22,R22*2) -> 0 | U22: =IF(P22="FULL FEED",(Q22*G22/1000),(Q22*2*G22/1000)) -> 0 | V22: =IF(P22="FULL FEED",(R22*H22/1000),(R22*2*H22/1000)) -> 0 | W22: =W21 -> 33 | X22: =X21 -> 20 | AE22: =SUM(Z22,AA22,AB22,AC22) -> 0 | AF22: =Y22-AE22 -> 0 | AG22: =IFERROR(Y22/H21,0) -> 0 | AH22: =IFERROR(Z22/$Y22,0) -> 0 | AI22: =IFERROR(AA22/$Y22,0) -> 0 | AJ22: =IFERROR(AB22/$Y22,0) -> 0 | AK22: =IFERROR(AC22/$Y22,0) -> 0 | AL22: =IFERROR(AE22/Y22,0) -> 0 | AM22: =IFERROR(AF22/Y22,0) -> 0 | AU22: =IF(OR(AT22="",AR22=""),"", (AT22-AR22)/100*1000) | AV22: =IF(OR(AR23="",OFFSET(AR23,-1,0)=""),"", (AR23-OFFSET(AR23,-1,0))/100*1000) | AW22: =IFERROR(IF(OR(AR22="",AT22="",K22="",L22=""),"", ((AT22-AR22)/100*1000)/(U22+V22)),0) | AX22: =IF(OR(AR22="",AR23="",M22="",N22=""),"", ((AR23-AR22)/100*1000)/((G22+H22))*1000) | BA22: =IF(OR(AY22="",AZ22=""),"",MOD(AZ22-AY22,1)*24) | BD22: =IF(OR(BB22="",BC22=""),"",MOD(BC22-BB22,1)*24)
A23: =A16+1 -> 2.6 | B23: =B22+1 -> 13 | G23: =G22-E23-C23 -> 0 | H23: =H22-F23-D23 -> 0 | I23: =IFERROR(C23/G22,0) -> 0 | J23: =IFERROR(E23/G22,0) -> 0 | K23: =IFERROR(D23/H22,0) -> 0 | L23: =IFERROR(F23/H22,0) -> 0 | M23: =IF(ROW()=11, IF($B$4>0,E23/$B$4,""), IF($B$4>0, (OFFSET(M23,-1,0)*$B$4 + E23)/$B$4, "") ) | N23: =IF(ROW()=11, IF($B$4>0,F23/$B$4,""), IF($B$4>0, (OFFSET(N23,-1,0)*$B$4 + F23)/$B$4, "") ) | O23: =$O$10 -> 0.0005 | S23: =IF($P23="FULL FEED",Q23,Q23*2) -> 0 | T23: =IF($P23="FULL FEED",R23,R23*2) -> 0 | U23: =IF(P23="FULL FEED",(Q23*G23/1000),(Q23*2*G23/1000)) -> 0 | V23: =IF(P23="FULL FEED",(R23*H23/1000),(R23*2*H23/1000)) -> 0 | W23: =W22 -> 33 | X23: =X22 -> 20 | AE23: =SUM(Z23,AA23,AB23,AC23) -> 0 | AF23: =Y23-AE23 -> 0 | AG23: =IFERROR(Y23/H22,0) -> 0 | AH23: =IFERROR(Z23/$Y23,0) -> 0 | AI23: =IFERROR(AA23/$Y23,0) -> 0 | AJ23: =IFERROR(AB23/$Y23,0) -> 0 | AK23: =IFERROR(AC23/$Y23,0) -> 0 | AL23: =IFERROR(AE23/Y23,0) -> 0 | AM23: =IFERROR(AF23/Y23,0) -> 0 | AU23: =IF(OR(AT23="",AR23=""),"", (AT23-AR23)/100*1000) | AV23: =IF(OR(AR24="",OFFSET(AR24,-1,0)=""),"", (AR24-OFFSET(AR24,-1,0))/100*1000) | AW23: =IFERROR(IF(OR(AR23="",AT23="",K23="",L23=""),"", ((AT23-AR23)/100*1000)/(U23+V23)),0) | AX23: =IF(OR(AR23="",AR24="",M23="",N23=""),"", ((AR24-AR23)/100*1000)/((G23+H23))*1000) | BA23: =IF(OR(AY23="",AZ23=""),"",MOD(AZ23-AY23,1)*24) | BD23: =IF(OR(BB23="",BC23=""),"",MOD(BC23-BB23,1)*24)
A24: =A17+1 -> 2.7 | B24: =B23+1 -> 14 | G24: =G23-E24-C24 -> 0 | H24: =H23-F24-D24 -> 0 | I24: =IFERROR(C24/G23,0) -> 0 | J24: =IFERROR(E24/G23,0) -> 0 | K24: =IFERROR(D24/H23,0) -> 0 | L24: =IFERROR(F24/H23,0) -> 0 | M24: =IF(ROW()=11, IF($B$4>0,E24/$B$4,""), IF($B$4>0, (OFFSET(M24,-1,0)*$B$4 + E24)/$B$4, "") ) | N24: =IF(ROW()=11, IF($B$4>0,F24/$B$4,""), IF($B$4>0, (OFFSET(N24,-1,0)*$B$4 + F24)/$B$4, "") ) | O24: =$O$10 -> 0.0005 | S24: =IF($P24="FULL FEED",Q24,Q24*2) -> 0 | T24: =IF($P24="FULL FEED",R24,R24*2) -> 0 | U24: =IF(P24="FULL FEED",(Q24*G24/1000),(Q24*2*G24/1000)) -> 0 | V24: =IF(P24="FULL FEED",(R24*H24/1000),(R24*2*H24/1000)) -> 0 | W24: =W23 -> 33 | X24: =X23 -> 20 | AE24: =SUM(Z24,AA24,AB24,AC24) -> 0 | AF24: =Y24-AE24 -> 0 | AG24: =IFERROR(Y24/H23,0) -> 0 | AH24: =IFERROR(Z24/$Y24,0) -> 0 | AI24: =IFERROR(AA24/$Y24,0) -> 0 | AJ24: =IFERROR(AB24/$Y24,0) -> 0 | AK24: =IFERROR(AC24/$Y24,0) -> 0 | AL24: =IFERROR(AE24/Y24,0) -> 0 | AM24: =IFERROR(AF24/Y24,0) -> 0 | AU24: =IF(OR(AT24="",AR24=""),"", (AT24-AR24)/100*1000) | AV24: =IF(OR(AR25="",OFFSET(AR25,-1,0)=""),"", (AR25-OFFSET(AR25,-1,0))/100*1000) | AW24: =IFERROR(IF(OR(AR24="",AT24="",K24="",L24=""),"", ((AT24-AR24)/100*1000)/(U24+V24)),0) | AX24: =IF(OR(AR24="",AR25="",M24="",N24=""),"", ((AR25-AR24)/100*1000)/((G24+H24))*1000) | BA24: =IF(OR(AY24="",AZ24=""),"",MOD(AZ24-AY24,1)*24) | BD24: =IF(OR(BB24="",BC24=""),"",MOD(BC24-BB24,1)*24)
A25: =A18+1 -> 3.1 | B25: =B24+1 -> 15 | G25: =G24-E25-C25 -> 0 | H25: =H24-F25-D25 -> 0 | I25: =IFERROR(C25/G24,0) -> 0 | J25: =IFERROR(E25/G24,0) -> 0 | K25: =IFERROR(D25/H24,0) -> 0 | L25: =IFERROR(F25/H24,0) -> 0 | M25: =IF(ROW()=11, IF($B$4>0,E25/$B$4,""), IF($B$4>0, (OFFSET(M25,-1,0)*$B$4 + E25)/$B$4, "") ) | N25: =IF(ROW()=11, IF($B$4>0,F25/$B$4,""), IF($B$4>0, (OFFSET(N25,-1,0)*$B$4 + F25)/$B$4, "") ) | O25: =$O$10 -> 0.0005 | S25: =IF($P25="FULL FEED",Q25,Q25*2) -> 0 | T25: =IF($P25="FULL FEED",R25,R25*2) -> 0 | U25: =IF(P25="FULL FEED",(Q25*G25/1000),(Q25*2*G25/1000)) -> 0 | V25: =IF(P25="FULL FEED",(R25*H25/1000),(R25*2*H25/1000)) -> 0 | W25: 42 | X25: 26 | AE25: =SUM(Z25,AA25,AB25,AC25) -> 0 | AF25: =Y25-AE25 -> 0 | AG25: =IFERROR(Y25/H24,0) -> 0 | AH25: =IFERROR(Z25/$Y25,0) -> 0 | AI25: =IFERROR(AA25/$Y25,0) -> 0 | AJ25: =IFERROR(AB25/$Y25,0) -> 0 | AK25: =IFERROR(AC25/$Y25,0) -> 0 | AL25: =IFERROR(AE25/Y25,0) -> 0 | AM25: =IFERROR(AF25/Y25,0) -> 0 | AU25: =IF(OR(AT25="",AR25=""),"", (AT25-AR25)/100*1000) | AV25: =IF(OR(AR26="",OFFSET(AR26,-1,0)=""),"", (AR26-OFFSET(AR26,-1,0))/100*1000) | AW25: =IFERROR(IF(OR(AR25="",AT25="",K25="",L25=""),"", ((AT25-AR25)/100*1000)/(U25+V25)),0) | AX25: =IF(OR(AR25="",AR26="",M25="",N25=""),"", ((AR26-AR25)/100*1000)/((G25+H25))*1000) | BA25: =IF(OR(AY25="",AZ25=""),"",MOD(AZ25-AY25,1)*24) | BD25: =IF(OR(BB25="",BC25=""),"",MOD(BC25-BB25,1)*24)
A26: =A19+1 -> 3.2 | B26: =B25+1 -> 16 | G26: =G25-E26-C26 -> 0 | H26: =H25-F26-D26 -> 0 | I26: =IFERROR(C26/G25,0) -> 0 | J26: =IFERROR(E26/G25,0) -> 0 | K26: =IFERROR(D26/H25,0) -> 0 | L26: =IFERROR(F26/H25,0) -> 0 | M26: =IF(ROW()=11, IF($B$4>0,E26/$B$4,""), IF($B$4>0, (OFFSET(M26,-1,0)*$B$4 + E26)/$B$4, "") ) | N26: =IF(ROW()=11, IF($B$4>0,F26/$B$4,""), IF($B$4>0, (OFFSET(N26,-1,0)*$B$4 + F26)/$B$4, "") ) | O26: =$O$10 -> 0.0005 | S26: =IF($P26="FULL FEED",Q26,Q26*2) -> 0 | T26: =IF($P26="FULL FEED",R26,R26*2) -> 0 | U26: =IF(P26="FULL FEED",(Q26*G26/1000),(Q26*2*G26/1000)) -> 0 | V26: =IF(P26="FULL FEED",(R26*H26/1000),(R26*2*H26/1000)) -> 0 | W26: =W25 -> 42 | X26: =X25 -> 26 | AE26: =SUM(Z26,AA26,AB26,AC26) -> 0 | AF26: =Y26-AE26 -> 0 | AG26: =IFERROR(Y26/H25,0) -> 0 | AH26: =IFERROR(Z26/$Y26,0) -> 0 | AI26: =IFERROR(AA26/$Y26,0) -> 0 | AJ26: =IFERROR(AB26/$Y26,0) -> 0 | AK26: =IFERROR(AC26/$Y26,0) -> 0 | AL26: =IFERROR(AE26/Y26,0) -> 0 | AM26: =IFERROR(AF26/Y26,0) -> 0 | AU26: =IF(OR(AT26="",AR26=""),"", (AT26-AR26)/100*1000) | AV26: =IF(OR(AR27="",OFFSET(AR27,-1,0)=""),"", (AR27-OFFSET(AR27,-1,0))/100*1000) | AW26: =IFERROR(IF(OR(AR26="",AT26="",K26="",L26=""),"", ((AT26-AR26)/100*1000)/(U26+V26)),0) | AX26: =IF(OR(AR26="",AR27="",M26="",N26=""),"", ((AR27-AR26)/100*1000)/((G26+H26))*1000) | BA26: =IF(OR(AY26="",AZ26=""),"",MOD(AZ26-AY26,1)*24) | BD26: =IF(OR(BB26="",BC26=""),"",MOD(BC26-BB26,1)*24)
A27: =A20+1 -> 3.3 | B27: =B26+1 -> 17 | G27: =G26-E27-C27 -> 0 | H27: =H26-F27-D27 -> 0 | I27: =IFERROR(C27/G26,0) -> 0 | J27: =IFERROR(E27/G26,0) -> 0 | K27: =IFERROR(D27/H26,0) -> 0 | L27: =IFERROR(F27/H26,0) -> 0 | M27: =IF(ROW()=11, IF($B$4>0,E27/$B$4,""), IF($B$4>0, (OFFSET(M27,-1,0)*$B$4 + E27)/$B$4, "") ) | N27: =IF(ROW()=11, IF($B$4>0,F27/$B$4,""), IF($B$4>0, (OFFSET(N27,-1,0)*$B$4 + F27)/$B$4, "") ) | O27: =$O$10 -> 0.0005 | S27: =IF($P27="FULL FEED",Q27,Q27*2) -> 0 | T27: =IF($P27="FULL FEED",R27,R27*2) -> 0 | U27: =IF(P27="FULL FEED",(Q27*G27/1000),(Q27*2*G27/1000)) -> 0 | V27: =IF(P27="FULL FEED",(R27*H27/1000),(R27*2*H27/1000)) -> 0 | W27: =W26 -> 42 | X27: =X26 -> 26 | AE27: =SUM(Z27,AA27,AB27,AC27) -> 0 | AF27: =Y27-AE27 -> 0 | AG27: =IFERROR(Y27/H26,0) -> 0 | AH27: =IFERROR(Z27/$Y27,0) -> 0 | AI27: =IFERROR(AA27/$Y27,0) -> 0 | AJ27: =IFERROR(AB27/$Y27,0) -> 0 | AK27: =IFERROR(AC27/$Y27,0) -> 0 | AL27: =IFERROR(AE27/Y27,0) -> 0 | AM27: =IFERROR(AF27/Y27,0) -> 0 | AU27: =IF(OR(AT27="",AR27=""),"", (AT27-AR27)/100*1000) | AV27: =IF(OR(AR28="",OFFSET(AR28,-1,0)=""),"", (AR28-OFFSET(AR28,-1,0))/100*1000) | AW27: =IFERROR(IF(OR(AR27="",AT27="",K27="",L27=""),"", ((AT27-AR27)/100*1000)/(U27+V27)),0) | AX27: =IF(OR(AR27="",AR28="",M27="",N27=""),"", ((AR28-AR27)/100*1000)/((G27+H27))*1000) | BA27: =IF(OR(AY27="",AZ27=""),"",MOD(AZ27-AY27,1)*24) | BD27: =IF(OR(BB27="",BC27=""),"",MOD(BC27-BB27,1)*24)
A28: =A21+1 -> 3.4 | B28: =B27+1 -> 18 | G28: =G27-E28-C28 -> 0 | H28: =H27-F28-D28 -> 0 | I28: =IFERROR(C28/G27,0) -> 0 | J28: =IFERROR(E28/G27,0) -> 0 | K28: =IFERROR(D28/H27,0) -> 0 | L28: =IFERROR(F28/H27,0) -> 0 | M28: =IF(ROW()=11, IF($B$4>0,E28/$B$4,""), IF($B$4>0, (OFFSET(M28,-1,0)*$B$4 + E28)/$B$4, "") ) | N28: =IF(ROW()=11, IF($B$4>0,F28/$B$4,""), IF($B$4>0, (OFFSET(N28,-1,0)*$B$4 + F28)/$B$4, "") ) | O28: =$O$10 -> 0.0005 | S28: =IF($P28="FULL FEED",Q28,Q28*2) -> 0 | T28: =IF($P28="FULL FEED",R28,R28*2) -> 0 | U28: =IF(P28="FULL FEED",(Q28*G28/1000),(Q28*2*G28/1000)) -> 0 | V28: =IF(P28="FULL FEED",(R28*H28/1000),(R28*2*H28/1000)) -> 0 | W28: =W27 -> 42 | X28: =X27 -> 26 | AE28: =SUM(Z28,AA28,AB28,AC28) -> 0 | AF28: =Y28-AE28 -> 0 | AG28: =IFERROR(Y28/H27,0) -> 0 | AH28: =IFERROR(Z28/$Y28,0) -> 0 | AI28: =IFERROR(AA28/$Y28,0) -> 0 | AJ28: =IFERROR(AB28/$Y28,0) -> 0 | AK28: =IFERROR(AC28/$Y28,0) -> 0 | AL28: =IFERROR(AE28/Y28,0) -> 0 | AM28: =IFERROR(AF28/Y28,0) -> 0 | AU28: =IF(OR(AT28="",AR28=""),"", (AT28-AR28)/100*1000) | AV28: =IF(OR(AR29="",OFFSET(AR29,-1,0)=""),"", (AR29-OFFSET(AR29,-1,0))/100*1000) | AW28: =IFERROR(IF(OR(AR28="",AT28="",K28="",L28=""),"", ((AT28-AR28)/100*1000)/(U28+V28)),0) | AX28: =IF(OR(AR28="",AR29="",M28="",N28=""),"", ((AR29-AR28)/100*1000)/((G28+H28))*1000) | BA28: =IF(OR(AY28="",AZ28=""),"",MOD(AZ28-AY28,1)*24) | BD28: =IF(OR(BB28="",BC28=""),"",MOD(BC28-BB28,1)*24)
A29: =A22+1 -> 3.5 | B29: =B28+1 -> 19 | G29: =G28-E29-C29 -> 0 | H29: =H28-F29-D29 -> 0 | I29: =IFERROR(C29/G28,0) -> 0 | J29: =IFERROR(E29/G28,0) -> 0 | K29: =IFERROR(D29/H28,0) -> 0 | L29: =IFERROR(F29/H28,0) -> 0 | M29: =IF(ROW()=11, IF($B$4>0,E29/$B$4,""), IF($B$4>0, (OFFSET(M29,-1,0)*$B$4 + E29)/$B$4, "") ) | N29: =IF(ROW()=11, IF($B$4>0,F29/$B$4,""), IF($B$4>0, (OFFSET(N29,-1,0)*$B$4 + F29)/$B$4, "") ) | O29: =$O$10 -> 0.0005 | S29: =IF($P29="FULL FEED",Q29,Q29*2) -> 0 | T29: =IF($P29="FULL FEED",R29,R29*2) -> 0 | U29: =IF(P29="FULL FEED",(Q29*G29/1000),(Q29*2*G29/1000)) -> 0 | V29: =IF(P29="FULL FEED",(R29*H29/1000),(R29*2*H29/1000)) -> 0 | W29: =W28 -> 42 | X29: =X28 -> 26 | AE29: =SUM(Z29,AA29,AB29,AC29) -> 0 | AF29: =Y29-AE29 -> 0 | AG29: =IFERROR(Y29/H28,0) -> 0 | AH29: =IFERROR(Z29/$Y29,0) -> 0 | AI29: =IFERROR(AA29/$Y29,0) -> 0 | AJ29: =IFERROR(AB29/$Y29,0) -> 0 | AK29: =IFERROR(AC29/$Y29,0) -> 0 | AL29: =IFERROR(AE29/Y29,0) -> 0 | AM29: =IFERROR(AF29/Y29,0) -> 0 | AU29: =IF(OR(AT29="",AR29=""),"", (AT29-AR29)/100*1000) | AV29: =IF(OR(AR30="",OFFSET(AR30,-1,0)=""),"", (AR30-OFFSET(AR30,-1,0))/100*1000) | AW29: =IFERROR(IF(OR(AR29="",AT29="",K29="",L29=""),"", ((AT29-AR29)/100*1000)/(U29+V29)),0) | AX29: =IF(OR(AR29="",AR30="",M29="",N29=""),"", ((AR30-AR29)/100*1000)/((G29+H29))*1000) | BA29: =IF(OR(AY29="",AZ29=""),"",MOD(AZ29-AY29,1)*24) | BD29: =IF(OR(BB29="",BC29=""),"",MOD(BC29-BB29,1)*24)
A30: =A23+1 -> 3.6 | B30: =B29+1 -> 20 | G30: =G29-E30-C30 -> 0 | H30: =H29-F30-D30 -> 0 | I30: =IFERROR(C30/G29,0) -> 0 | J30: =IFERROR(E30/G29,0) -> 0 | K30: =IFERROR(D30/H29,0) -> 0 | L30: =IFERROR(F30/H29,0) -> 0 | M30: =IF(ROW()=11, IF($B$4>0,E30/$B$4,""), IF($B$4>0, (OFFSET(M30,-1,0)*$B$4 + E30)/$B$4, "") ) | N30: =IF(ROW()=11, IF($B$4>0,F30/$B$4,""), IF($B$4>0, (OFFSET(N30,-1,0)*$B$4 + F30)/$B$4, "") ) | O30: =$O$10 -> 0.0005 | S30: =IF($P30="FULL FEED",Q30,Q30*2) -> 0 | T30: =IF($P30="FULL FEED",R30,R30*2) -> 0 | U30: =IF(P30="FULL FEED",(Q30*G30/1000),(Q30*2*G30/1000)) -> 0 | V30: =IF(P30="FULL FEED",(R30*H30/1000),(R30*2*H30/1000)) -> 0 | W30: =W29 -> 42 | X30: =X29 -> 26 | AE30: =SUM(Z30,AA30,AB30,AC30) -> 0 | AF30: =Y30-AE30 -> 0 | AG30: =IFERROR(Y30/H29,0) -> 0 | AH30: =IFERROR(Z30/$Y30,0) -> 0 | AI30: =IFERROR(AA30/$Y30,0) -> 0 | AJ30: =IFERROR(AB30/$Y30,0) -> 0 | AK30: =IFERROR(AC30/$Y30,0) -> 0 | AL30: =IFERROR(AE30/Y30,0) -> 0 | AM30: =IFERROR(AF30/Y30,0) -> 0 | AU30: =IF(OR(AT30="",AR30=""),"", (AT30-AR30)/100*1000) | AV30: =IF(OR(AR31="",OFFSET(AR31,-1,0)=""),"", (AR31-OFFSET(AR31,-1,0))/100*1000) | AW30: =IFERROR(IF(OR(AR30="",AT30="",K30="",L30=""),"", ((AT30-AR30)/100*1000)/(U30+V30)),0) | AX30: =IF(OR(AR30="",AR31="",M30="",N30=""),"", ((AR31-AR30)/100*1000)/((G30+H30))*1000) | BA30: =IF(OR(AY30="",AZ30=""),"",MOD(AZ30-AY30,1)*24) | BD30: =IF(OR(BB30="",BC30=""),"",MOD(BC30-BB30,1)*24)
A31: =A24+1 -> 3.7 | B31: =B30+1 -> 21 | G31: =G30-E31-C31 -> 0 | H31: =H30-F31-D31 -> 0 | I31: =IFERROR(C31/G30,0) -> 0 | J31: =IFERROR(E31/G30,0) -> 0 | K31: =IFERROR(D31/H30,0) -> 0 | L31: =IFERROR(F31/H30,0) -> 0 | M31: =IF(ROW()=11, IF($B$4>0,E31/$B$4,""), IF($B$4>0, (OFFSET(M31,-1,0)*$B$4 + E31)/$B$4, "") ) | N31: =IF(ROW()=11, IF($B$4>0,F31/$B$4,""), IF($B$4>0, (OFFSET(N31,-1,0)*$B$4 + F31)/$B$4, "") ) | O31: =$O$10 -> 0.0005 | S31: =IF($P31="FULL FEED",Q31,Q31*2) -> 0 | T31: =IF($P31="FULL FEED",R31,R31*2) -> 0 | U31: =IF(P31="FULL FEED",(Q31*G31/1000),(Q31*2*G31/1000)) -> 0 | V31: =IF(P31="FULL FEED",(R31*H31/1000),(R31*2*H31/1000)) -> 0 | W31: =W30 -> 42 | X31: =X30 -> 26 | AE31: =SUM(Z31,AA31,AB31,AC31) -> 0 | AF31: =Y31-AE31 -> 0 | AG31: =IFERROR(Y31/H30,0) -> 0 | AH31: =IFERROR(Z31/$Y31,0) -> 0 | AI31: =IFERROR(AA31/$Y31,0) -> 0 | AJ31: =IFERROR(AB31/$Y31,0) -> 0 | AK31: =IFERROR(AC31/$Y31,0) -> 0 | AL31: =IFERROR(AE31/Y31,0) -> 0 | AM31: =IFERROR(AF31/Y31,0) -> 0 | AU31: =IF(OR(AT31="",AR31=""),"", (AT31-AR31)/100*1000) | AV31: =IF(OR(AR32="",OFFSET(AR32,-1,0)=""),"", (AR32-OFFSET(AR32,-1,0))/100*1000) | AW31: =IFERROR(IF(OR(AR31="",AT31="",K31="",L31=""),"", ((AT31-AR31)/100*1000)/(U31+V31)),0) | AX31: =IF(OR(AR31="",AR32="",M31="",N31=""),"", ((AR32-AR31)/100*1000)/((G31+H31))*1000) | BA31: =IF(OR(AY31="",AZ31=""),"",MOD(AZ31-AY31,1)*24) | BD31: =IF(OR(BB31="",BC31=""),"",MOD(BC31-BB31,1)*24)
A32: =A25+1 -> 4.1 | B32: =B31+1 -> 22 | G32: =G31-E32-C32 -> 0 | H32: =H31-F32-D32 -> 0 | I32: =IFERROR(C32/G31,0) -> 0 | J32: =IFERROR(E32/G31,0) -> 0 | K32: =IFERROR(D32/H31,0) -> 0 | L32: =IFERROR(F32/H31,0) -> 0 | M32: =IF(ROW()=11, IF($B$4>0,E32/$B$4,""), IF($B$4>0, (OFFSET(M32,-1,0)*$B$4 + E32)/$B$4, "") ) | N32: =IF(ROW()=11, IF($B$4>0,F32/$B$4,""), IF($B$4>0, (OFFSET(N32,-1,0)*$B$4 + F32)/$B$4, "") ) | O32: =$O$10 -> 0.0005 | S32: =IF($P32="FULL FEED",Q32,Q32*2) -> 0 | T32: =IF($P32="FULL FEED",R32,R32*2) -> 0 | U32: =IF(P32="FULL FEED",(Q32*G32/1000),(Q32*2*G32/1000)) -> 0 | V32: =IF(P32="FULL FEED",(R32*H32/1000),(R32*2*H32/1000)) -> 0 | W32: 49 | X32: 31 | AE32: =SUM(Z32,AA32,AB32,AC32) -> 0 | AF32: =Y32-AE32 -> 0 | AG32: =IFERROR(Y32/H31,0) -> 0 | AH32: =IFERROR(Z32/$Y32,0) -> 0 | AI32: =IFERROR(AA32/$Y32,0) -> 0 | AJ32: =IFERROR(AB32/$Y32,0) -> 0 | AK32: =IFERROR(AC32/$Y32,0) -> 0 | AL32: =IFERROR(AE32/Y32,0) -> 0 | AM32: =IFERROR(AF32/Y32,0) -> 0 | AU32: =IF(OR(AT32="",AR32=""),"", (AT32-AR32)/100*1000) | AV32: =IF(OR(AR33="",OFFSET(AR33,-1,0)=""),"", (AR33-OFFSET(AR33,-1,0))/100*1000) | AW32: =IFERROR(IF(OR(AR32="",AT32="",K32="",L32=""),"", ((AT32-AR32)/100*1000)/(U32+V32)),0) | AX32: =IF(OR(AR32="",AR33="",M32="",N32=""),"", ((AR33-AR32)/100*1000)/((G32+H32))*1000) | BA32: =IF(OR(AY32="",AZ32=""),"",MOD(AZ32-AY32,1)*24) | BD32: =IF(OR(BB32="",BC32=""),"",MOD(BC32-BB32,1)*24)
A33: =A26+1 -> 4.2 | B33: =B32+1 -> 23 | G33: =G32-E33-C33 -> 0 | H33: =H32-F33-D33 -> 0 | I33: =IFERROR(C33/G32,0) -> 0 | J33: =IFERROR(E33/G32,0) -> 0 | K33: =IFERROR(D33/H32,0) -> 0 | L33: =IFERROR(F33/H32,0) -> 0 | M33: =IF(ROW()=11, IF($B$4>0,E33/$B$4,""), IF($B$4>0, (OFFSET(M33,-1,0)*$B$4 + E33)/$B$4, "") ) | N33: =IF(ROW()=11, IF($B$4>0,F33/$B$4,""), IF($B$4>0, (OFFSET(N33,-1,0)*$B$4 + F33)/$B$4, "") ) | O33: =$O$10 -> 0.0005 | S33: =IF($P33="FULL FEED",Q33,Q33*2) -> 0 | T33: =IF($P33="FULL FEED",R33,R33*2) -> 0 | U33: =IF(P33="FULL FEED",(Q33*G33/1000),(Q33*2*G33/1000)) -> 0 | V33: =IF(P33="FULL FEED",(R33*H33/1000),(R33*2*H33/1000)) -> 0 | W33: =W32 -> 49 | X33: =X32 -> 31 | AE33: =SUM(Z33,AA33,AB33,AC33) -> 0 | AF33: =Y33-AE33 -> 0 | AG33: =IFERROR(Y33/H32,0) -> 0 | AH33: =IFERROR(Z33/$Y33,0) -> 0 | AI33: =IFERROR(AA33/$Y33,0) -> 0 | AJ33: =IFERROR(AB33/$Y33,0) -> 0 | AK33: =IFERROR(AC33/$Y33,0) -> 0 | AL33: =IFERROR(AE33/Y33,0) -> 0 | AM33: =IFERROR(AF33/Y33,0) -> 0 | AU33: =IF(OR(AT33="",AR33=""),"", (AT33-AR33)/100*1000) | AV33: =IF(OR(AR34="",OFFSET(AR34,-1,0)=""),"", (AR34-OFFSET(AR34,-1,0))/100*1000) | AW33: =IFERROR(IF(OR(AR33="",AT33="",K33="",L33=""),"", ((AT33-AR33)/100*1000)/(U33+V33)),0) | AX33: =IF(OR(AR33="",AR34="",M33="",N33=""),"", ((AR34-AR33)/100*1000)/((G33+H33))*1000) | BA33: =IF(OR(AY33="",AZ33=""),"",MOD(AZ33-AY33,1)*24) | BD33: =IF(OR(BB33="",BC33=""),"",MOD(BC33-BB33,1)*24)
A34: =A27+1 -> 4.3 | B34: =B33+1 -> 24 | G34: =G33-E34-C34 -> 0 | H34: =H33-F34-D34 -> 0 | I34: =IFERROR(C34/G33,0) -> 0 | J34: =IFERROR(E34/G33,0) -> 0 | K34: =IFERROR(D34/H33,0) -> 0 | L34: =IFERROR(F34/H33,0) -> 0 | M34: =IF(ROW()=11, IF($B$4>0,E34/$B$4,""), IF($B$4>0, (OFFSET(M34,-1,0)*$B$4 + E34)/$B$4, "") ) | N34: =IF(ROW()=11, IF($B$4>0,F34/$B$4,""), IF($B$4>0, (OFFSET(N34,-1,0)*$B$4 + F34)/$B$4, "") ) | O34: =$O$10 -> 0.0005 | S34: =IF($P34="FULL FEED",Q34,Q34*2) -> 0 | T34: =IF($P34="FULL FEED",R34,R34*2) -> 0 | U34: =IF(P34="FULL FEED",(Q34*G34/1000),(Q34*2*G34/1000)) -> 0 | V34: =IF(P34="FULL FEED",(R34*H34/1000),(R34*2*H34/1000)) -> 0 | W34: =W33 -> 49 | X34: =X33 -> 31 | AE34: =SUM(Z34,AA34,AB34,AC34) -> 0 | AF34: =Y34-AE34 -> 0 | AG34: =IFERROR(Y34/H33,0) -> 0 | AH34: =IFERROR(Z34/$Y34,0) -> 0 | AI34: =IFERROR(AA34/$Y34,0) -> 0 | AJ34: =IFERROR(AB34/$Y34,0) -> 0 | AK34: =IFERROR(AC34/$Y34,0) -> 0 | AL34: =IFERROR(AE34/Y34,0) -> 0 | AM34: =IFERROR(AF34/Y34,0) -> 0 | AU34: =IF(OR(AT34="",AR34=""),"", (AT34-AR34)/100*1000) | AV34: =IF(OR(AR35="",OFFSET(AR35,-1,0)=""),"", (AR35-OFFSET(AR35,-1,0))/100*1000) | AW34: =IFERROR(IF(OR(AR34="",AT34="",K34="",L34=""),"", ((AT34-AR34)/100*1000)/(U34+V34)),0) | AX34: =IF(OR(AR34="",AR35="",M34="",N34=""),"", ((AR35-AR34)/100*1000)/((G34+H34))*1000) | BA34: =IF(OR(AY34="",AZ34=""),"",MOD(AZ34-AY34,1)*24) | BD34: =IF(OR(BB34="",BC34=""),"",MOD(BC34-BB34,1)*24)
A35: =A28+1 -> 4.4 | B35: =B34+1 -> 25 | G35: =G34-E35-C35 -> 0 | H35: =H34-F35-D35 -> 0 | I35: =IFERROR(C35/G34,0) -> 0 | J35: =IFERROR(E35/G34,0) -> 0 | K35: =IFERROR(D35/H34,0) -> 0 | L35: =IFERROR(F35/H34,0) -> 0 | M35: =IF(ROW()=11, IF($B$4>0,E35/$B$4,""), IF($B$4>0, (OFFSET(M35,-1,0)*$B$4 + E35)/$B$4, "") ) | N35: =IF(ROW()=11, IF($B$4>0,F35/$B$4,""), IF($B$4>0, (OFFSET(N35,-1,0)*$B$4 + F35)/$B$4, "") ) | O35: =$O$10 -> 0.0005 | S35: =IF($P35="FULL FEED",Q35,Q35*2) -> 0 | T35: =IF($P35="FULL FEED",R35,R35*2) -> 0 | U35: =IF(P35="FULL FEED",(Q35*G35/1000),(Q35*2*G35/1000)) -> 0 | V35: =IF(P35="FULL FEED",(R35*H35/1000),(R35*2*H35/1000)) -> 0 | W35: =W34 -> 49 | X35: =X34 -> 31 | AE35: =SUM(Z35,AA35,AB35,AC35) -> 0 | AF35: =Y35-AE35 -> 0 | AG35: =IFERROR(Y35/H34,0) -> 0 | AH35: =IFERROR(Z35/$Y35,0) -> 0 | AI35: =IFERROR(AA35/$Y35,0) -> 0 | AJ35: =IFERROR(AB35/$Y35,0) -> 0 | AK35: =IFERROR(AC35/$Y35,0) -> 0 | AL35: =IFERROR(AE35/Y35,0) -> 0 | AM35: =IFERROR(AF35/Y35,0) -> 0 | AU35: =IF(OR(AT35="",AR35=""),"", (AT35-AR35)/100*1000) | AV35: =IF(OR(AR36="",OFFSET(AR36,-1,0)=""),"", (AR36-OFFSET(AR36,-1,0))/100*1000) | AW35: =IFERROR(IF(OR(AR35="",AT35="",K35="",L35=""),"", ((AT35-AR35)/100*1000)/(U35+V35)),0) | AX35: =IF(OR(AR35="",AR36="",M35="",N35=""),"", ((AR36-AR35)/100*1000)/((G35+H35))*1000) | BA35: =IF(OR(AY35="",AZ35=""),"",MOD(AZ35-AY35,1)*24) | BD35: =IF(OR(BB35="",BC35=""),"",MOD(BC35-BB35,1)*24)
A36: =A29+1 -> 4.5 | B36: =B35+1 -> 26 | G36: =G35-E36-C36 -> 0 | H36: =H35-F36-D36 -> 0 | I36: =IFERROR(C36/G35,0) -> 0 | J36: =IFERROR(E36/G35,0) -> 0 | K36: =IFERROR(D36/H35,0) -> 0 | L36: =IFERROR(F36/H35,0) -> 0 | M36: =IF(ROW()=11, IF($B$4>0,E36/$B$4,""), IF($B$4>0, (OFFSET(M36,-1,0)*$B$4 + E36)/$B$4, "") ) | N36: =IF(ROW()=11, IF($B$4>0,F36/$B$4,""), IF($B$4>0, (OFFSET(N36,-1,0)*$B$4 + F36)/$B$4, "") ) | O36: =$O$10 -> 0.0005 | S36: =IF($P36="FULL FEED",Q36,Q36*2) -> 0 | T36: =IF($P36="FULL FEED",R36,R36*2) -> 0 | U36: =IF(P36="FULL FEED",(Q36*G36/1000),(Q36*2*G36/1000)) -> 0 | V36: =IF(P36="FULL FEED",(R36*H36/1000),(R36*2*H36/1000)) -> 0 | W36: =W35 -> 49 | X36: =X35 -> 31 | AE36: =SUM(Z36,AA36,AB36,AC36) -> 0 | AF36: =Y36-AE36 -> 0 | AG36: =IFERROR(Y36/H35,0) -> 0 | AH36: =IFERROR(Z36/$Y36,0) -> 0 | AI36: =IFERROR(AA36/$Y36,0) -> 0 | AJ36: =IFERROR(AB36/$Y36,0) -> 0 | AK36: =IFERROR(AC36/$Y36,0) -> 0 | AL36: =IFERROR(AE36/Y36,0) -> 0 | AM36: =IFERROR(AF36/Y36,0) -> 0 | AU36: =IF(OR(AT36="",AR36=""),"", (AT36-AR36)/100*1000) | AV36: =IF(OR(AR37="",OFFSET(AR37,-1,0)=""),"", (AR37-OFFSET(AR37,-1,0))/100*1000) | AW36: =IFERROR(IF(OR(AR36="",AT36="",K36="",L36=""),"", ((AT36-AR36)/100*1000)/(U36+V36)),0) | AX36: =IF(OR(AR36="",AR37="",M36="",N36=""),"", ((AR37-AR36)/100*1000)/((G36+H36))*1000) | BA36: =IF(OR(AY36="",AZ36=""),"",MOD(AZ36-AY36,1)*24) | BD36: =IF(OR(BB36="",BC36=""),"",MOD(BC36-BB36,1)*24)
A37: =A30+1 -> 4.6 | B37: =B36+1 -> 27 | G37: =G36-E37-C37 -> 0 | H37: =H36-F37-D37 -> 0 | I37: =IFERROR(C37/G36,0) -> 0 | J37: =IFERROR(E37/G36,0) -> 0 | K37: =IFERROR(D37/H36,0) -> 0 | L37: =IFERROR(F37/H36,0) -> 0 | M37: =IF(ROW()=11, IF($B$4>0,E37/$B$4,""), IF($B$4>0, (OFFSET(M37,-1,0)*$B$4 + E37)/$B$4, "") ) | N37: =IF(ROW()=11, IF($B$4>0,F37/$B$4,""), IF($B$4>0, (OFFSET(N37,-1,0)*$B$4 + F37)/$B$4, "") ) | O37: =$O$10 -> 0.0005 | S37: =IF($P37="FULL FEED",Q37,Q37*2) -> 0 | T37: =IF($P37="FULL FEED",R37,R37*2) -> 0 | U37: =IF(P37="FULL FEED",(Q37*G37/1000),(Q37*2*G37/1000)) -> 0 | V37: =IF(P37="FULL FEED",(R37*H37/1000),(R37*2*H37/1000)) -> 0 | W37: =W36 -> 49 | X37: =X36 -> 31 | AE37: =SUM(Z37,AA37,AB37,AC37) -> 0 | AF37: =Y37-AE37 -> 0 | AG37: =IFERROR(Y37/H36,0) -> 0 | AH37: =IFERROR(Z37/$Y37,0) -> 0 | AI37: =IFERROR(AA37/$Y37,0) -> 0 | AJ37: =IFERROR(AB37/$Y37,0) -> 0 | AK37: =IFERROR(AC37/$Y37,0) -> 0 | AL37: =IFERROR(AE37/Y37,0) -> 0 | AM37: =IFERROR(AF37/Y37,0) -> 0 | AU37: =IF(OR(AT37="",AR37=""),"", (AT37-AR37)/100*1000) | AV37: =IF(OR(AR38="",OFFSET(AR38,-1,0)=""),"", (AR38-OFFSET(AR38,-1,0))/100*1000) | AW37: =IFERROR(IF(OR(AR37="",AT37="",K37="",L37=""),"", ((AT37-AR37)/100*1000)/(U37+V37)),0) | AX37: =IF(OR(AR37="",AR38="",M37="",N37=""),"", ((AR38-AR37)/100*1000)/((G37+H37))*1000) | BA37: =IF(OR(AY37="",AZ37=""),"",MOD(AZ37-AY37,1)*24) | BD37: =IF(OR(BB37="",BC37=""),"",MOD(BC37-BB37,1)*24)
A38: =A31+1 -> 4.7 | B38: =B37+1 -> 28 | G38: =G37-E38-C38 -> 0 | H38: =H37-F38-D38 -> 0 | I38: =IFERROR(C38/G37,0) -> 0 | J38: =IFERROR(E38/G37,0) -> 0 | K38: =IFERROR(D38/H37,0) -> 0 | L38: =IFERROR(F38/H37,0) -> 0 | M38: =IF(ROW()=11, IF($B$4>0,E38/$B$4,""), IF($B$4>0, (OFFSET(M38,-1,0)*$B$4 + E38)/$B$4, "") ) | N38: =IF(ROW()=11, IF($B$4>0,F38/$B$4,""), IF($B$4>0, (OFFSET(N38,-1,0)*$B$4 + F38)/$B$4, "") ) | O38: =$O$10 -> 0.0005 | S38: =IF($P38="FULL FEED",Q38,Q38*2) -> 0 | T38: =IF($P38="FULL FEED",R38,R38*2) -> 0 | U38: =IF(P38="FULL FEED",(Q38*G38/1000),(Q38*2*G38/1000)) -> 0 | V38: =IF(P38="FULL FEED",(R38*H38/1000),(R38*2*H38/1000)) -> 0 | W38: =W37 -> 49 | X38: =X37 -> 31 | AE38: =SUM(Z38,AA38,AB38,AC38) -> 0 | AF38: =Y38-AE38 -> 0 | AG38: =IFERROR(Y38/H37,0) -> 0 | AH38: =IFERROR(Z38/$Y38,0) -> 0 | AI38: =IFERROR(AA38/$Y38,0) -> 0 | AJ38: =IFERROR(AB38/$Y38,0) -> 0 | AK38: =IFERROR(AC38/$Y38,0) -> 0 | AL38: =IFERROR(AE38/Y38,0) -> 0 | AM38: =IFERROR(AF38/Y38,0) -> 0 | AU38: =IF(OR(AT38="",AR38=""),"", (AT38-AR38)/100*1000) | AV38: =IF(OR(AR39="",OFFSET(AR39,-1,0)=""),"", (AR39-OFFSET(AR39,-1,0))/100*1000) | AW38: =IFERROR(IF(OR(AR38="",AT38="",K38="",L38=""),"", ((AT38-AR38)/100*1000)/(U38+V38)),0) | AX38: =IF(OR(AR38="",AR39="",M38="",N38=""),"", ((AR39-AR38)/100*1000)/((G38+H38))*1000) | BA38: =IF(OR(AY38="",AZ38=""),"",MOD(AZ38-AY38,1)*24) | BD38: =IF(OR(BB38="",BC38=""),"",MOD(BC38-BB38,1)*24)
A39: =A32+1 -> 5.1 | B39: =B38+1 -> 29 | G39: =G38-E39-C39 -> 0 | H39: =H38-F39-D39 -> 0 | I39: =IFERROR(C39/G38,0) -> 0 | J39: =IFERROR(E39/G38,0) -> 0 | K39: =IFERROR(D39/H38,0) -> 0 | L39: =IFERROR(F39/H38,0) -> 0 | M39: =IF(ROW()=11, IF($B$4>0,E39/$B$4,""), IF($B$4>0, (OFFSET(M39,-1,0)*$B$4 + E39)/$B$4, "") ) | N39: =IF(ROW()=11, IF($B$4>0,F39/$B$4,""), IF($B$4>0, (OFFSET(N39,-1,0)*$B$4 + F39)/$B$4, "") ) | O39: =$O$10 -> 0.0005 | S39: =IF($P39="FULL FEED",Q39,Q39*2) -> 0 | T39: =IF($P39="FULL FEED",R39,R39*2) -> 0 | U39: =IF(P39="FULL FEED",(Q39*G39/1000),(Q39*2*G39/1000)) -> 0 | V39: =IF(P39="FULL FEED",(R39*H39/1000),(R39*2*H39/1000)) -> 0 | W39: 54 | X39: 34 | AE39: =SUM(Z39,AA39,AB39,AC39) -> 0 | AF39: =Y39-AE39 -> 0 | AG39: =IFERROR(Y39/H38,0) -> 0 | AH39: =IFERROR(Z39/$Y39,0) -> 0 | AI39: =IFERROR(AA39/$Y39,0) -> 0 | AJ39: =IFERROR(AB39/$Y39,0) -> 0 | AK39: =IFERROR(AC39/$Y39,0) -> 0 | AL39: =IFERROR(AE39/Y39,0) -> 0 | AM39: =IFERROR(AF39/Y39,0) -> 0 | AU39: =IF(OR(AT39="",AR39=""),"", (AT39-AR39)/100*1000) | AV39: =IF(OR(AR40="",OFFSET(AR40,-1,0)=""),"", (AR40-OFFSET(AR40,-1,0))/100*1000) | AW39: =IFERROR(IF(OR(AR39="",AT39="",K39="",L39=""),"", ((AT39-AR39)/100*1000)/(U39+V39)),0) | AX39: =IF(OR(AR39="",AR40="",M39="",N39=""),"", ((AR40-AR39)/100*1000)/((G39+H39))*1000) | BA39: =IF(OR(AY39="",AZ39=""),"",MOD(AZ39-AY39,1)*24) | BD39: =IF(OR(BB39="",BC39=""),"",MOD(BC39-BB39,1)*24)
A40: =A33+1 -> 5.2 | B40: =B39+1 -> 30 | G40: =G39-E40-C40 -> 0 | H40: =H39-F40-D40 -> 0 | I40: =IFERROR(C40/G39,0) -> 0 | J40: =IFERROR(E40/G39,0) -> 0 | K40: =IFERROR(D40/H39,0) -> 0 | L40: =IFERROR(F40/H39,0) -> 0 | M40: =IF(ROW()=11, IF($B$4>0,E40/$B$4,""), IF($B$4>0, (OFFSET(M40,-1,0)*$B$4 + E40)/$B$4, "") ) | N40: =IF(ROW()=11, IF($B$4>0,F40/$B$4,""), IF($B$4>0, (OFFSET(N40,-1,0)*$B$4 + F40)/$B$4, "") ) | O40: =$O$10 -> 0.0005 | S40: =IF($P40="FULL FEED",Q40,Q40*2) -> 0 | T40: =IF($P40="FULL FEED",R40,R40*2) -> 0 | U40: =IF(P40="FULL FEED",(Q40*G40/1000),(Q40*2*G40/1000)) -> 0 | V40: =IF(P40="FULL FEED",(R40*H40/1000),(R40*2*H40/1000)) -> 0 | W40: =W39 -> 54 | X40: =X39 -> 34 | AE40: =SUM(Z40,AA40,AB40,AC40) -> 0 | AF40: =Y40-AE40 -> 0 | AG40: =IFERROR(Y40/H39,0) -> 0 | AH40: =IFERROR(Z40/$Y40,0) -> 0 | AI40: =IFERROR(AA40/$Y40,0) -> 0 | AJ40: =IFERROR(AB40/$Y40,0) -> 0 | AK40: =IFERROR(AC40/$Y40,0) -> 0 | AL40: =IFERROR(AE40/Y40,0) -> 0 | AM40: =IFERROR(AF40/Y40,0) -> 0 | AU40: =IF(OR(AT40="",AR40=""),"", (AT40-AR40)/100*1000) | AV40: =IF(OR(AR41="",OFFSET(AR41,-1,0)=""),"", (AR41-OFFSET(AR41,-1,0))/100*1000) | AW40: =IFERROR(IF(OR(AR40="",AT40="",K40="",L40=""),"", ((AT40-AR40)/100*1000)/(U40+V40)),0) | AX40: =IF(OR(AR40="",AR41="",M40="",N40=""),"", ((AR41-AR40)/100*1000)/((G40+H40))*1000) | BA40: =IF(OR(AY40="",AZ40=""),"",MOD(AZ40-AY40,1)*24) | BD40: =IF(OR(BB40="",BC40=""),"",MOD(BC40-BB40,1)*24)
A41: =A34+1 -> 5.3 | B41: =B40+1 -> 31 | G41: =G40-E41-C41 -> 0 | H41: =H40-F41-D41 -> 0 | I41: =IFERROR(C41/G40,0) -> 0 | J41: =IFERROR(E41/G40,0) -> 0 | K41: =IFERROR(D41/H40,0) -> 0 | L41: =IFERROR(F41/H40,0) -> 0 | M41: =IF(ROW()=11, IF($B$4>0,E41/$B$4,""), IF($B$4>0, (OFFSET(M41,-1,0)*$B$4 + E41)/$B$4, "") ) | N41: =IF(ROW()=11, IF($B$4>0,F41/$B$4,""), IF($B$4>0, (OFFSET(N41,-1,0)*$B$4 + F41)/$B$4, "") ) | O41: =$O$10 -> 0.0005 | S41: =IF($P41="FULL FEED",Q41,Q41*2) -> 0 | T41: =IF($P41="FULL FEED",R41,R41*2) -> 0 | U41: =IF(P41="FULL FEED",(Q41*G41/1000),(Q41*2*G41/1000)) -> 0 | V41: =IF(P41="FULL FEED",(R41*H41/1000),(R41*2*H41/1000)) -> 0 | W41: =W40 -> 54 | X41: =X40 -> 34 | AE41: =SUM(Z41,AA41,AB41,AC41) -> 0 | AF41: =Y41-AE41 -> 0 | AG41: =IFERROR(Y41/H40,0) -> 0 | AH41: =IFERROR(Z41/$Y41,0) -> 0 | AI41: =IFERROR(AA41/$Y41,0) -> 0 | AJ41: =IFERROR(AB41/$Y41,0) -> 0 | AK41: =IFERROR(AC41/$Y41,0) -> 0 | AL41: =IFERROR(AE41/Y41,0) -> 0 | AM41: =IFERROR(AF41/Y41,0) -> 0 | AU41: =IF(OR(AT41="",AR41=""),"", (AT41-AR41)/100*1000) | AV41: =IF(OR(AR42="",OFFSET(AR42,-1,0)=""),"", (AR42-OFFSET(AR42,-1,0))/100*1000) | AW41: =IFERROR(IF(OR(AR41="",AT41="",K41="",L41=""),"", ((AT41-AR41)/100*1000)/(U41+V41)),0) | AX41: =IF(OR(AR41="",AR42="",M41="",N41=""),"", ((AR42-AR41)/100*1000)/((G41+H41))*1000) | BA41: =IF(OR(AY41="",AZ41=""),"",MOD(AZ41-AY41,1)*24) | BD41: =IF(OR(BB41="",BC41=""),"",MOD(BC41-BB41,1)*24)
...

Sheet DASHBOARD
A1: Farm Performance Dashboard | Q1: DF | R1: CF | S1: DM | T1: CM | U1: EP | V1: HE | W1: EG | X1: J | Y1: S | Z1: A | AA1: C | AB1: R | AC1: TF | AD1: FGB | AE1: FF | AF1: TM | AG1: MGB | AH1: FM | AI1: FBW | AJ1: FUNI | AK1: MBW | AL1: MUNI
A2: *ONLY WHITE CELL ARE EDITABLE | Q2: {=_xlfn.LET( _xlpm.sh, $B$5, _xlpm.refDate, --$D$5, _xlpm.colDate, MATCH("DATE", INDIRECT("'"&_xlpm.sh&"'!9:9"), 0), _xlpm.colMetric, MATCH("DEAD FEMALE%", INDIRECT("'"&_xlpm.sh&"'!9:9"), 0), _xlpm.dates, INDEX(INDIRECT("'"&_xlpm.sh&"'!11:500"),,_xlpm.colDate), _xlpm.values, INDEX(INDIRECT("'"&_xlpm.sh&"'!11:500"),,_xlpm.colMetric), _xlpm.recent, (_xlpm.dates >= _xlpm.refDate - 6) * (_xlpm.dates <= _xlpm.refDate), _xlpm.filtered, _xlfn._xlws.FILTER(_xlpm.values, _xlpm.recent), IFERROR(_xlpm.filtered, "") )} -> 0 | R2: {=_xlfn.LET( _xlpm.sh, $B$5, _xlpm.refDate, --$D$5, _xlpm.colDate, MATCH("DATE", INDIRECT("'"&_xlpm.sh&"'!9:9"), 0), _xlpm.colMetric, MATCH("CULL FEMALE%", INDIRECT("'"&_xlpm.sh&"'!9:9"), 0), _xlpm.dates, INDEX(INDIRECT("'"&_xlpm.sh&"'!11:500"),,_xlpm.colDate), _xlpm.values, INDEX(INDIRECT("'"&_xlpm.sh&"'!11:500"),,_xlpm.colMetric), _xlpm.recent, (_xlpm.dates >= _xlpm.refDate - 6) * (_xlpm.dates <= _xlpm.refDate), _xlpm.filtered, _xlfn._xlws.FILTER(_xlpm.values, _xlpm.recent), IFERROR(_xlpm.filtered, "") )} -> 0 | S2: {=_xlfn.LET( _xlpm.sh, $B$5, _xlpm.refDate, --$D$5, _xlpm.colDate, MATCH("DATE", INDIRECT("'"&_xlpm.sh&"'!9:9"), 0), _xlpm.colMetric, MATCH("DEAD MALE%", INDIRECT("'"&_xlpm.sh&"'!9:9"), 0), _xlpm.dates, INDEX(INDIRECT("'"&_xlpm.sh&"'!11:500"),,_xlpm.colDate), _xlpm.values, INDEX(INDIRECT("'"&_xlpm.sh&"'!11:500"),,_xlpm.colMetric), _xlpm.recent, (_xlpm.dates >= _xlpm.refDate - 6) * (_xlpm.dates <= _xlpm.refDate), _xlpm.filtered, _xlfn._xlws.FILTER(_xlpm.values, _xlpm.recent), IFERROR(_xlpm.filtered, "") )} -> 0 | T2: {=_xlfn.LET( _xlpm.sh, $B$5, _xlpm.refDate, --$D$5, _xlpm.colDate, MATCH("DATE", INDIRECT("'"&_xlpm.sh&"'!9:9"), 0), _xlpm.colMetric, MATCH("CULL MALE%", INDIRECT("'"&_xlpm.sh&"'!9:9"), 0), _xlpm.dates, INDEX(INDIRECT("'"&_xlpm.sh&"'!11:500"),,_xlpm.colDate), _xlpm.values, INDEX(INDIRECT("'"&_xlpm.sh&"'!11:500"),,_xlpm.colMetric), _xlpm.recent, (_xlpm.dates >= _xlpm.refDate - 6) * (_xlpm.dates <= _xlpm.refDate), _xlpm.filtered, _xlfn._xlws.FILTER(_xlpm.values, _xlpm.recent), IFERROR(_xlpm.filtered, "") )} -> 0 | U2: {=_xlfn.LET( _xlpm.sh, $B$5, _xlpm.refDate, --$D$5, _xlpm.colDate, MATCH("DATE", INDIRECT("'"&_xlpm.sh&"'!9:9"), 0), _xlpm.colMetric, MATCH("EGG PRODUCTION%", INDIRECT("'"&_xlpm.sh&"'!9:9"), 0), _xlpm.dates, INDEX(INDIRECT("'"&_xlpm.sh&"'!11:500"),,_xlpm.colDate), _xlpm.values, INDEX(INDIRECT("'"&_xlpm.sh&"'!11:500"),,_xlpm.colMetric), _xlpm.recent, (_xlpm.dates >= _xlpm.refDate - 6) * (_xlpm.dates <= _xlpm.refDate), _xlpm.filtered, _xlfn._xlws.FILTER(_xlpm.values, _xlpm.recent), IFERROR(_xlpm.filtered, "") )} -> 0 | V2: {=_xlfn.LET( _xlpm.sh, $B$5, _xlpm.refDate, --$D$5, _xlpm.colDate, MATCH("DATE", INDIRECT("'"&_xlpm.sh&"'!9:9"), 0), _xlpm.colMetric, MATCH("H.E%", INDIRECT("'"&_xlpm.sh&"'!9:9"), 0), _xlpm.dates, INDEX(INDIRECT("'"&_xlpm.sh&"'!11:500"),,_xlpm.colDate), _xlpm.values, INDEX(INDIRECT("'"&_xlpm.sh&"'!11:500"),,_xlpm.colMetric), _xlpm.recent, (_xlpm.dates >= _xlpm.refDate - 6) * (_xlpm.dates <= _xlpm.refDate), _xlpm.filtered, _xlfn._xlws.FILTER(_xlpm.values, _xlpm.recent), IFERROR(_xlpm.filtered, "") )} -> 0 | W2: {=_xlfn.LET( _xlpm.sh, $B$5, _xlpm.refDate, --$D$5, _xlpm.colDate, MATCH("DATE", INDIRECT("'"&_xlpm.sh&"'!9:9"), 0), _xlpm.colMetric, MATCH("GRAM EGG", INDIRECT("'"&_xlpm.sh&"'!9:9"), 0), _xlpm.dates, INDEX(INDIRECT("'"&_xlpm.sh&"'!11:500"),,_xlpm.colDate), _xlpm.values, INDEX(INDIRECT("'"&_xlpm.sh&"'!11:500"),,_xlpm.colMetric), _xlpm.recent, (_xlpm.dates >= _xlpm.refDate - 6) * (_xlpm.dates <= _xlpm.refDate), _xlpm.filtered, _xlfn._xlws.FILTER(_xlpm.values, _xlpm.recent), IFERROR(_xlpm.filtered, "") )} -> 0 | X2: {=_xlfn.LET( _xlpm.sh, $B$5, _xlpm.refDate, --$D$5, _xlpm.colDate, MATCH("DATE", INDIRECT("'"&_xlpm.sh&"'!9:9"), 0), _xlpm.colMetric, MATCH("JUMBO%", INDIRECT("'"&_xlpm.sh&"'!9:9"), 0), _xlpm.dates, INDEX(INDIRECT("'"&_xlpm.sh&"'!11:500"),,_xlpm.colDate), _xlpm.values, INDEX(INDIRECT("'"&_xlpm.sh&"'!11:500"),,_xlpm.colMetric), _xlpm.recent, (_xlpm.dates >= _xlpm.refDate - 6) * (_xlpm.dates <= _xlpm.refDate), _xlpm.filtered, _xlfn._xlws.FILTER(_xlpm.values, _xlpm.recent), IFERROR(_xlpm.filtered, "") )} -> 0 | Y2: {=_xlfn.LET( _xlpm.sh, $B$5, _xlpm.refDate, --$D$5, _xlpm.colDate, MATCH("DATE", INDIRECT("'"&_xlpm.sh&"'!9:9"), 0), _xlpm.colMetric, MATCH("SMALL%", INDIRECT("'"&_xlpm.sh&"'!9:9"), 0), _xlpm.dates, INDEX(INDIRECT("'"&_xlpm.sh&"'!11:500"),,_xlpm.colDate), _xlpm.values, INDEX(INDIRECT("'"&_xlpm.sh&"'!11:500"),,_xlpm.colMetric), _xlpm.recent, (_xlpm.dates >= _xlpm.refDate - 6) * (_xlpm.dates <= _xlpm.refDate), _xlpm.filtered, _xlfn._xlws.FILTER(_xlpm.values, _xlpm.recent), IFERROR(_xlpm.filtered, "") )} -> 0 | Z2: {=_xlfn.LET( _xlpm.sh, $B$5, _xlpm.refDate, --$D$5, _xlpm.colDate, MATCH("DATE", INDIRECT("'"&_xlpm.sh&"'!9:9"), 0), _xlpm.colMetric, MATCH("ABNORMAL%", INDIRECT("'"&_xlpm.sh&"'!9:9"), 0), _xlpm.dates, INDEX(INDIRECT("'"&_xlpm.sh&"'!11:500"),,_xlpm.colDate), _xlpm.values, INDEX(INDIRECT("'"&_xlpm.sh&"'!11:500"),,_xlpm.colMetric), _xlpm.recent, (_xlpm.dates >= _xlpm.refDate - 6) * (_xlpm.dates <= _xlpm.refDate), _xlpm.filtered, _xlfn._xlws.FILTER(_xlpm.values, _xlpm.recent), IFERROR(_xlpm.filtered, "") )} -> 0 | AA2: {=_xlfn.LET( _xlpm.sh, $B$5, _xlpm.refDate, --$D$5, _xlpm.colDate, MATCH("DATE", INDIRECT("'"&_xlpm.sh&"'!9:9"), 0), _xlpm.colMetric, MATCH("CRACK%", INDIRECT("'"&_xlpm.sh&"'!9:9"), 0), _xlpm.dates, INDEX(INDIRECT("'"&_xlpm.sh&"'!11:500"),,_xlpm.colDate), _xlpm.values, INDEX(INDIRECT("'"&_xlpm.sh&"'!11:500"),,_xlpm.colMetric), _xlpm.recent, (_xlpm.dates >= _xlpm.refDate - 6) * (_xlpm.dates <= _xlpm.refDate), _xlpm.filtered, _xlfn._xlws.FILTER(_xlpm.values, _xlpm.recent), IFERROR(_xlpm.filtered, "") )} -> 0 | AB2: {=_xlfn.LET( _xlpm.sh, $B$5, _xlpm.refDate, --$D$5, _xlpm.colDate, MATCH("DATE", INDIRECT("'"&_xlpm.sh&"'!9:9"), 0), _xlpm.colMetric, MATCH("REJECT%", INDIRECT("'"&_xlpm.sh&"'!9:9"), 0), _xlpm.dates, INDEX(INDIRECT("'"&_xlpm.sh&"'!11:500"),,_xlpm.colDate), _xlpm.values, INDEX(INDIRECT("'"&_xlpm.sh&"'!11:500"),,_xlpm.colMetric), _xlpm.recent, (_xlpm.dates >= _xlpm.refDate - 6) * (_xlpm.dates <= _xlpm.refDate), _xlpm.filtered, _xlfn._xlws.FILTER(_xlpm.values, _xlpm.recent), IFERROR(_xlpm.filtered, "") )} -> 0 | AC2: {=_xlfn.LET( _xlpm.sh, $B$5, _xlpm.refDate, --$D$5, _xlpm.colDate, MATCH("DATE", INDIRECT("'"&_xlpm.sh&"'!9:9"), 0), _xlpm.colMetric, MATCH("FEMALE STOCK", INDIRECT("'"&_xlpm.sh&"'!9:9"), 0), _xlpm.dates, INDEX(INDIRECT("'"&_xlpm.sh&"'!11:500"),,_xlpm.colDate), _xlpm.values, INDEX(INDIRECT("'"&_xlpm.sh&"'!11:500"),,_xlpm.colMetric), _xlpm.recent, (_xlpm.dates >= _xlpm.refDate - 6) * (_xlpm.dates <= _xlpm.refDate), _xlpm.filtered, _xlfn._xlws.FILTER(_xlpm.values, _xlpm.recent), IFERROR(_xlpm.filtered, "") )} -> 5890 | AD2: {=_xlfn.LET( _xlpm.sh, $B$5, _xlpm.refDate, --$D$5, _xlpm.colDate, MATCH("DATE", INDIRECT("'"&_xlpm.sh&"'!9:9"), 0), _xlpm.colMetric, MATCH("ACTUAL FEMALE G/B", INDIRECT("'"&_xlpm.sh&"'!9:9"), 0), _xlpm.dates, INDEX(INDIRECT("'"&_xlpm.sh&"'!11:500"),,_xlpm.colDate), _xlpm.values, INDEX(INDIRECT("'"&_xlpm.sh&"'!11:500"),,_xlpm.colMetric), _xlpm.recent, (_xlpm.dates >= _xlpm.refDate - 6) * (_xlpm.dates <= _xlpm.refDate), _xlpm.filtered, _xlfn._xlws.FILTER(_xlpm.values, _xlpm.recent), IFERROR(_xlpm.filtered, "") )} -> 38 | AE2: {=_xlfn.LET( _xlpm.sh, $B$5, _xlpm.refDate, --$D$5, _xlpm.colDate, MATCH("DATE", INDIRECT("'"&_xlpm.sh&"'!9:9"), 0), _xlpm.colMetric, MATCH("FEMALE TOTAL FEED (KG)", INDIRECT("'"&_xlpm.sh&"'!9:9"), 0), _xlpm.dates, INDEX(INDIRECT("'"&_xlpm.sh&"'!11:500"),,_xlpm.colDate), _xlpm.values, INDEX(INDIRECT("'"&_xlpm.sh&"'!11:500"),,_xlpm.colMetric), _xlpm.recent, (_xlpm.dates >= _xlpm.refDate - 6) * (_xlpm.dates <= _xlpm.refDate), _xlpm.filtered, _xlfn._xlws.FILTER(_xlpm.values, _xlpm.recent), IFERROR(_xlpm.filtered, "") )} -> 223.82 | AF2: {=_xlfn.LET( _xlpm.sh, $B$5, _xlpm.refDate, --$D$5, _xlpm.colDate, MATCH("DATE", INDIRECT("'"&_xlpm.sh&"'!9:9"), 0), _xlpm.colMetric, MATCH("FEMALE STOCK", INDIRECT("'"&_xlpm.sh&"'!9:9"), 0), _xlpm.dates, INDEX(INDIRECT("'"&_xlpm.sh&"'!11:500"),,_xlpm.colDate), _xlpm.values, INDEX(INDIRECT("'"&_xlpm.sh&"'!11:500"),,_xlpm.colMetric), _xlpm.recent, (_xlpm.dates >= _xlpm.refDate - 6) * (_xlpm.dates <= _xlpm.refDate), _xlpm.filtered, _xlfn._xlws.FILTER(_xlpm.values, _xlpm.recent), IFERROR(_xlpm.filtered, "") )} -> 5890 | AG2: {=_xlfn.LET( _xlpm.sh, $B$5, _xlpm.refDate, --$D$5, _xlpm.colDate, MATCH("DATE", INDIRECT("'"&_xlpm.sh&"'!9:9"), 0), _xlpm.colMetric, MATCH("ACTUAL FEMALE G/B", INDIRECT("'"&_xlpm.sh&"'!9:9"), 0), _xlpm.dates, INDEX(INDIRECT("'"&_xlpm.sh&"'!11:500"),,_xlpm.colDate), _xlpm.values, INDEX(INDIRECT("'"&_xlpm.sh&"'!11:500"),,_xlpm.colMetric), _xlpm.recent, (_xlpm.dates >= _xlpm.refDate - 6) * (_xlpm.dates <= _xlpm.refDate), _xlpm.filtered, _xlfn._xlws.FILTER(_xlpm.values, _xlpm.recent), IFERROR(_xlpm.filtered, "") )} -> 38 | AH2: {=_xlfn.LET( _xlpm.sh, $B$5, _xlpm.refDate, --$D$5, _xlpm.colDate, MATCH("DATE", INDIRECT("'"&_xlpm.sh&"'!9:9"), 0), _xlpm.colMetric, MATCH("FEMALE TOTAL FEED (KG)", INDIRECT("'"&_xlpm.sh&"'!9:9"), 0), _xlpm.dates, INDEX(INDIRECT("'"&_xlpm.sh&"'!11:500"),,_xlpm.colDate), _xlpm.values, INDEX(INDIRECT("'"&_xlpm.sh&"'!11:500"),,_xlpm.colMetric), _xlpm.recent, (_xlpm.dates >= _xlpm.refDate - 6) * (_xlpm.dates <= _xlpm.refDate), _xlpm.filtered, _xlfn._xlws.FILTER(_xlpm.values, _xlpm.recent), IFERROR(_xlpm.filtered, "") )} -> 223.82 | AI2: {=_xlfn.LET( _xlpm.sh, $B$5, _xlpm.refWeek, $G$5, _xlpm.colWeek, MATCH("WEEK", INDIRECT("'" & _xlpm.sh & "'!506:506"), 0), _xlpm.colBW, MATCH("FEMALE BW", INDIRECT("'" & _xlpm.sh & "'!506:506"), 0), _xlpm.wk, INDEX(INDIRECT("'" & _xlpm.sh & "'!508:577"), , _xlpm.colWeek), _xlpm.bw, INDEX(INDIRECT("'" & _xlpm.sh & "'!508:577"), , _xlpm.colBW), _xlpm.recent, (_xlpm.wk >= _xlpm.refWeek - 6) * (_xlpm.wk <= _xlpm.refWeek) * (_xlpm.bw <> ""), _xlpm.filtered, _xlfn._xlws.FILTER(_xlpm.bw, _xlpm.recent), _xlpm.filled, IF(_xlpm.filtered = "", 0, _xlpm.filtered), IFERROR(_xlpm.filled, 0) )} -> 132.5 | AJ2: {=_xlfn.LET( _xlpm.sh, $B$5, _xlpm.refWeek, $G$5, _xlpm.colWeek, MATCH("WEEK", INDIRECT("'" & _xlpm.sh & "'!506:506"), 0), _xlpm.colBW, MATCH("FEMALE uni%", INDIRECT("'" & _xlpm.sh & "'!506:506"), 0), _xlpm.wk, INDEX(INDIRECT("'" & _xlpm.sh & "'!508:577"), , _xlpm.colWeek), _xlpm.bw, INDEX(INDIRECT("'" & _xlpm.sh & "'!508:577"), , _xlpm.colBW), _xlpm.recent, (_xlpm.wk >= _xlpm.refWeek - 6) * (_xlpm.wk <= _xlpm.refWeek) * (_xlpm.bw <> ""), _xlpm.filtered, _xlfn._xlws.FILTER(_xlpm.bw, _xlpm.recent), _xlpm.filled, IF(_xlpm.filtered = "", 0, _xlpm.filtered), IFERROR(_xlpm.filled, 0) )} -> 0 | AK2: {=_xlfn.LET( _xlpm.sh, $B$5, _xlpm.refWeek, $G$5, _xlpm.colWeek, MATCH("WEEK", INDIRECT("'" & _xlpm.sh & "'!506:506"), 0), _xlpm.colBW, MATCH("MALE BW", INDIRECT("'" & _xlpm.sh & "'!506:506"), 0), _xlpm.wk, INDEX(INDIRECT("'" & _xlpm.sh & "'!508:577"), , _xlpm.colWeek), _xlpm.bw, INDEX(INDIRECT("'" & _xlpm.sh & "'!508:577"), , _xlpm.colBW), _xlpm.recent, (_xlpm.wk >= _xlpm.refWeek - 6) * (_xlpm.wk <= _xlpm.refWeek) * (_xlpm.bw <> ""), _xlpm.filtered, _xlfn._xlws.FILTER(_xlpm.bw, _xlpm.recent), _xlpm.filled, IF(_xlpm.filtered = "", 0, _xlpm.filtered), IFERROR(_xlpm.filled, 0) )} -> 138 | AL2: {=_xlfn.LET( _xlpm.sh, $B$5, _xlpm.refWeek, $G$5, _xlpm.colWeek, MATCH("WEEK", INDIRECT("'" & _xlpm.sh & "'!506:506"), 0), _xlpm.colBW, MATCH("MALE UNI%", INDIRECT("'" & _xlpm.sh & "'!506:506"), 0), _xlpm.wk, INDEX(INDIRECT("'" & _xlpm.sh & "'!508:577"), , _xlpm.colWeek), _xlpm.bw, INDEX(INDIRECT("'" & _xlpm.sh & "'!508:577"), , _xlpm.colBW), _xlpm.recent, (_xlpm.wk >= _xlpm.refWeek - 6) * (_xlpm.wk <= _xlpm.refWeek) * (_xlpm.bw <> ""), _xlpm.filtered, _xlfn._xlws.FILTER(_xlpm.bw, _xlpm.recent), _xlpm.filled, IF(_xlpm.filtered = "", 0, _xlpm.filtered), IFERROR(_xlpm.filled, 0) )} -> 0
